Workbook

Sheet Check before use
A1: DRAFT PARASTATAL scoring workbook - generated from the methodology sheet
A3: This draft follows the same layout as the UPD scoring workbook, so the app can fill, merge and read it. The scoring experts should:
A4: 1. Replace each question sheet's simple inputs (yellow) and Points formula with the real ones, keeping the row-11 instructions (e.g. SELECT YES / NO) and the column names 'Points (Auto-generate)' and 'SCORER COMMENTS'.
A5: 2. Check 'Applies?' (filled in from each agency's type and the question's Applicability). To change it, fix the agency in the city register or Sources workbook and generate again.
A6: 3. Fix the points below in the methodology sheet and generate again.
A8: Points to check:
A9: • Section 'Decentralised Participatory Governance' has no (CODE); using DPG
A10: • Section 'State Capacities' has no (CODE); using SC
A11: • Question Bank row 57: the ID "SC-5" is used twice. Each question needs its own ID; the second one was skipped.
A12: • UPD 1a: the methodology gives scores up to 10, but the Max Score is 5. Say how the score should be scaled.
A13: • DPG 4 has no Tag or Max Score, so it is left out of the scores. Add them if it should be scored.

Sheet PARASTATAL_SUMMARY_RAW
A1: ASICS 2027_Report_Q No | B1: Group | C1: MQ_SQ | D1: Question | E1: Assessment level | F1: Max Score | G1: Bengaluru – BWSSB | H1: Bengaluru – BMTC | I1: Bengaluru – BDA | J1: Bengaluru – BMRCL | K1: Bengaluru – BMRDA | L1: Surat – SUDA | M1: Surat – GMRC
A2: ENTER | B2: Derived | C2: Derived | D2: Derived | E2: Derived | F2: Derived | G2: Derived | H2: Derived | I2: Derived | J2: Derived | K2: Derived | L2: Derived | M2: Derived
A3: UPD1 | B3: =VLOOKUP($A3,'PARASTATAL Questions'!$A:$J,3,0)&"" | C3: =VLOOKUP($A3,'PARASTATAL Questions'!$A:$J,4,0)&"" | D3: =VLOOKUP($A3,'PARASTATAL Questions'!$A:$J,5,0)&"" | E3: =VLOOKUP($A3,'PARASTATAL Questions'!$A:$J,7,0)&"" | F3: =VLOOKUP($A3,'PARASTATAL Questions'!$A:$J,6,0) | G3: =IF(OR(G4="ER",G5="ER"),"ER",IF(OR(G4="?",G5="?"),"?",IF(AND(G4="NA",G5="NA"),"NA",SUM(G4,G5)/((G4<>"NA")*$F$4+(G5<>"NA")*$F$5)*$F3))) | H3: =IF(OR(H4="ER",H5="ER"),"ER",IF(OR(H4="?",H5="?"),"?",IF(AND(H4="NA",H5="NA"),"NA",SUM(H4,H5)/((H4<>"NA")*$F$4+(H5<>"NA")*$F$5)*$F3))) | I3: =IF(OR(I4="ER",I5="ER"),"ER",IF(OR(I4="?",I5="?"),"?",IF(AND(I4="NA",I5="NA"),"NA",SUM(I4,I5)/((I4<>"NA")*$F$4+(I5<>"NA")*$F$5)*$F3))) | J3: =IF(OR(J4="ER",J5="ER"),"ER",IF(OR(J4="?",J5="?"),"?",IF(AND(J4="NA",J5="NA"),"NA",SUM(J4,J5)/((J4<>"NA")*$F$4+(J5<>"NA")*$F$5)*$F3))) | K3: =IF(OR(K4="ER",K5="ER"),"ER",IF(OR(K4="?",K5="?"),"?",IF(AND(K4="NA",K5="NA"),"NA",SUM(K4,K5)/((K4<>"NA")*$F$4+(K5<>"NA")*$F$5)*$F3))) | L3: =IF(OR(L4="ER",L5="ER"),"ER",IF(OR(L4="?",L5="?"),"?",IF(AND(L4="NA",L5="NA"),"NA",SUM(L4,L5)/((L4<>"NA")*$F$4+(L5<>"NA")*$F$5)*$F3))) | M3: =IF(OR(M4="ER",M5="ER"),"ER",IF(OR(M4="?",M5="?"),"?",IF(AND(M4="NA",M5="NA"),"NA",SUM(M4,M5)/((M4<>"NA")*$F$4+(M5<>"NA")*$F$5)*$F3)))
A4: UPD1a | B4: =VLOOKUP($A4,'PARASTATAL Questions'!$A:$J,3,0)&"" | C4: =VLOOKUP($A4,'PARASTATAL Questions'!$A:$J,4,0)&"" | D4: =VLOOKUP($A4,'PARASTATAL Questions'!$A:$J,5,0)&"" | E4: =VLOOKUP($A4,'PARASTATAL Questions'!$A:$J,7,0)&"" | F4: =VLOOKUP($A4,'PARASTATAL Questions'!$A:$J,6,0) | G4: =IF($F4=0,"NA",IF($A4=INDIRECT("'"&$A4&"'!$B$1"),IF(VLOOKUP(G$1,INDIRECT("'"&$A4&"'!$A$12:$Z$19"),MATCH("Points (Auto-generate)",INDIRECT("'"&$A4&"'!$A$12:$Z$12"),0),0)="","?",VLOOKUP(G$1,INDIRECT("'"&$A4&"'!$A$12:$Z$19"),MATCH("Points (Auto-generate)",INDIRECT("'"&$A4&"'!$A$12:$Z$12"),0),0)),"ER")) | H4: =IF($F4=0,"NA",IF($A4=INDIRECT("'"&$A4&"'!$B$1"),IF(VLOOKUP(H$1,INDIRECT("'"&$A4&"'!$A$12:$Z$19"),MATCH("Points (Auto-generate)",INDIRECT("'"&$A4&"'!$A$12:$Z$12"),0),0)="","?",VLOOKUP(H$1,INDIRECT("'"&$A4&"'!$A$12:$Z$19"),MATCH("Points (Auto-generate)",INDIRECT("'"&$A4&"'!$A$12:$Z$12"),0),0)),"ER")) | I4: =IF($F4=0,"NA",IF($A4=INDIRECT("'"&$A4&"'!$B$1"),IF(VLOOKUP(I$1,INDIRECT("'"&$A4&"'!$A$12:$Z$19"),MATCH("Points (Auto-generate)",INDIRECT("'"&$A4&"'!$A$12:$Z$12"),0),0)="","?",VLOOKUP(I$1,INDIRECT("'"&$A4&"'!$A$12:$Z$19"),MATCH("Points (Auto-generate)",INDIRECT("'"&$A4&"'!$A$12:$Z$12"),0),0)),"ER")) | J4: =IF($F4=0,"NA",IF($A4=INDIRECT("'"&$A4&"'!$B$1"),IF(VLOOKUP(J$1,INDIRECT("'"&$A4&"'!$A$12:$Z$19"),MATCH("Points (Auto-generate)",INDIRECT("'"&$A4&"'!$A$12:$Z$12"),0),0)="","?",VLOOKUP(J$1,INDIRECT("'"&$A4&"'!$A$12:$Z$19"),MATCH("Points (Auto-generate)",INDIRECT("'"&$A4&"'!$A$12:$Z$12"),0),0)),"ER")) | K4: =IF($F4=0,"NA",IF($A4=INDIRECT("'"&$A4&"'!$B$1"),IF(VLOOKUP(K$1,INDIRECT("'"&$A4&"'!$A$12:$Z$19"),MATCH("Points (Auto-generate)",INDIRECT("'"&$A4&"'!$A$12:$Z$12"),0),0)="","?",VLOOKUP(K$1,INDIRECT("'"&$A4&"'!$A$12:$Z$19"),MATCH("Points (Auto-generate)",INDIRECT("'"&$A4&"'!$A$12:$Z$12"),0),0)),"ER")) | L4: =IF($F4=0,"NA",IF($A4=INDIRECT("'"&$A4&"'!$B$1"),IF(VLOOKUP(L$1,INDIRECT("'"&$A4&"'!$A$12:$Z$19"),MATCH("Points (Auto-generate)",INDIRECT("'"&$A4&"'!$A$12:$Z$12"),0),0)="","?",VLOOKUP(L$1,INDIRECT("'"&$A4&"'!$A$12:$Z$19"),MATCH("Points (Auto-generate)",INDIRECT("'"&$A4&"'!$A$12:$Z$12"),0),0)),"ER")) | M4: =IF($F4=0,"NA",IF($A4=INDIRECT("'"&$A4&"'!$B$1"),IF(VLOOKUP(M$1,INDIRECT("'"&$A4&"'!$A$12:$Z$19"),MATCH("Points (Auto-generate)",INDIRECT("'"&$A4&"'!$A$12:$Z$12"),0),0)="","?",VLOOKUP(M$1,INDIRECT("'"&$A4&"'!$A$12:$Z$19"),MATCH("Points (Auto-generate)",INDIRECT("'"&$A4&"'!$A$12:$Z$12"),0),0)),"ER"))
A5: UPD1b | B5: =VLOOKUP($A5,'PARASTATAL Questions'!$A:$J,3,0)&"" | C5: =VLOOKUP($A5,'PARASTATAL Questions'!$A:$J,4,0)&"" | D5: =VLOOKUP($A5,'PARASTATAL Questions'!$A:$J,5,0)&"" | E5: =VLOOKUP($A5,'PARASTATAL Questions'!$A:$J,7,0)&"" | F5: =VLOOKUP($A5,'PARASTATAL Questions'!$A:$J,6,0) | G5: =IF($F5=0,"NA",IF($A5=INDIRECT("'"&$A5&"'!$B$1"),IF(VLOOKUP(G$1,INDIRECT("'"&$A5&"'!$A$12:$Z$19"),MATCH("Points (Auto-generate)",INDIRECT("'"&$A5&"'!$A$12:$Z$12"),0),0)="","?",VLOOKUP(G$1,INDIRECT("'"&$A5&"'!$A$12:$Z$19"),MATCH("Points (Auto-generate)",INDIRECT("'"&$A5&"'!$A$12:$Z$12"),0),0)),"ER")) | H5: =IF($F5=0,"NA",IF($A5=INDIRECT("'"&$A5&"'!$B$1"),IF(VLOOKUP(H$1,INDIRECT("'"&$A5&"'!$A$12:$Z$19"),MATCH("Points (Auto-generate)",INDIRECT("'"&$A5&"'!$A$12:$Z$12"),0),0)="","?",VLOOKUP(H$1,INDIRECT("'"&$A5&"'!$A$12:$Z$19"),MATCH("Points (Auto-generate)",INDIRECT("'"&$A5&"'!$A$12:$Z$12"),0),0)),"ER")) | I5: =IF($F5=0,"NA",IF($A5=INDIRECT("'"&$A5&"'!$B$1"),IF(VLOOKUP(I$1,INDIRECT("'"&$A5&"'!$A$12:$Z$19"),MATCH("Points (Auto-generate)",INDIRECT("'"&$A5&"'!$A$12:$Z$12"),0),0)="","?",VLOOKUP(I$1,INDIRECT("'"&$A5&"'!$A$12:$Z$19"),MATCH("Points (Auto-generate)",INDIRECT("'"&$A5&"'!$A$12:$Z$12"),0),0)),"ER")) | J5: =IF($F5=0,"NA",IF($A5=INDIRECT("'"&$A5&"'!$B$1"),IF(VLOOKUP(J$1,INDIRECT("'"&$A5&"'!$A$12:$Z$19"),MATCH("Points (Auto-generate)",INDIRECT("'"&$A5&"'!$A$12:$Z$12"),0),0)="","?",VLOOKUP(J$1,INDIRECT("'"&$A5&"'!$A$12:$Z$19"),MATCH("Points (Auto-generate)",INDIRECT("'"&$A5&"'!$A$12:$Z$12"),0),0)),"ER")) | K5: =IF($F5=0,"NA",IF($A5=INDIRECT("'"&$A5&"'!$B$1"),IF(VLOOKUP(K$1,INDIRECT("'"&$A5&"'!$A$12:$Z$19"),MATCH("Points (Auto-generate)",INDIRECT("'"&$A5&"'!$A$12:$Z$12"),0),0)="","?",VLOOKUP(K$1,INDIRECT("'"&$A5&"'!$A$12:$Z$19"),MATCH("Points (Auto-generate)",INDIRECT("'"&$A5&"'!$A$12:$Z$12"),0),0)),"ER")) | L5: =IF($F5=0,"NA",IF($A5=INDIRECT("'"&$A5&"'!$B$1"),IF(VLOOKUP(L$1,INDIRECT("'"&$A5&"'!$A$12:$Z$19"),MATCH("Points (Auto-generate)",INDIRECT("'"&$A5&"'!$A$12:$Z$12"),0),0)="","?",VLOOKUP(L$1,INDIRECT("'"&$A5&"'!$A$12:$Z$19"),MATCH("Points (Auto-generate)",INDIRECT("'"&$A5&"'!$A$12:$Z$12"),0),0)),"ER")) | M5: =IF($F5=0,"NA",IF($A5=INDIRECT("'"&$A5&"'!$B$1"),IF(VLOOKUP(M$1,INDIRECT("'"&$A5&"'!$A$12:$Z$19"),MATCH("Points (Auto-generate)",INDIRECT("'"&$A5&"'!$A$12:$Z$12"),0),0)="","?",VLOOKUP(M$1,INDIRECT("'"&$A5&"'!$A$12:$Z$19"),MATCH("Points (Auto-generate)",INDIRECT("'"&$A5&"'!$A$12:$Z$12"),0),0)),"ER"))
A6: UPD2 | B6: =VLOOKUP($A6,'PARASTATAL Questions'!$A:$J,3,0)&"" | C6: =VLOOKUP($A6,'PARASTATAL Questions'!$A:$J,4,0)&"" | D6: =VLOOKUP($A6,'PARASTATAL Questions'!$A:$J,5,0)&"" | E6: =VLOOKUP($A6,'PARASTATAL Questions'!$A:$J,7,0)&"" | F6: =VLOOKUP($A6,'PARASTATAL Questions'!$A:$J,6,0) | G6: =IF(OR(G7="ER",G8="ER",G9="ER",G10="ER"),"ER",IF(OR(G7="?",G8="?",G9="?",G10="?"),"?",IF(AND(G7="NA",G8="NA",G9="NA",G10="NA"),"NA",SUM(G7,G8,G9,G10)/((G7<>"NA")*$F$7+(G8<>"NA")*$F$8+(G9<>"NA")*$F$9+(G10<>"NA")*$F$10)*$F6))) | H6: =IF(OR(H7="ER",H8="ER",H9="ER",H10="ER"),"ER",IF(OR(H7="?",H8="?",H9="?",H10="?"),"?",IF(AND(H7="NA",H8="NA",H9="NA",H10="NA"),"NA",SUM(H7,H8,H9,H10)/((H7<>"NA")*$F$7+(H8<>"NA")*$F$8+(H9<>"NA")*$F$9+(H10<>"NA")*$F$10)*$F6))) | I6: =IF(OR(I7="ER",I8="ER",I9="ER",I10="ER"),"ER",IF(OR(I7="?",I8="?",I9="?",I10="?"),"?",IF(AND(I7="NA",I8="NA",I9="NA",I10="NA"),"NA",SUM(I7,I8,I9,I10)/((I7<>"NA")*$F$7+(I8<>"NA")*$F$8+(I9<>"NA")*$F$9+(I10<>"NA")*$F$10)*$F6))) | J6: =IF(OR(J7="ER",J8="ER",J9="ER",J10="ER"),"ER",IF(OR(J7="?",J8="?",J9="?",J10="?"),"?",IF(AND(J7="NA",J8="NA",J9="NA",J10="NA"),"NA",SUM(J7,J8,J9,J10)/((J7<>"NA")*$F$7+(J8<>"NA")*$F$8+(J9<>"NA")*$F$9+(J10<>"NA")*$F$10)*$F6))) | K6: =IF(OR(K7="ER",K8="ER",K9="ER",K10="ER"),"ER",IF(OR(K7="?",K8="?",K9="?",K10="?"),"?",IF(AND(K7="NA",K8="NA",K9="NA",K10="NA"),"NA",SUM(K7,K8,K9,K10)/((K7<>"NA")*$F$7+(K8<>"NA")*$F$8+(K9<>"NA")*$F$9+(K10<>"NA")*$F$10)*$F6))) | L6: =IF(OR(L7="ER",L8="ER",L9="ER",L10="ER"),"ER",IF(OR(L7="?",L8="?",L9="?",L10="?"),"?",IF(AND(L7="NA",L8="NA",L9="NA",L10="NA"),"NA",SUM(L7,L8,L9,L10)/((L7<>"NA")*$F$7+(L8<>"NA")*$F$8+(L9<>"NA")*$F$9+(L10<>"NA")*$F$10)*$F6))) | M6: =IF(OR(M7="ER",M8="ER",M9="ER",M10="ER"),"ER",IF(OR(M7="?",M8="?",M9="?",M10="?"),"?",IF(AND(M7="NA",M8="NA",M9="NA",M10="NA"),"NA",SUM(M7,M8,M9,M10)/((M7<>"NA")*$F$7+(M8<>"NA")*$F$8+(M9<>"NA")*$F$9+(M10<>"NA")*$F$10)*$F6)))
A7: UPD2a | B7: =VLOOKUP($A7,'PARASTATAL Questions'!$A:$J,3,0)&"" | C7: =VLOOKUP($A7,'PARASTATAL Questions'!$A:$J,4,0)&"" | D7: =VLOOKUP($A7,'PARASTATAL Questions'!$A:$J,5,0)&"" | E7: =VLOOKUP($A7,'PARASTATAL Questions'!$A:$J,7,0)&"" | F7: =VLOOKUP($A7,'PARASTATAL Questions'!$A:$J,6,0) | G7: =IF($F7=0,"NA",IF($A7=INDIRECT("'"&$A7&"'!$B$1"),IF(VLOOKUP(G$1,INDIRECT("'"&$A7&"'!$A$12:$Z$19"),MATCH("Points (Auto-generate)",INDIRECT("'"&$A7&"'!$A$12:$Z$12"),0),0)="","?",VLOOKUP(G$1,INDIRECT("'"&$A7&"'!$A$12:$Z$19"),MATCH("Points (Auto-generate)",INDIRECT("'"&$A7&"'!$A$12:$Z$12"),0),0)),"ER")) | H7: =IF($F7=0,"NA",IF($A7=INDIRECT("'"&$A7&"'!$B$1"),IF(VLOOKUP(H$1,INDIRECT("'"&$A7&"'!$A$12:$Z$19"),MATCH("Points (Auto-generate)",INDIRECT("'"&$A7&"'!$A$12:$Z$12"),0),0)="","?",VLOOKUP(H$1,INDIRECT("'"&$A7&"'!$A$12:$Z$19"),MATCH("Points (Auto-generate)",INDIRECT("'"&$A7&"'!$A$12:$Z$12"),0),0)),"ER")) | I7: =IF($F7=0,"NA",IF($A7=INDIRECT("'"&$A7&"'!$B$1"),IF(VLOOKUP(I$1,INDIRECT("'"&$A7&"'!$A$12:$Z$19"),MATCH("Points (Auto-generate)",INDIRECT("'"&$A7&"'!$A$12:$Z$12"),0),0)="","?",VLOOKUP(I$1,INDIRECT("'"&$A7&"'!$A$12:$Z$19"),MATCH("Points (Auto-generate)",INDIRECT("'"&$A7&"'!$A$12:$Z$12"),0),0)),"ER")) | J7: =IF($F7=0,"NA",IF($A7=INDIRECT("'"&$A7&"'!$B$1"),IF(VLOOKUP(J$1,INDIRECT("'"&$A7&"'!$A$12:$Z$19"),MATCH("Points (Auto-generate)",INDIRECT("'"&$A7&"'!$A$12:$Z$12"),0),0)="","?",VLOOKUP(J$1,INDIRECT("'"&$A7&"'!$A$12:$Z$19"),MATCH("Points (Auto-generate)",INDIRECT("'"&$A7&"'!$A$12:$Z$12"),0),0)),"ER")) | K7: =IF($F7=0,"NA",IF($A7=INDIRECT("'"&$A7&"'!$B$1"),IF(VLOOKUP(K$1,INDIRECT("'"&$A7&"'!$A$12:$Z$19"),MATCH("Points (Auto-generate)",INDIRECT("'"&$A7&"'!$A$12:$Z$12"),0),0)="","?",VLOOKUP(K$1,INDIRECT("'"&$A7&"'!$A$12:$Z$19"),MATCH("Points (Auto-generate)",INDIRECT("'"&$A7&"'!$A$12:$Z$12"),0),0)),"ER")) | L7: =IF($F7=0,"NA",IF($A7=INDIRECT("'"&$A7&"'!$B$1"),IF(VLOOKUP(L$1,INDIRECT("'"&$A7&"'!$A$12:$Z$19"),MATCH("Points (Auto-generate)",INDIRECT("'"&$A7&"'!$A$12:$Z$12"),0),0)="","?",VLOOKUP(L$1,INDIRECT("'"&$A7&"'!$A$12:$Z$19"),MATCH("Points (Auto-generate)",INDIRECT("'"&$A7&"'!$A$12:$Z$12"),0),0)),"ER")) | M7: =IF($F7=0,"NA",IF($A7=INDIRECT("'"&$A7&"'!$B$1"),IF(VLOOKUP(M$1,INDIRECT("'"&$A7&"'!$A$12:$Z$19"),MATCH("Points (Auto-generate)",INDIRECT("'"&$A7&"'!$A$12:$Z$12"),0),0)="","?",VLOOKUP(M$1,INDIRECT("'"&$A7&"'!$A$12:$Z$19"),MATCH("Points (Auto-generate)",INDIRECT("'"&$A7&"'!$A$12:$Z$12"),0),0)),"ER"))
A8: UPD2b | B8: =VLOOKUP($A8,'PARASTATAL Questions'!$A:$J,3,0)&"" | C8: =VLOOKUP($A8,'PARASTATAL Questions'!$A:$J,4,0)&"" | D8: =VLOOKUP($A8,'PARASTATAL Questions'!$A:$J,5,0)&"" | E8: =VLOOKUP($A8,'PARASTATAL Questions'!$A:$J,7,0)&"" | F8: =VLOOKUP($A8,'PARASTATAL Questions'!$A:$J,6,0) | G8: =IF($F8=0,"NA",IF($A8=INDIRECT("'"&$A8&"'!$B$1"),IF(VLOOKUP(G$1,INDIRECT("'"&$A8&"'!$A$12:$Z$19"),MATCH("Points (Auto-generate)",INDIRECT("'"&$A8&"'!$A$12:$Z$12"),0),0)="","?",VLOOKUP(G$1,INDIRECT("'"&$A8&"'!$A$12:$Z$19"),MATCH("Points (Auto-generate)",INDIRECT("'"&$A8&"'!$A$12:$Z$12"),0),0)),"ER")) | H8: =IF($F8=0,"NA",IF($A8=INDIRECT("'"&$A8&"'!$B$1"),IF(VLOOKUP(H$1,INDIRECT("'"&$A8&"'!$A$12:$Z$19"),MATCH("Points (Auto-generate)",INDIRECT("'"&$A8&"'!$A$12:$Z$12"),0),0)="","?",VLOOKUP(H$1,INDIRECT("'"&$A8&"'!$A$12:$Z$19"),MATCH("Points (Auto-generate)",INDIRECT("'"&$A8&"'!$A$12:$Z$12"),0),0)),"ER")) | I8: =IF($F8=0,"NA",IF($A8=INDIRECT("'"&$A8&"'!$B$1"),IF(VLOOKUP(I$1,INDIRECT("'"&$A8&"'!$A$12:$Z$19"),MATCH("Points (Auto-generate)",INDIRECT("'"&$A8&"'!$A$12:$Z$12"),0),0)="","?",VLOOKUP(I$1,INDIRECT("'"&$A8&"'!$A$12:$Z$19"),MATCH("Points (Auto-generate)",INDIRECT("'"&$A8&"'!$A$12:$Z$12"),0),0)),"ER")) | J8: =IF($F8=0,"NA",IF($A8=INDIRECT("'"&$A8&"'!$B$1"),IF(VLOOKUP(J$1,INDIRECT("'"&$A8&"'!$A$12:$Z$19"),MATCH("Points (Auto-generate)",INDIRECT("'"&$A8&"'!$A$12:$Z$12"),0),0)="","?",VLOOKUP(J$1,INDIRECT("'"&$A8&"'!$A$12:$Z$19"),MATCH("Points (Auto-generate)",INDIRECT("'"&$A8&"'!$A$12:$Z$12"),0),0)),"ER")) | K8: =IF($F8=0,"NA",IF($A8=INDIRECT("'"&$A8&"'!$B$1"),IF(VLOOKUP(K$1,INDIRECT("'"&$A8&"'!$A$12:$Z$19"),MATCH("Points (Auto-generate)",INDIRECT("'"&$A8&"'!$A$12:$Z$12"),0),0)="","?",VLOOKUP(K$1,INDIRECT("'"&$A8&"'!$A$12:$Z$19"),MATCH("Points (Auto-generate)",INDIRECT("'"&$A8&"'!$A$12:$Z$12"),0),0)),"ER")) | L8: =IF($F8=0,"NA",IF($A8=INDIRECT("'"&$A8&"'!$B$1"),IF(VLOOKUP(L$1,INDIRECT("'"&$A8&"'!$A$12:$Z$19"),MATCH("Points (Auto-generate)",INDIRECT("'"&$A8&"'!$A$12:$Z$12"),0),0)="","?",VLOOKUP(L$1,INDIRECT("'"&$A8&"'!$A$12:$Z$19"),MATCH("Points (Auto-generate)",INDIRECT("'"&$A8&"'!$A$12:$Z$12"),0),0)),"ER")) | M8: =IF($F8=0,"NA",IF($A8=INDIRECT("'"&$A8&"'!$B$1"),IF(VLOOKUP(M$1,INDIRECT("'"&$A8&"'!$A$12:$Z$19"),MATCH("Points (Auto-generate)",INDIRECT("'"&$A8&"'!$A$12:$Z$12"),0),0)="","?",VLOOKUP(M$1,INDIRECT("'"&$A8&"'!$A$12:$Z$19"),MATCH("Points (Auto-generate)",INDIRECT("'"&$A8&"'!$A$12:$Z$12"),0),0)),"ER"))
A9: UPD2c | B9: =VLOOKUP($A9,'PARASTATAL Questions'!$A:$J,3,0)&"" | C9: =VLOOKUP($A9,'PARASTATAL Questions'!$A:$J,4,0)&"" | D9: =VLOOKUP($A9,'PARASTATAL Questions'!$A:$J,5,0)&"" | E9: =VLOOKUP($A9,'PARASTATAL Questions'!$A:$J,7,0)&"" | F9: =VLOOKUP($A9,'PARASTATAL Questions'!$A:$J,6,0) | G9: =IF($F9=0,"NA",IF($A9=INDIRECT("'"&$A9&"'!$B$1"),IF(VLOOKUP(G$1,INDIRECT("'"&$A9&"'!$A$12:$Z$19"),MATCH("Points (Auto-generate)",INDIRECT("'"&$A9&"'!$A$12:$Z$12"),0),0)="","?",VLOOKUP(G$1,INDIRECT("'"&$A9&"'!$A$12:$Z$19"),MATCH("Points (Auto-generate)",INDIRECT("'"&$A9&"'!$A$12:$Z$12"),0),0)),"ER")) | H9: =IF($F9=0,"NA",IF($A9=INDIRECT("'"&$A9&"'!$B$1"),IF(VLOOKUP(H$1,INDIRECT("'"&$A9&"'!$A$12:$Z$19"),MATCH("Points (Auto-generate)",INDIRECT("'"&$A9&"'!$A$12:$Z$12"),0),0)="","?",VLOOKUP(H$1,INDIRECT("'"&$A9&"'!$A$12:$Z$19"),MATCH("Points (Auto-generate)",INDIRECT("'"&$A9&"'!$A$12:$Z$12"),0),0)),"ER")) | I9: =IF($F9=0,"NA",IF($A9=INDIRECT("'"&$A9&"'!$B$1"),IF(VLOOKUP(I$1,INDIRECT("'"&$A9&"'!$A$12:$Z$19"),MATCH("Points (Auto-generate)",INDIRECT("'"&$A9&"'!$A$12:$Z$12"),0),0)="","?",VLOOKUP(I$1,INDIRECT("'"&$A9&"'!$A$12:$Z$19"),MATCH("Points (Auto-generate)",INDIRECT("'"&$A9&"'!$A$12:$Z$12"),0),0)),"ER")) | J9: =IF($F9=0,"NA",IF($A9=INDIRECT("'"&$A9&"'!$B$1"),IF(VLOOKUP(J$1,INDIRECT("'"&$A9&"'!$A$12:$Z$19"),MATCH("Points (Auto-generate)",INDIRECT("'"&$A9&"'!$A$12:$Z$12"),0),0)="","?",VLOOKUP(J$1,INDIRECT("'"&$A9&"'!$A$12:$Z$19"),MATCH("Points (Auto-generate)",INDIRECT("'"&$A9&"'!$A$12:$Z$12"),0),0)),"ER")) | K9: =IF($F9=0,"NA",IF($A9=INDIRECT("'"&$A9&"'!$B$1"),IF(VLOOKUP(K$1,INDIRECT("'"&$A9&"'!$A$12:$Z$19"),MATCH("Points (Auto-generate)",INDIRECT("'"&$A9&"'!$A$12:$Z$12"),0),0)="","?",VLOOKUP(K$1,INDIRECT("'"&$A9&"'!$A$12:$Z$19"),MATCH("Points (Auto-generate)",INDIRECT("'"&$A9&"'!$A$12:$Z$12"),0),0)),"ER")) | L9: =IF($F9=0,"NA",IF($A9=INDIRECT("'"&$A9&"'!$B$1"),IF(VLOOKUP(L$1,INDIRECT("'"&$A9&"'!$A$12:$Z$19"),MATCH("Points (Auto-generate)",INDIRECT("'"&$A9&"'!$A$12:$Z$12"),0),0)="","?",VLOOKUP(L$1,INDIRECT("'"&$A9&"'!$A$12:$Z$19"),MATCH("Points (Auto-generate)",INDIRECT("'"&$A9&"'!$A$12:$Z$12"),0),0)),"ER")) | M9: =IF($F9=0,"NA",IF($A9=INDIRECT("'"&$A9&"'!$B$1"),IF(VLOOKUP(M$1,INDIRECT("'"&$A9&"'!$A$12:$Z$19"),MATCH("Points (Auto-generate)",INDIRECT("'"&$A9&"'!$A$12:$Z$12"),0),0)="","?",VLOOKUP(M$1,INDIRECT("'"&$A9&"'!$A$12:$Z$19"),MATCH("Points (Auto-generate)",INDIRECT("'"&$A9&"'!$A$12:$Z$12"),0),0)),"ER"))
A10: UPD2d | B10: =VLOOKUP($A10,'PARASTATAL Questions'!$A:$J,3,0)&"" | C10: =VLOOKUP($A10,'PARASTATAL Questions'!$A:$J,4,0)&"" | D10: =VLOOKUP($A10,'PARASTATAL Questions'!$A:$J,5,0)&"" | E10: =VLOOKUP($A10,'PARASTATAL Questions'!$A:$J,7,0)&"" | F10: =VLOOKUP($A10,'PARASTATAL Questions'!$A:$J,6,0) | G10: =IF($F10=0,"NA",IF($A10=INDIRECT("'"&$A10&"'!$B$1"),IF(VLOOKUP(G$1,INDIRECT("'"&$A10&"'!$A$12:$Z$19"),MATCH("Points (Auto-generate)",INDIRECT("'"&$A10&"'!$A$12:$Z$12"),0),0)="","?",VLOOKUP(G$1,INDIRECT("'"&$A10&"'!$A$12:$Z$19"),MATCH("Points (Auto-generate)",INDIRECT("'"&$A10&"'!$A$12:$Z$12"),0),0)),"ER")) | H10: =IF($F10=0,"NA",IF($A10=INDIRECT("'"&$A10&"'!$B$1"),IF(VLOOKUP(H$1,INDIRECT("'"&$A10&"'!$A$12:$Z$19"),MATCH("Points (Auto-generate)",INDIRECT("'"&$A10&"'!$A$12:$Z$12"),0),0)="","?",VLOOKUP(H$1,INDIRECT("'"&$A10&"'!$A$12:$Z$19"),MATCH("Points (Auto-generate)",INDIRECT("'"&$A10&"'!$A$12:$Z$12"),0),0)),"ER")) | I10: =IF($F10=0,"NA",IF($A10=INDIRECT("'"&$A10&"'!$B$1"),IF(VLOOKUP(I$1,INDIRECT("'"&$A10&"'!$A$12:$Z$19"),MATCH("Points (Auto-generate)",INDIRECT("'"&$A10&"'!$A$12:$Z$12"),0),0)="","?",VLOOKUP(I$1,INDIRECT("'"&$A10&"'!$A$12:$Z$19"),MATCH("Points (Auto-generate)",INDIRECT("'"&$A10&"'!$A$12:$Z$12"),0),0)),"ER")) | J10: =IF($F10=0,"NA",IF($A10=INDIRECT("'"&$A10&"'!$B$1"),IF(VLOOKUP(J$1,INDIRECT("'"&$A10&"'!$A$12:$Z$19"),MATCH("Points (Auto-generate)",INDIRECT("'"&$A10&"'!$A$12:$Z$12"),0),0)="","?",VLOOKUP(J$1,INDIRECT("'"&$A10&"'!$A$12:$Z$19"),MATCH("Points (Auto-generate)",INDIRECT("'"&$A10&"'!$A$12:$Z$12"),0),0)),"ER")) | K10: =IF($F10=0,"NA",IF($A10=INDIRECT("'"&$A10&"'!$B$1"),IF(VLOOKUP(K$1,INDIRECT("'"&$A10&"'!$A$12:$Z$19"),MATCH("Points (Auto-generate)",INDIRECT("'"&$A10&"'!$A$12:$Z$12"),0),0)="","?",VLOOKUP(K$1,INDIRECT("'"&$A10&"'!$A$12:$Z$19"),MATCH("Points (Auto-generate)",INDIRECT("'"&$A10&"'!$A$12:$Z$12"),0),0)),"ER")) | L10: =IF($F10=0,"NA",IF($A10=INDIRECT("'"&$A10&"'!$B$1"),IF(VLOOKUP(L$1,INDIRECT("'"&$A10&"'!$A$12:$Z$19"),MATCH("Points (Auto-generate)",INDIRECT("'"&$A10&"'!$A$12:$Z$12"),0),0)="","?",VLOOKUP(L$1,INDIRECT("'"&$A10&"'!$A$12:$Z$19"),MATCH("Points (Auto-generate)",INDIRECT("'"&$A10&"'!$A$12:$Z$12"),0),0)),"ER")) | M10: =IF($F10=0,"NA",IF($A10=INDIRECT("'"&$A10&"'!$B$1"),IF(VLOOKUP(M$1,INDIRECT("'"&$A10&"'!$A$12:$Z$19"),MATCH("Points (Auto-generate)",INDIRECT("'"&$A10&"'!$A$12:$Z$12"),0),0)="","?",VLOOKUP(M$1,INDIRECT("'"&$A10&"'!$A$12:$Z$19"),MATCH("Points (Auto-generate)",INDIRECT("'"&$A10&"'!$A$12:$Z$12"),0),0)),"ER"))
A11: UPD3 | B11: =VLOOKUP($A11,'PARASTATAL Questions'!$A:$J,3,0)&"" | C11: =VLOOKUP($A11,'PARASTATAL Questions'!$A:$J,4,0)&"" | D11: =VLOOKUP($A11,'PARASTATAL Questions'!$A:$J,5,0)&"" | E11: =VLOOKUP($A11,'PARASTATAL Questions'!$A:$J,7,0)&"" | F11: =VLOOKUP($A11,'PARASTATAL Questions'!$A:$J,6,0) | G11: =IF(OR(G12="ER",G13="ER"),"ER",IF(OR(G12="?",G13="?"),"?",IF(AND(G12="NA",G13="NA"),"NA",SUM(G12,G13)/((G12<>"NA")*$F$12+(G13<>"NA")*$F$13)*$F11))) | H11: =IF(OR(H12="ER",H13="ER"),"ER",IF(OR(H12="?",H13="?"),"?",IF(AND(H12="NA",H13="NA"),"NA",SUM(H12,H13)/((H12<>"NA")*$F$12+(H13<>"NA")*$F$13)*$F11))) | I11: =IF(OR(I12="ER",I13="ER"),"ER",IF(OR(I12="?",I13="?"),"?",IF(AND(I12="NA",I13="NA"),"NA",SUM(I12,I13)/((I12<>"NA")*$F$12+(I13<>"NA")*$F$13)*$F11))) | J11: =IF(OR(J12="ER",J13="ER"),"ER",IF(OR(J12="?",J13="?"),"?",IF(AND(J12="NA",J13="NA"),"NA",SUM(J12,J13)/((J12<>"NA")*$F$12+(J13<>"NA")*$F$13)*$F11))) | K11: =IF(OR(K12="ER",K13="ER"),"ER",IF(OR(K12="?",K13="?"),"?",IF(AND(K12="NA",K13="NA"),"NA",SUM(K12,K13)/((K12<>"NA")*$F$12+(K13<>"NA")*$F$13)*$F11))) | L11: =IF(OR(L12="ER",L13="ER"),"ER",IF(OR(L12="?",L13="?"),"?",IF(AND(L12="NA",L13="NA"),"NA",SUM(L12,L13)/((L12<>"NA")*$F$12+(L13<>"NA")*$F$13)*$F11))) | M11: =IF(OR(M12="ER",M13="ER"),"ER",IF(OR(M12="?",M13="?"),"?",IF(AND(M12="NA",M13="NA"),"NA",SUM(M12,M13)/((M12<>"NA")*$F$12+(M13<>"NA")*$F$13)*$F11)))
A12: UPD3a | B12: =VLOOKUP($A12,'PARASTATAL Questions'!$A:$J,3,0)&"" | C12: =VLOOKUP($A12,'PARASTATAL Questions'!$A:$J,4,0)&"" | D12: =VLOOKUP($A12,'PARASTATAL Questions'!$A:$J,5,0)&"" | E12: =VLOOKUP($A12,'PARASTATAL Questions'!$A:$J,7,0)&"" | F12: =VLOOKUP($A12,'PARASTATAL Questions'!$A:$J,6,0) | G12: =IF($F12=0,"NA",IF($A12=INDIRECT("'"&$A12&"'!$B$1"),IF(VLOOKUP(G$1,INDIRECT("'"&$A12&"'!$A$12:$Z$19"),MATCH("Points (Auto-generate)",INDIRECT("'"&$A12&"'!$A$12:$Z$12"),0),0)="","?",VLOOKUP(G$1,INDIRECT("'"&$A12&"'!$A$12:$Z$19"),MATCH("Points (Auto-generate)",INDIRECT("'"&$A12&"'!$A$12:$Z$12"),0),0)),"ER")) | H12: =IF($F12=0,"NA",IF($A12=INDIRECT("'"&$A12&"'!$B$1"),IF(VLOOKUP(H$1,INDIRECT("'"&$A12&"'!$A$12:$Z$19"),MATCH("Points (Auto-generate)",INDIRECT("'"&$A12&"'!$A$12:$Z$12"),0),0)="","?",VLOOKUP(H$1,INDIRECT("'"&$A12&"'!$A$12:$Z$19"),MATCH("Points (Auto-generate)",INDIRECT("'"&$A12&"'!$A$12:$Z$12"),0),0)),"ER")) | I12: =IF($F12=0,"NA",IF($A12=INDIRECT("'"&$A12&"'!$B$1"),IF(VLOOKUP(I$1,INDIRECT("'"&$A12&"'!$A$12:$Z$19"),MATCH("Points (Auto-generate)",INDIRECT("'"&$A12&"'!$A$12:$Z$12"),0),0)="","?",VLOOKUP(I$1,INDIRECT("'"&$A12&"'!$A$12:$Z$19"),MATCH("Points (Auto-generate)",INDIRECT("'"&$A12&"'!$A$12:$Z$12"),0),0)),"ER")) | J12: =IF($F12=0,"NA",IF($A12=INDIRECT("'"&$A12&"'!$B$1"),IF(VLOOKUP(J$1,INDIRECT("'"&$A12&"'!$A$12:$Z$19"),MATCH("Points (Auto-generate)",INDIRECT("'"&$A12&"'!$A$12:$Z$12"),0),0)="","?",VLOOKUP(J$1,INDIRECT("'"&$A12&"'!$A$12:$Z$19"),MATCH("Points (Auto-generate)",INDIRECT("'"&$A12&"'!$A$12:$Z$12"),0),0)),"ER")) | K12: =IF($F12=0,"NA",IF($A12=INDIRECT("'"&$A12&"'!$B$1"),IF(VLOOKUP(K$1,INDIRECT("'"&$A12&"'!$A$12:$Z$19"),MATCH("Points (Auto-generate)",INDIRECT("'"&$A12&"'!$A$12:$Z$12"),0),0)="","?",VLOOKUP(K$1,INDIRECT("'"&$A12&"'!$A$12:$Z$19"),MATCH("Points (Auto-generate)",INDIRECT("'"&$A12&"'!$A$12:$Z$12"),0),0)),"ER")) | L12: =IF($F12=0,"NA",IF($A12=INDIRECT("'"&$A12&"'!$B$1"),IF(VLOOKUP(L$1,INDIRECT("'"&$A12&"'!$A$12:$Z$19"),MATCH("Points (Auto-generate)",INDIRECT("'"&$A12&"'!$A$12:$Z$12"),0),0)="","?",VLOOKUP(L$1,INDIRECT("'"&$A12&"'!$A$12:$Z$19"),MATCH("Points (Auto-generate)",INDIRECT("'"&$A12&"'!$A$12:$Z$12"),0),0)),"ER")) | M12: =IF($F12=0,"NA",IF($A12=INDIRECT("'"&$A12&"'!$B$1"),IF(VLOOKUP(M$1,INDIRECT("'"&$A12&"'!$A$12:$Z$19"),MATCH("Points (Auto-generate)",INDIRECT("'"&$A12&"'!$A$12:$Z$12"),0),0)="","?",VLOOKUP(M$1,INDIRECT("'"&$A12&"'!$A$12:$Z$19"),MATCH("Points (Auto-generate)",INDIRECT("'"&$A12&"'!$A$12:$Z$12"),0),0)),"ER"))
A13: UPD3b | B13: =VLOOKUP($A13,'PARASTATAL Questions'!$A:$J,3,0)&"" | C13: =VLOOKUP($A13,'PARASTATAL Questions'!$A:$J,4,0)&"" | D13: =VLOOKUP($A13,'PARASTATAL Questions'!$A:$J,5,0)&"" | E13: =VLOOKUP($A13,'PARASTATAL Questions'!$A:$J,7,0)&"" | F13: =VLOOKUP($A13,'PARASTATAL Questions'!$A:$J,6,0) | G13: =IF($F13=0,"NA",IF($A13=INDIRECT("'"&$A13&"'!$B$1"),IF(VLOOKUP(G$1,INDIRECT("'"&$A13&"'!$A$12:$Z$19"),MATCH("Points (Auto-generate)",INDIRECT("'"&$A13&"'!$A$12:$Z$12"),0),0)="","?",VLOOKUP(G$1,INDIRECT("'"&$A13&"'!$A$12:$Z$19"),MATCH("Points (Auto-generate)",INDIRECT("'"&$A13&"'!$A$12:$Z$12"),0),0)),"ER")) | H13: =IF($F13=0,"NA",IF($A13=INDIRECT("'"&$A13&"'!$B$1"),IF(VLOOKUP(H$1,INDIRECT("'"&$A13&"'!$A$12:$Z$19"),MATCH("Points (Auto-generate)",INDIRECT("'"&$A13&"'!$A$12:$Z$12"),0),0)="","?",VLOOKUP(H$1,INDIRECT("'"&$A13&"'!$A$12:$Z$19"),MATCH("Points (Auto-generate)",INDIRECT("'"&$A13&"'!$A$12:$Z$12"),0),0)),"ER")) | I13: =IF($F13=0,"NA",IF($A13=INDIRECT("'"&$A13&"'!$B$1"),IF(VLOOKUP(I$1,INDIRECT("'"&$A13&"'!$A$12:$Z$19"),MATCH("Points (Auto-generate)",INDIRECT("'"&$A13&"'!$A$12:$Z$12"),0),0)="","?",VLOOKUP(I$1,INDIRECT("'"&$A13&"'!$A$12:$Z$19"),MATCH("Points (Auto-generate)",INDIRECT("'"&$A13&"'!$A$12:$Z$12"),0),0)),"ER")) | J13: =IF($F13=0,"NA",IF($A13=INDIRECT("'"&$A13&"'!$B$1"),IF(VLOOKUP(J$1,INDIRECT("'"&$A13&"'!$A$12:$Z$19"),MATCH("Points (Auto-generate)",INDIRECT("'"&$A13&"'!$A$12:$Z$12"),0),0)="","?",VLOOKUP(J$1,INDIRECT("'"&$A13&"'!$A$12:$Z$19"),MATCH("Points (Auto-generate)",INDIRECT("'"&$A13&"'!$A$12:$Z$12"),0),0)),"ER")) | K13: =IF($F13=0,"NA",IF($A13=INDIRECT("'"&$A13&"'!$B$1"),IF(VLOOKUP(K$1,INDIRECT("'"&$A13&"'!$A$12:$Z$19"),MATCH("Points (Auto-generate)",INDIRECT("'"&$A13&"'!$A$12:$Z$12"),0),0)="","?",VLOOKUP(K$1,INDIRECT("'"&$A13&"'!$A$12:$Z$19"),MATCH("Points (Auto-generate)",INDIRECT("'"&$A13&"'!$A$12:$Z$12"),0),0)),"ER")) | L13: =IF($F13=0,"NA",IF($A13=INDIRECT("'"&$A13&"'!$B$1"),IF(VLOOKUP(L$1,INDIRECT("'"&$A13&"'!$A$12:$Z$19"),MATCH("Points (Auto-generate)",INDIRECT("'"&$A13&"'!$A$12:$Z$12"),0),0)="","?",VLOOKUP(L$1,INDIRECT("'"&$A13&"'!$A$12:$Z$19"),MATCH("Points (Auto-generate)",INDIRECT("'"&$A13&"'!$A$12:$Z$12"),0),0)),"ER")) | M13: =IF($F13=0,"NA",IF($A13=INDIRECT("'"&$A13&"'!$B$1"),IF(VLOOKUP(M$1,INDIRECT("'"&$A13&"'!$A$12:$Z$19"),MATCH("Points (Auto-generate)",INDIRECT("'"&$A13&"'!$A$12:$Z$12"),0),0)="","?",VLOOKUP(M$1,INDIRECT("'"&$A13&"'!$A$12:$Z$19"),MATCH("Points (Auto-generate)",INDIRECT("'"&$A13&"'!$A$12:$Z$12"),0),0)),"ER"))
A14: UPD4 | B14: =VLOOKUP($A14,'PARASTATAL Questions'!$A:$J,3,0)&"" | C14: =VLOOKUP($A14,'PARASTATAL Questions'!$A:$J,4,0)&"" | D14: =VLOOKUP($A14,'PARASTATAL Questions'!$A:$J,5,0)&"" | E14: =VLOOKUP($A14,'PARASTATAL Questions'!$A:$J,7,0)&"" | F14: =VLOOKUP($A14,'PARASTATAL Questions'!$A:$J,6,0) | G14: =IF(OR(G15="ER",G16="ER"),"ER",IF(OR(G15="?",G16="?"),"?",IF(AND(G15="NA",G16="NA"),"NA",SUM(G15,G16)/((G15<>"NA")*$F$15+(G16<>"NA")*$F$16)*$F14))) | H14: =IF(OR(H15="ER",H16="ER"),"ER",IF(OR(H15="?",H16="?"),"?",IF(AND(H15="NA",H16="NA"),"NA",SUM(H15,H16)/((H15<>"NA")*$F$15+(H16<>"NA")*$F$16)*$F14))) | I14: =IF(OR(I15="ER",I16="ER"),"ER",IF(OR(I15="?",I16="?"),"?",IF(AND(I15="NA",I16="NA"),"NA",SUM(I15,I16)/((I15<>"NA")*$F$15+(I16<>"NA")*$F$16)*$F14))) | J14: =IF(OR(J15="ER",J16="ER"),"ER",IF(OR(J15="?",J16="?"),"?",IF(AND(J15="NA",J16="NA"),"NA",SUM(J15,J16)/((J15<>"NA")*$F$15+(J16<>"NA")*$F$16)*$F14))) | K14: =IF(OR(K15="ER",K16="ER"),"ER",IF(OR(K15="?",K16="?"),"?",IF(AND(K15="NA",K16="NA"),"NA",SUM(K15,K16)/((K15<>"NA")*$F$15+(K16<>"NA")*$F$16)*$F14))) | L14: =IF(OR(L15="ER",L16="ER"),"ER",IF(OR(L15="?",L16="?"),"?",IF(AND(L15="NA",L16="NA"),"NA",SUM(L15,L16)/((L15<>"NA")*$F$15+(L16<>"NA")*$F$16)*$F14))) | M14: =IF(OR(M15="ER",M16="ER"),"ER",IF(OR(M15="?",M16="?"),"?",IF(AND(M15="NA",M16="NA"),"NA",SUM(M15,M16)/((M15<>"NA")*$F$15+(M16<>"NA")*$F$16)*$F14)))
A15: UPD4a | B15: =VLOOKUP($A15,'PARASTATAL Questions'!$A:$J,3,0)&"" | C15: =VLOOKUP($A15,'PARASTATAL Questions'!$A:$J,4,0)&"" | D15: =VLOOKUP($A15,'PARASTATAL Questions'!$A:$J,5,0)&"" | E15: =VLOOKUP($A15,'PARASTATAL Questions'!$A:$J,7,0)&"" | F15: =VLOOKUP($A15,'PARASTATAL Questions'!$A:$J,6,0) | G15: =IF($F15=0,"NA",IF($A15=INDIRECT("'"&$A15&"'!$B$1"),IF(VLOOKUP(G$1,INDIRECT("'"&$A15&"'!$A$12:$Z$19"),MATCH("Points (Auto-generate)",INDIRECT("'"&$A15&"'!$A$12:$Z$12"),0),0)="","?",VLOOKUP(G$1,INDIRECT("'"&$A15&"'!$A$12:$Z$19"),MATCH("Points (Auto-generate)",INDIRECT("'"&$A15&"'!$A$12:$Z$12"),0),0)),"ER")) | H15: =IF($F15=0,"NA",IF($A15=INDIRECT("'"&$A15&"'!$B$1"),IF(VLOOKUP(H$1,INDIRECT("'"&$A15&"'!$A$12:$Z$19"),MATCH("Points (Auto-generate)",INDIRECT("'"&$A15&"'!$A$12:$Z$12"),0),0)="","?",VLOOKUP(H$1,INDIRECT("'"&$A15&"'!$A$12:$Z$19"),MATCH("Points (Auto-generate)",INDIRECT("'"&$A15&"'!$A$12:$Z$12"),0),0)),"ER")) | I15: =IF($F15=0,"NA",IF($A15=INDIRECT("'"&$A15&"'!$B$1"),IF(VLOOKUP(I$1,INDIRECT("'"&$A15&"'!$A$12:$Z$19"),MATCH("Points (Auto-generate)",INDIRECT("'"&$A15&"'!$A$12:$Z$12"),0),0)="","?",VLOOKUP(I$1,INDIRECT("'"&$A15&"'!$A$12:$Z$19"),MATCH("Points (Auto-generate)",INDIRECT("'"&$A15&"'!$A$12:$Z$12"),0),0)),"ER")) | J15: =IF($F15=0,"NA",IF($A15=INDIRECT("'"&$A15&"'!$B$1"),IF(VLOOKUP(J$1,INDIRECT("'"&$A15&"'!$A$12:$Z$19"),MATCH("Points (Auto-generate)",INDIRECT("'"&$A15&"'!$A$12:$Z$12"),0),0)="","?",VLOOKUP(J$1,INDIRECT("'"&$A15&"'!$A$12:$Z$19"),MATCH("Points (Auto-generate)",INDIRECT("'"&$A15&"'!$A$12:$Z$12"),0),0)),"ER")) | K15: =IF($F15=0,"NA",IF($A15=INDIRECT("'"&$A15&"'!$B$1"),IF(VLOOKUP(K$1,INDIRECT("'"&$A15&"'!$A$12:$Z$19"),MATCH("Points (Auto-generate)",INDIRECT("'"&$A15&"'!$A$12:$Z$12"),0),0)="","?",VLOOKUP(K$1,INDIRECT("'"&$A15&"'!$A$12:$Z$19"),MATCH("Points (Auto-generate)",INDIRECT("'"&$A15&"'!$A$12:$Z$12"),0),0)),"ER")) | L15: =IF($F15=0,"NA",IF($A15=INDIRECT("'"&$A15&"'!$B$1"),IF(VLOOKUP(L$1,INDIRECT("'"&$A15&"'!$A$12:$Z$19"),MATCH("Points (Auto-generate)",INDIRECT("'"&$A15&"'!$A$12:$Z$12"),0),0)="","?",VLOOKUP(L$1,INDIRECT("'"&$A15&"'!$A$12:$Z$19"),MATCH("Points (Auto-generate)",INDIRECT("'"&$A15&"'!$A$12:$Z$12"),0),0)),"ER")) | M15: =IF($F15=0,"NA",IF($A15=INDIRECT("'"&$A15&"'!$B$1"),IF(VLOOKUP(M$1,INDIRECT("'"&$A15&"'!$A$12:$Z$19"),MATCH("Points (Auto-generate)",INDIRECT("'"&$A15&"'!$A$12:$Z$12"),0),0)="","?",VLOOKUP(M$1,INDIRECT("'"&$A15&"'!$A$12:$Z$19"),MATCH("Points (Auto-generate)",INDIRECT("'"&$A15&"'!$A$12:$Z$12"),0),0)),"ER"))
A16: UPD4b | B16: =VLOOKUP($A16,'PARASTATAL Questions'!$A:$J,3,0)&"" | C16: =VLOOKUP($A16,'PARASTATAL Questions'!$A:$J,4,0)&"" | D16: =VLOOKUP($A16,'PARASTATAL Questions'!$A:$J,5,0)&"" | E16: =VLOOKUP($A16,'PARASTATAL Questions'!$A:$J,7,0)&"" | F16: =VLOOKUP($A16,'PARASTATAL Questions'!$A:$J,6,0) | G16: =IF($F16=0,"NA",IF($A16=INDIRECT("'"&$A16&"'!$B$1"),IF(VLOOKUP(G$1,INDIRECT("'"&$A16&"'!$A$12:$Z$19"),MATCH("Points (Auto-generate)",INDIRECT("'"&$A16&"'!$A$12:$Z$12"),0),0)="","?",VLOOKUP(G$1,INDIRECT("'"&$A16&"'!$A$12:$Z$19"),MATCH("Points (Auto-generate)",INDIRECT("'"&$A16&"'!$A$12:$Z$12"),0),0)),"ER")) | H16: =IF($F16=0,"NA",IF($A16=INDIRECT("'"&$A16&"'!$B$1"),IF(VLOOKUP(H$1,INDIRECT("'"&$A16&"'!$A$12:$Z$19"),MATCH("Points (Auto-generate)",INDIRECT("'"&$A16&"'!$A$12:$Z$12"),0),0)="","?",VLOOKUP(H$1,INDIRECT("'"&$A16&"'!$A$12:$Z$19"),MATCH("Points (Auto-generate)",INDIRECT("'"&$A16&"'!$A$12:$Z$12"),0),0)),"ER")) | I16: =IF($F16=0,"NA",IF($A16=INDIRECT("'"&$A16&"'!$B$1"),IF(VLOOKUP(I$1,INDIRECT("'"&$A16&"'!$A$12:$Z$19"),MATCH("Points (Auto-generate)",INDIRECT("'"&$A16&"'!$A$12:$Z$12"),0),0)="","?",VLOOKUP(I$1,INDIRECT("'"&$A16&"'!$A$12:$Z$19"),MATCH("Points (Auto-generate)",INDIRECT("'"&$A16&"'!$A$12:$Z$12"),0),0)),"ER")) | J16: =IF($F16=0,"NA",IF($A16=INDIRECT("'"&$A16&"'!$B$1"),IF(VLOOKUP(J$1,INDIRECT("'"&$A16&"'!$A$12:$Z$19"),MATCH("Points (Auto-generate)",INDIRECT("'"&$A16&"'!$A$12:$Z$12"),0),0)="","?",VLOOKUP(J$1,INDIRECT("'"&$A16&"'!$A$12:$Z$19"),MATCH("Points (Auto-generate)",INDIRECT("'"&$A16&"'!$A$12:$Z$12"),0),0)),"ER")) | K16: =IF($F16=0,"NA",IF($A16=INDIRECT("'"&$A16&"'!$B$1"),IF(VLOOKUP(K$1,INDIRECT("'"&$A16&"'!$A$12:$Z$19"),MATCH("Points (Auto-generate)",INDIRECT("'"&$A16&"'!$A$12:$Z$12"),0),0)="","?",VLOOKUP(K$1,INDIRECT("'"&$A16&"'!$A$12:$Z$19"),MATCH("Points (Auto-generate)",INDIRECT("'"&$A16&"'!$A$12:$Z$12"),0),0)),"ER")) | L16: =IF($F16=0,"NA",IF($A16=INDIRECT("'"&$A16&"'!$B$1"),IF(VLOOKUP(L$1,INDIRECT("'"&$A16&"'!$A$12:$Z$19"),MATCH("Points (Auto-generate)",INDIRECT("'"&$A16&"'!$A$12:$Z$12"),0),0)="","?",VLOOKUP(L$1,INDIRECT("'"&$A16&"'!$A$12:$Z$19"),MATCH("Points (Auto-generate)",INDIRECT("'"&$A16&"'!$A$12:$Z$12"),0),0)),"ER")) | M16: =IF($F16=0,"NA",IF($A16=INDIRECT("'"&$A16&"'!$B$1"),IF(VLOOKUP(M$1,INDIRECT("'"&$A16&"'!$A$12:$Z$19"),MATCH("Points (Auto-generate)",INDIRECT("'"&$A16&"'!$A$12:$Z$12"),0),0)="","?",VLOOKUP(M$1,INDIRECT("'"&$A16&"'!$A$12:$Z$19"),MATCH("Points (Auto-generate)",INDIRECT("'"&$A16&"'!$A$12:$Z$12"),0),0)),"ER"))
A17: UPD5 | B17: =VLOOKUP($A17,'PARASTATAL Questions'!$A:$J,3,0)&"" | C17: =VLOOKUP($A17,'PARASTATAL Questions'!$A:$J,4,0)&"" | D17: =VLOOKUP($A17,'PARASTATAL Questions'!$A:$J,5,0)&"" | E17: =VLOOKUP($A17,'PARASTATAL Questions'!$A:$J,7,0)&"" | F17: =VLOOKUP($A17,'PARASTATAL Questions'!$A:$J,6,0) | G17: =IF(OR(G18="ER",G19="ER"),"ER",IF(OR(G18="?",G19="?"),"?",IF(AND(G18="NA",G19="NA"),"NA",SUM(G18,G19)/((G18<>"NA")*$F$18+(G19<>"NA")*$F$19)*$F17))) | H17: =IF(OR(H18="ER",H19="ER"),"ER",IF(OR(H18="?",H19="?"),"?",IF(AND(H18="NA",H19="NA"),"NA",SUM(H18,H19)/((H18<>"NA")*$F$18+(H19<>"NA")*$F$19)*$F17))) | I17: =IF(OR(I18="ER",I19="ER"),"ER",IF(OR(I18="?",I19="?"),"?",IF(AND(I18="NA",I19="NA"),"NA",SUM(I18,I19)/((I18<>"NA")*$F$18+(I19<>"NA")*$F$19)*$F17))) | J17: =IF(OR(J18="ER",J19="ER"),"ER",IF(OR(J18="?",J19="?"),"?",IF(AND(J18="NA",J19="NA"),"NA",SUM(J18,J19)/((J18<>"NA")*$F$18+(J19<>"NA")*$F$19)*$F17))) | K17: =IF(OR(K18="ER",K19="ER"),"ER",IF(OR(K18="?",K19="?"),"?",IF(AND(K18="NA",K19="NA"),"NA",SUM(K18,K19)/((K18<>"NA")*$F$18+(K19<>"NA")*$F$19)*$F17))) | L17: =IF(OR(L18="ER",L19="ER"),"ER",IF(OR(L18="?",L19="?"),"?",IF(AND(L18="NA",L19="NA"),"NA",SUM(L18,L19)/((L18<>"NA")*$F$18+(L19<>"NA")*$F$19)*$F17))) | M17: =IF(OR(M18="ER",M19="ER"),"ER",IF(OR(M18="?",M19="?"),"?",IF(AND(M18="NA",M19="NA"),"NA",SUM(M18,M19)/((M18<>"NA")*$F$18+(M19<>"NA")*$F$19)*$F17)))
A18: UPD5a | B18: =VLOOKUP($A18,'PARASTATAL Questions'!$A:$J,3,0)&"" | C18: =VLOOKUP($A18,'PARASTATAL Questions'!$A:$J,4,0)&"" | D18: =VLOOKUP($A18,'PARASTATAL Questions'!$A:$J,5,0)&"" | E18: =VLOOKUP($A18,'PARASTATAL Questions'!$A:$J,7,0)&"" | F18: =VLOOKUP($A18,'PARASTATAL Questions'!$A:$J,6,0) | G18: =IF($F18=0,"NA",IF($A18=INDIRECT("'"&$A18&"'!$B$1"),IF(VLOOKUP(G$1,INDIRECT("'"&$A18&"'!$A$12:$Z$19"),MATCH("Points (Auto-generate)",INDIRECT("'"&$A18&"'!$A$12:$Z$12"),0),0)="","?",VLOOKUP(G$1,INDIRECT("'"&$A18&"'!$A$12:$Z$19"),MATCH("Points (Auto-generate)",INDIRECT("'"&$A18&"'!$A$12:$Z$12"),0),0)),"ER")) | H18: =IF($F18=0,"NA",IF($A18=INDIRECT("'"&$A18&"'!$B$1"),IF(VLOOKUP(H$1,INDIRECT("'"&$A18&"'!$A$12:$Z$19"),MATCH("Points (Auto-generate)",INDIRECT("'"&$A18&"'!$A$12:$Z$12"),0),0)="","?",VLOOKUP(H$1,INDIRECT("'"&$A18&"'!$A$12:$Z$19"),MATCH("Points (Auto-generate)",INDIRECT("'"&$A18&"'!$A$12:$Z$12"),0),0)),"ER")) | I18: =IF($F18=0,"NA",IF($A18=INDIRECT("'"&$A18&"'!$B$1"),IF(VLOOKUP(I$1,INDIRECT("'"&$A18&"'!$A$12:$Z$19"),MATCH("Points (Auto-generate)",INDIRECT("'"&$A18&"'!$A$12:$Z$12"),0),0)="","?",VLOOKUP(I$1,INDIRECT("'"&$A18&"'!$A$12:$Z$19"),MATCH("Points (Auto-generate)",INDIRECT("'"&$A18&"'!$A$12:$Z$12"),0),0)),"ER")) | J18: =IF($F18=0,"NA",IF($A18=INDIRECT("'"&$A18&"'!$B$1"),IF(VLOOKUP(J$1,INDIRECT("'"&$A18&"'!$A$12:$Z$19"),MATCH("Points (Auto-generate)",INDIRECT("'"&$A18&"'!$A$12:$Z$12"),0),0)="","?",VLOOKUP(J$1,INDIRECT("'"&$A18&"'!$A$12:$Z$19"),MATCH("Points (Auto-generate)",INDIRECT("'"&$A18&"'!$A$12:$Z$12"),0),0)),"ER")) | K18: =IF($F18=0,"NA",IF($A18=INDIRECT("'"&$A18&"'!$B$1"),IF(VLOOKUP(K$1,INDIRECT("'"&$A18&"'!$A$12:$Z$19"),MATCH("Points (Auto-generate)",INDIRECT("'"&$A18&"'!$A$12:$Z$12"),0),0)="","?",VLOOKUP(K$1,INDIRECT("'"&$A18&"'!$A$12:$Z$19"),MATCH("Points (Auto-generate)",INDIRECT("'"&$A18&"'!$A$12:$Z$12"),0),0)),"ER")) | L18: =IF($F18=0,"NA",IF($A18=INDIRECT("'"&$A18&"'!$B$1"),IF(VLOOKUP(L$1,INDIRECT("'"&$A18&"'!$A$12:$Z$19"),MATCH("Points (Auto-generate)",INDIRECT("'"&$A18&"'!$A$12:$Z$12"),0),0)="","?",VLOOKUP(L$1,INDIRECT("'"&$A18&"'!$A$12:$Z$19"),MATCH("Points (Auto-generate)",INDIRECT("'"&$A18&"'!$A$12:$Z$12"),0),0)),"ER")) | M18: =IF($F18=0,"NA",IF($A18=INDIRECT("'"&$A18&"'!$B$1"),IF(VLOOKUP(M$1,INDIRECT("'"&$A18&"'!$A$12:$Z$19"),MATCH("Points (Auto-generate)",INDIRECT("'"&$A18&"'!$A$12:$Z$12"),0),0)="","?",VLOOKUP(M$1,INDIRECT("'"&$A18&"'!$A$12:$Z$19"),MATCH("Points (Auto-generate)",INDIRECT("'"&$A18&"'!$A$12:$Z$12"),0),0)),"ER"))
A19: UPD5b | B19: =VLOOKUP($A19,'PARASTATAL Questions'!$A:$J,3,0)&"" | C19: =VLOOKUP($A19,'PARASTATAL Questions'!$A:$J,4,0)&"" | D19: =VLOOKUP($A19,'PARASTATAL Questions'!$A:$J,5,0)&"" | E19: =VLOOKUP($A19,'PARASTATAL Questions'!$A:$J,7,0)&"" | F19: =VLOOKUP($A19,'PARASTATAL Questions'!$A:$J,6,0) | G19: =IF($F19=0,"NA",IF($A19=INDIRECT("'"&$A19&"'!$B$1"),IF(VLOOKUP(G$1,INDIRECT("'"&$A19&"'!$A$12:$Z$19"),MATCH("Points (Auto-generate)",INDIRECT("'"&$A19&"'!$A$12:$Z$12"),0),0)="","?",VLOOKUP(G$1,INDIRECT("'"&$A19&"'!$A$12:$Z$19"),MATCH("Points (Auto-generate)",INDIRECT("'"&$A19&"'!$A$12:$Z$12"),0),0)),"ER")) | H19: =IF($F19=0,"NA",IF($A19=INDIRECT("'"&$A19&"'!$B$1"),IF(VLOOKUP(H$1,INDIRECT("'"&$A19&"'!$A$12:$Z$19"),MATCH("Points (Auto-generate)",INDIRECT("'"&$A19&"'!$A$12:$Z$12"),0),0)="","?",VLOOKUP(H$1,INDIRECT("'"&$A19&"'!$A$12:$Z$19"),MATCH("Points (Auto-generate)",INDIRECT("'"&$A19&"'!$A$12:$Z$12"),0),0)),"ER")) | I19: =IF($F19=0,"NA",IF($A19=INDIRECT("'"&$A19&"'!$B$1"),IF(VLOOKUP(I$1,INDIRECT("'"&$A19&"'!$A$12:$Z$19"),MATCH("Points (Auto-generate)",INDIRECT("'"&$A19&"'!$A$12:$Z$12"),0),0)="","?",VLOOKUP(I$1,INDIRECT("'"&$A19&"'!$A$12:$Z$19"),MATCH("Points (Auto-generate)",INDIRECT("'"&$A19&"'!$A$12:$Z$12"),0),0)),"ER")) | J19: =IF($F19=0,"NA",IF($A19=INDIRECT("'"&$A19&"'!$B$1"),IF(VLOOKUP(J$1,INDIRECT("'"&$A19&"'!$A$12:$Z$19"),MATCH("Points (Auto-generate)",INDIRECT("'"&$A19&"'!$A$12:$Z$12"),0),0)="","?",VLOOKUP(J$1,INDIRECT("'"&$A19&"'!$A$12:$Z$19"),MATCH("Points (Auto-generate)",INDIRECT("'"&$A19&"'!$A$12:$Z$12"),0),0)),"ER")) | K19: =IF($F19=0,"NA",IF($A19=INDIRECT("'"&$A19&"'!$B$1"),IF(VLOOKUP(K$1,INDIRECT("'"&$A19&"'!$A$12:$Z$19"),MATCH("Points (Auto-generate)",INDIRECT("'"&$A19&"'!$A$12:$Z$12"),0),0)="","?",VLOOKUP(K$1,INDIRECT("'"&$A19&"'!$A$12:$Z$19"),MATCH("Points (Auto-generate)",INDIRECT("'"&$A19&"'!$A$12:$Z$12"),0),0)),"ER")) | L19: =IF($F19=0,"NA",IF($A19=INDIRECT("'"&$A19&"'!$B$1"),IF(VLOOKUP(L$1,INDIRECT("'"&$A19&"'!$A$12:$Z$19"),MATCH("Points (Auto-generate)",INDIRECT("'"&$A19&"'!$A$12:$Z$12"),0),0)="","?",VLOOKUP(L$1,INDIRECT("'"&$A19&"'!$A$12:$Z$19"),MATCH("Points (Auto-generate)",INDIRECT("'"&$A19&"'!$A$12:$Z$12"),0),0)),"ER")) | M19: =IF($F19=0,"NA",IF($A19=INDIRECT("'"&$A19&"'!$B$1"),IF(VLOOKUP(M$1,INDIRECT("'"&$A19&"'!$A$12:$Z$19"),MATCH("Points (Auto-generate)",INDIRECT("'"&$A19&"'!$A$12:$Z$12"),0),0)="","?",VLOOKUP(M$1,INDIRECT("'"&$A19&"'!$A$12:$Z$19"),MATCH("Points (Auto-generate)",INDIRECT("'"&$A19&"'!$A$12:$Z$12"),0),0)),"ER"))
A20: UPD6 | B20: =VLOOKUP($A20,'PARASTATAL Questions'!$A:$J,3,0)&"" | C20: =VLOOKUP($A20,'PARASTATAL Questions'!$A:$J,4,0)&"" | D20: =VLOOKUP($A20,'PARASTATAL Questions'!$A:$J,5,0)&"" | E20: =VLOOKUP($A20,'PARASTATAL Questions'!$A:$J,7,0)&"" | F20: =VLOOKUP($A20,'PARASTATAL Questions'!$A:$J,6,0) | G20: =IF(OR(G21="ER",G22="ER"),"ER",IF(OR(G21="?",G22="?"),"?",IF(AND(G21="NA",G22="NA"),"NA",SUM(G21,G22)/((G21<>"NA")*$F$21+(G22<>"NA")*$F$22)*$F20))) | H20: =IF(OR(H21="ER",H22="ER"),"ER",IF(OR(H21="?",H22="?"),"?",IF(AND(H21="NA",H22="NA"),"NA",SUM(H21,H22)/((H21<>"NA")*$F$21+(H22<>"NA")*$F$22)*$F20))) | I20: =IF(OR(I21="ER",I22="ER"),"ER",IF(OR(I21="?",I22="?"),"?",IF(AND(I21="NA",I22="NA"),"NA",SUM(I21,I22)/((I21<>"NA")*$F$21+(I22<>"NA")*$F$22)*$F20))) | J20: =IF(OR(J21="ER",J22="ER"),"ER",IF(OR(J21="?",J22="?"),"?",IF(AND(J21="NA",J22="NA"),"NA",SUM(J21,J22)/((J21<>"NA")*$F$21+(J22<>"NA")*$F$22)*$F20))) | K20: =IF(OR(K21="ER",K22="ER"),"ER",IF(OR(K21="?",K22="?"),"?",IF(AND(K21="NA",K22="NA"),"NA",SUM(K21,K22)/((K21<>"NA")*$F$21+(K22<>"NA")*$F$22)*$F20))) | L20: =IF(OR(L21="ER",L22="ER"),"ER",IF(OR(L21="?",L22="?"),"?",IF(AND(L21="NA",L22="NA"),"NA",SUM(L21,L22)/((L21<>"NA")*$F$21+(L22<>"NA")*$F$22)*$F20))) | M20: =IF(OR(M21="ER",M22="ER"),"ER",IF(OR(M21="?",M22="?"),"?",IF(AND(M21="NA",M22="NA"),"NA",SUM(M21,M22)/((M21<>"NA")*$F$21+(M22<>"NA")*$F$22)*$F20)))
A21: UPD6a | B21: =VLOOKUP($A21,'PARASTATAL Questions'!$A:$J,3,0)&"" | C21: =VLOOKUP($A21,'PARASTATAL Questions'!$A:$J,4,0)&"" | D21: =VLOOKUP($A21,'PARASTATAL Questions'!$A:$J,5,0)&"" | E21: =VLOOKUP($A21,'PARASTATAL Questions'!$A:$J,7,0)&"" | F21: =VLOOKUP($A21,'PARASTATAL Questions'!$A:$J,6,0) | G21: =IF($F21=0,"NA",IF($A21=INDIRECT("'"&$A21&"'!$B$1"),IF(VLOOKUP(G$1,INDIRECT("'"&$A21&"'!$A$12:$Z$19"),MATCH("Points (Auto-generate)",INDIRECT("'"&$A21&"'!$A$12:$Z$12"),0),0)="","?",VLOOKUP(G$1,INDIRECT("'"&$A21&"'!$A$12:$Z$19"),MATCH("Points (Auto-generate)",INDIRECT("'"&$A21&"'!$A$12:$Z$12"),0),0)),"ER")) | H21: =IF($F21=0,"NA",IF($A21=INDIRECT("'"&$A21&"'!$B$1"),IF(VLOOKUP(H$1,INDIRECT("'"&$A21&"'!$A$12:$Z$19"),MATCH("Points (Auto-generate)",INDIRECT("'"&$A21&"'!$A$12:$Z$12"),0),0)="","?",VLOOKUP(H$1,INDIRECT("'"&$A21&"'!$A$12:$Z$19"),MATCH("Points (Auto-generate)",INDIRECT("'"&$A21&"'!$A$12:$Z$12"),0),0)),"ER")) | I21: =IF($F21=0,"NA",IF($A21=INDIRECT("'"&$A21&"'!$B$1"),IF(VLOOKUP(I$1,INDIRECT("'"&$A21&"'!$A$12:$Z$19"),MATCH("Points (Auto-generate)",INDIRECT("'"&$A21&"'!$A$12:$Z$12"),0),0)="","?",VLOOKUP(I$1,INDIRECT("'"&$A21&"'!$A$12:$Z$19"),MATCH("Points (Auto-generate)",INDIRECT("'"&$A21&"'!$A$12:$Z$12"),0),0)),"ER")) | J21: =IF($F21=0,"NA",IF($A21=INDIRECT("'"&$A21&"'!$B$1"),IF(VLOOKUP(J$1,INDIRECT("'"&$A21&"'!$A$12:$Z$19"),MATCH("Points (Auto-generate)",INDIRECT("'"&$A21&"'!$A$12:$Z$12"),0),0)="","?",VLOOKUP(J$1,INDIRECT("'"&$A21&"'!$A$12:$Z$19"),MATCH("Points (Auto-generate)",INDIRECT("'"&$A21&"'!$A$12:$Z$12"),0),0)),"ER")) | K21: =IF($F21=0,"NA",IF($A21=INDIRECT("'"&$A21&"'!$B$1"),IF(VLOOKUP(K$1,INDIRECT("'"&$A21&"'!$A$12:$Z$19"),MATCH("Points (Auto-generate)",INDIRECT("'"&$A21&"'!$A$12:$Z$12"),0),0)="","?",VLOOKUP(K$1,INDIRECT("'"&$A21&"'!$A$12:$Z$19"),MATCH("Points (Auto-generate)",INDIRECT("'"&$A21&"'!$A$12:$Z$12"),0),0)),"ER")) | L21: =IF($F21=0,"NA",IF($A21=INDIRECT("'"&$A21&"'!$B$1"),IF(VLOOKUP(L$1,INDIRECT("'"&$A21&"'!$A$12:$Z$19"),MATCH("Points (Auto-generate)",INDIRECT("'"&$A21&"'!$A$12:$Z$12"),0),0)="","?",VLOOKUP(L$1,INDIRECT("'"&$A21&"'!$A$12:$Z$19"),MATCH("Points (Auto-generate)",INDIRECT("'"&$A21&"'!$A$12:$Z$12"),0),0)),"ER")) | M21: =IF($F21=0,"NA",IF($A21=INDIRECT("'"&$A21&"'!$B$1"),IF(VLOOKUP(M$1,INDIRECT("'"&$A21&"'!$A$12:$Z$19"),MATCH("Points (Auto-generate)",INDIRECT("'"&$A21&"'!$A$12:$Z$12"),0),0)="","?",VLOOKUP(M$1,INDIRECT("'"&$A21&"'!$A$12:$Z$19"),MATCH("Points (Auto-generate)",INDIRECT("'"&$A21&"'!$A$12:$Z$12"),0),0)),"ER"))
A22: UPD6b | B22: =VLOOKUP($A22,'PARASTATAL Questions'!$A:$J,3,0)&"" | C22: =VLOOKUP($A22,'PARASTATAL Questions'!$A:$J,4,0)&"" | D22: =VLOOKUP($A22,'PARASTATAL Questions'!$A:$J,5,0)&"" | E22: =VLOOKUP($A22,'PARASTATAL Questions'!$A:$J,7,0)&"" | F22: =VLOOKUP($A22,'PARASTATAL Questions'!$A:$J,6,0) | G22: =IF($F22=0,"NA",IF($A22=INDIRECT("'"&$A22&"'!$B$1"),IF(VLOOKUP(G$1,INDIRECT("'"&$A22&"'!$A$12:$Z$19"),MATCH("Points (Auto-generate)",INDIRECT("'"&$A22&"'!$A$12:$Z$12"),0),0)="","?",VLOOKUP(G$1,INDIRECT("'"&$A22&"'!$A$12:$Z$19"),MATCH("Points (Auto-generate)",INDIRECT("'"&$A22&"'!$A$12:$Z$12"),0),0)),"ER")) | H22: =IF($F22=0,"NA",IF($A22=INDIRECT("'"&$A22&"'!$B$1"),IF(VLOOKUP(H$1,INDIRECT("'"&$A22&"'!$A$12:$Z$19"),MATCH("Points (Auto-generate)",INDIRECT("'"&$A22&"'!$A$12:$Z$12"),0),0)="","?",VLOOKUP(H$1,INDIRECT("'"&$A22&"'!$A$12:$Z$19"),MATCH("Points (Auto-generate)",INDIRECT("'"&$A22&"'!$A$12:$Z$12"),0),0)),"ER")) | I22: =IF($F22=0,"NA",IF($A22=INDIRECT("'"&$A22&"'!$B$1"),IF(VLOOKUP(I$1,INDIRECT("'"&$A22&"'!$A$12:$Z$19"),MATCH("Points (Auto-generate)",INDIRECT("'"&$A22&"'!$A$12:$Z$12"),0),0)="","?",VLOOKUP(I$1,INDIRECT("'"&$A22&"'!$A$12:$Z$19"),MATCH("Points (Auto-generate)",INDIRECT("'"&$A22&"'!$A$12:$Z$12"),0),0)),"ER")) | J22: =IF($F22=0,"NA",IF($A22=INDIRECT("'"&$A22&"'!$B$1"),IF(VLOOKUP(J$1,INDIRECT("'"&$A22&"'!$A$12:$Z$19"),MATCH("Points (Auto-generate)",INDIRECT("'"&$A22&"'!$A$12:$Z$12"),0),0)="","?",VLOOKUP(J$1,INDIRECT("'"&$A22&"'!$A$12:$Z$19"),MATCH("Points (Auto-generate)",INDIRECT("'"&$A22&"'!$A$12:$Z$12"),0),0)),"ER")) | K22: =IF($F22=0,"NA",IF($A22=INDIRECT("'"&$A22&"'!$B$1"),IF(VLOOKUP(K$1,INDIRECT("'"&$A22&"'!$A$12:$Z$19"),MATCH("Points (Auto-generate)",INDIRECT("'"&$A22&"'!$A$12:$Z$12"),0),0)="","?",VLOOKUP(K$1,INDIRECT("'"&$A22&"'!$A$12:$Z$19"),MATCH("Points (Auto-generate)",INDIRECT("'"&$A22&"'!$A$12:$Z$12"),0),0)),"ER")) | L22: =IF($F22=0,"NA",IF($A22=INDIRECT("'"&$A22&"'!$B$1"),IF(VLOOKUP(L$1,INDIRECT("'"&$A22&"'!$A$12:$Z$19"),MATCH("Points (Auto-generate)",INDIRECT("'"&$A22&"'!$A$12:$Z$12"),0),0)="","?",VLOOKUP(L$1,INDIRECT("'"&$A22&"'!$A$12:$Z$19"),MATCH("Points (Auto-generate)",INDIRECT("'"&$A22&"'!$A$12:$Z$12"),0),0)),"ER")) | M22: =IF($F22=0,"NA",IF($A22=INDIRECT("'"&$A22&"'!$B$1"),IF(VLOOKUP(M$1,INDIRECT("'"&$A22&"'!$A$12:$Z$19"),MATCH("Points (Auto-generate)",INDIRECT("'"&$A22&"'!$A$12:$Z$12"),0),0)="","?",VLOOKUP(M$1,INDIRECT("'"&$A22&"'!$A$12:$Z$19"),MATCH("Points (Auto-generate)",INDIRECT("'"&$A22&"'!$A$12:$Z$12"),0),0)),"ER"))
A23: DPG1 | B23: =VLOOKUP($A23,'PARASTATAL Questions'!$A:$J,3,0)&"" | C23: =VLOOKUP($A23,'PARASTATAL Questions'!$A:$J,4,0)&"" | D23: =VLOOKUP($A23,'PARASTATAL Questions'!$A:$J,5,0)&"" | E23: =VLOOKUP($A23,'PARASTATAL Questions'!$A:$J,7,0)&"" | F23: =VLOOKUP($A23,'PARASTATAL Questions'!$A:$J,6,0) | G23: =IF(OR(G24="ER",G25="ER"),"ER",IF(OR(G24="?",G25="?"),"?",IF(AND(G24="NA",G25="NA"),"NA",SUM(G24,G25)/((G24<>"NA")*$F$24+(G25<>"NA")*$F$25)*$F23))) | H23: =IF(OR(H24="ER",H25="ER"),"ER",IF(OR(H24="?",H25="?"),"?",IF(AND(H24="NA",H25="NA"),"NA",SUM(H24,H25)/((H24<>"NA")*$F$24+(H25<>"NA")*$F$25)*$F23))) | I23: =IF(OR(I24="ER",I25="ER"),"ER",IF(OR(I24="?",I25="?"),"?",IF(AND(I24="NA",I25="NA"),"NA",SUM(I24,I25)/((I24<>"NA")*$F$24+(I25<>"NA")*$F$25)*$F23))) | J23: =IF(OR(J24="ER",J25="ER"),"ER",IF(OR(J24="?",J25="?"),"?",IF(AND(J24="NA",J25="NA"),"NA",SUM(J24,J25)/((J24<>"NA")*$F$24+(J25<>"NA")*$F$25)*$F23))) | K23: =IF(OR(K24="ER",K25="ER"),"ER",IF(OR(K24="?",K25="?"),"?",IF(AND(K24="NA",K25="NA"),"NA",SUM(K24,K25)/((K24<>"NA")*$F$24+(K25<>"NA")*$F$25)*$F23))) | L23: =IF(OR(L24="ER",L25="ER"),"ER",IF(OR(L24="?",L25="?"),"?",IF(AND(L24="NA",L25="NA"),"NA",SUM(L24,L25)/((L24<>"NA")*$F$24+(L25<>"NA")*$F$25)*$F23))) | M23: =IF(OR(M24="ER",M25="ER"),"ER",IF(OR(M24="?",M25="?"),"?",IF(AND(M24="NA",M25="NA"),"NA",SUM(M24,M25)/((M24<>"NA")*$F$24+(M25<>"NA")*$F$25)*$F23)))
A24: DPG1a | B24: =VLOOKUP($A24,'PARASTATAL Questions'!$A:$J,3,0)&"" | C24: =VLOOKUP($A24,'PARASTATAL Questions'!$A:$J,4,0)&"" | D24: =VLOOKUP($A24,'PARASTATAL Questions'!$A:$J,5,0)&"" | E24: =VLOOKUP($A24,'PARASTATAL Questions'!$A:$J,7,0)&"" | F24: =VLOOKUP($A24,'PARASTATAL Questions'!$A:$J,6,0) | G24: =IF($F24=0,"NA",IF($A24=INDIRECT("'"&$A24&"'!$B$1"),IF(VLOOKUP(G$1,INDIRECT("'"&$A24&"'!$A$12:$Z$19"),MATCH("Points (Auto-generate)",INDIRECT("'"&$A24&"'!$A$12:$Z$12"),0),0)="","?",VLOOKUP(G$1,INDIRECT("'"&$A24&"'!$A$12:$Z$19"),MATCH("Points (Auto-generate)",INDIRECT("'"&$A24&"'!$A$12:$Z$12"),0),0)),"ER")) | H24: =IF($F24=0,"NA",IF($A24=INDIRECT("'"&$A24&"'!$B$1"),IF(VLOOKUP(H$1,INDIRECT("'"&$A24&"'!$A$12:$Z$19"),MATCH("Points (Auto-generate)",INDIRECT("'"&$A24&"'!$A$12:$Z$12"),0),0)="","?",VLOOKUP(H$1,INDIRECT("'"&$A24&"'!$A$12:$Z$19"),MATCH("Points (Auto-generate)",INDIRECT("'"&$A24&"'!$A$12:$Z$12"),0),0)),"ER")) | I24: =IF($F24=0,"NA",IF($A24=INDIRECT("'"&$A24&"'!$B$1"),IF(VLOOKUP(I$1,INDIRECT("'"&$A24&"'!$A$12:$Z$19"),MATCH("Points (Auto-generate)",INDIRECT("'"&$A24&"'!$A$12:$Z$12"),0),0)="","?",VLOOKUP(I$1,INDIRECT("'"&$A24&"'!$A$12:$Z$19"),MATCH("Points (Auto-generate)",INDIRECT("'"&$A24&"'!$A$12:$Z$12"),0),0)),"ER")) | J24: =IF($F24=0,"NA",IF($A24=INDIRECT("'"&$A24&"'!$B$1"),IF(VLOOKUP(J$1,INDIRECT("'"&$A24&"'!$A$12:$Z$19"),MATCH("Points (Auto-generate)",INDIRECT("'"&$A24&"'!$A$12:$Z$12"),0),0)="","?",VLOOKUP(J$1,INDIRECT("'"&$A24&"'!$A$12:$Z$19"),MATCH("Points (Auto-generate)",INDIRECT("'"&$A24&"'!$A$12:$Z$12"),0),0)),"ER")) | K24: =IF($F24=0,"NA",IF($A24=INDIRECT("'"&$A24&"'!$B$1"),IF(VLOOKUP(K$1,INDIRECT("'"&$A24&"'!$A$12:$Z$19"),MATCH("Points (Auto-generate)",INDIRECT("'"&$A24&"'!$A$12:$Z$12"),0),0)="","?",VLOOKUP(K$1,INDIRECT("'"&$A24&"'!$A$12:$Z$19"),MATCH("Points (Auto-generate)",INDIRECT("'"&$A24&"'!$A$12:$Z$12"),0),0)),"ER")) | L24: =IF($F24=0,"NA",IF($A24=INDIRECT("'"&$A24&"'!$B$1"),IF(VLOOKUP(L$1,INDIRECT("'"&$A24&"'!$A$12:$Z$19"),MATCH("Points (Auto-generate)",INDIRECT("'"&$A24&"'!$A$12:$Z$12"),0),0)="","?",VLOOKUP(L$1,INDIRECT("'"&$A24&"'!$A$12:$Z$19"),MATCH("Points (Auto-generate)",INDIRECT("'"&$A24&"'!$A$12:$Z$12"),0),0)),"ER")) | M24: =IF($F24=0,"NA",IF($A24=INDIRECT("'"&$A24&"'!$B$1"),IF(VLOOKUP(M$1,INDIRECT("'"&$A24&"'!$A$12:$Z$19"),MATCH("Points (Auto-generate)",INDIRECT("'"&$A24&"'!$A$12:$Z$12"),0),0)="","?",VLOOKUP(M$1,INDIRECT("'"&$A24&"'!$A$12:$Z$19"),MATCH("Points (Auto-generate)",INDIRECT("'"&$A24&"'!$A$12:$Z$12"),0),0)),"ER"))
A25: DPG1b | B25: =VLOOKUP($A25,'PARASTATAL Questions'!$A:$J,3,0)&"" | C25: =VLOOKUP($A25,'PARASTATAL Questions'!$A:$J,4,0)&"" | D25: =VLOOKUP($A25,'PARASTATAL Questions'!$A:$J,5,0)&"" | E25: =VLOOKUP($A25,'PARASTATAL Questions'!$A:$J,7,0)&"" | F25: =VLOOKUP($A25,'PARASTATAL Questions'!$A:$J,6,0) | G25: =IF($F25=0,"NA",IF($A25=INDIRECT("'"&$A25&"'!$B$1"),IF(VLOOKUP(G$1,INDIRECT("'"&$A25&"'!$A$12:$Z$19"),MATCH("Points (Auto-generate)",INDIRECT("'"&$A25&"'!$A$12:$Z$12"),0),0)="","?",VLOOKUP(G$1,INDIRECT("'"&$A25&"'!$A$12:$Z$19"),MATCH("Points (Auto-generate)",INDIRECT("'"&$A25&"'!$A$12:$Z$12"),0),0)),"ER")) | H25: =IF($F25=0,"NA",IF($A25=INDIRECT("'"&$A25&"'!$B$1"),IF(VLOOKUP(H$1,INDIRECT("'"&$A25&"'!$A$12:$Z$19"),MATCH("Points (Auto-generate)",INDIRECT("'"&$A25&"'!$A$12:$Z$12"),0),0)="","?",VLOOKUP(H$1,INDIRECT("'"&$A25&"'!$A$12:$Z$19"),MATCH("Points (Auto-generate)",INDIRECT("'"&$A25&"'!$A$12:$Z$12"),0),0)),"ER")) | I25: =IF($F25=0,"NA",IF($A25=INDIRECT("'"&$A25&"'!$B$1"),IF(VLOOKUP(I$1,INDIRECT("'"&$A25&"'!$A$12:$Z$19"),MATCH("Points (Auto-generate)",INDIRECT("'"&$A25&"'!$A$12:$Z$12"),0),0)="","?",VLOOKUP(I$1,INDIRECT("'"&$A25&"'!$A$12:$Z$19"),MATCH("Points (Auto-generate)",INDIRECT("'"&$A25&"'!$A$12:$Z$12"),0),0)),"ER")) | J25: =IF($F25=0,"NA",IF($A25=INDIRECT("'"&$A25&"'!$B$1"),IF(VLOOKUP(J$1,INDIRECT("'"&$A25&"'!$A$12:$Z$19"),MATCH("Points (Auto-generate)",INDIRECT("'"&$A25&"'!$A$12:$Z$12"),0),0)="","?",VLOOKUP(J$1,INDIRECT("'"&$A25&"'!$A$12:$Z$19"),MATCH("Points (Auto-generate)",INDIRECT("'"&$A25&"'!$A$12:$Z$12"),0),0)),"ER")) | K25: =IF($F25=0,"NA",IF($A25=INDIRECT("'"&$A25&"'!$B$1"),IF(VLOOKUP(K$1,INDIRECT("'"&$A25&"'!$A$12:$Z$19"),MATCH("Points (Auto-generate)",INDIRECT("'"&$A25&"'!$A$12:$Z$12"),0),0)="","?",VLOOKUP(K$1,INDIRECT("'"&$A25&"'!$A$12:$Z$19"),MATCH("Points (Auto-generate)",INDIRECT("'"&$A25&"'!$A$12:$Z$12"),0),0)),"ER")) | L25: =IF($F25=0,"NA",IF($A25=INDIRECT("'"&$A25&"'!$B$1"),IF(VLOOKUP(L$1,INDIRECT("'"&$A25&"'!$A$12:$Z$19"),MATCH("Points (Auto-generate)",INDIRECT("'"&$A25&"'!$A$12:$Z$12"),0),0)="","?",VLOOKUP(L$1,INDIRECT("'"&$A25&"'!$A$12:$Z$19"),MATCH("Points (Auto-generate)",INDIRECT("'"&$A25&"'!$A$12:$Z$12"),0),0)),"ER")) | M25: =IF($F25=0,"NA",IF($A25=INDIRECT("'"&$A25&"'!$B$1"),IF(VLOOKUP(M$1,INDIRECT("'"&$A25&"'!$A$12:$Z$19"),MATCH("Points (Auto-generate)",INDIRECT("'"&$A25&"'!$A$12:$Z$12"),0),0)="","?",VLOOKUP(M$1,INDIRECT("'"&$A25&"'!$A$12:$Z$19"),MATCH("Points (Auto-generate)",INDIRECT("'"&$A25&"'!$A$12:$Z$12"),0),0)),"ER"))
A26: DPG2 | B26: =VLOOKUP($A26,'PARASTATAL Questions'!$A:$J,3,0)&"" | C26: =VLOOKUP($A26,'PARASTATAL Questions'!$A:$J,4,0)&"" | D26: =VLOOKUP($A26,'PARASTATAL Questions'!$A:$J,5,0)&"" | E26: =VLOOKUP($A26,'PARASTATAL Questions'!$A:$J,7,0)&"" | F26: =VLOOKUP($A26,'PARASTATAL Questions'!$A:$J,6,0) | G26: =IF(OR(G27="ER",G28="ER"),"ER",IF(OR(G27="?",G28="?"),"?",IF(AND(G27="NA",G28="NA"),"NA",SUM(G27,G28)/((G27<>"NA")*$F$27+(G28<>"NA")*$F$28)*$F26))) | H26: =IF(OR(H27="ER",H28="ER"),"ER",IF(OR(H27="?",H28="?"),"?",IF(AND(H27="NA",H28="NA"),"NA",SUM(H27,H28)/((H27<>"NA")*$F$27+(H28<>"NA")*$F$28)*$F26))) | I26: =IF(OR(I27="ER",I28="ER"),"ER",IF(OR(I27="?",I28="?"),"?",IF(AND(I27="NA",I28="NA"),"NA",SUM(I27,I28)/((I27<>"NA")*$F$27+(I28<>"NA")*$F$28)*$F26))) | J26: =IF(OR(J27="ER",J28="ER"),"ER",IF(OR(J27="?",J28="?"),"?",IF(AND(J27="NA",J28="NA"),"NA",SUM(J27,J28)/((J27<>"NA")*$F$27+(J28<>"NA")*$F$28)*$F26))) | K26: =IF(OR(K27="ER",K28="ER"),"ER",IF(OR(K27="?",K28="?"),"?",IF(AND(K27="NA",K28="NA"),"NA",SUM(K27,K28)/((K27<>"NA")*$F$27+(K28<>"NA")*$F$28)*$F26))) | L26: =IF(OR(L27="ER",L28="ER"),"ER",IF(OR(L27="?",L28="?"),"?",IF(AND(L27="NA",L28="NA"),"NA",SUM(L27,L28)/((L27<>"NA")*$F$27+(L28<>"NA")*$F$28)*$F26))) | M26: =IF(OR(M27="ER",M28="ER"),"ER",IF(OR(M27="?",M28="?"),"?",IF(AND(M27="NA",M28="NA"),"NA",SUM(M27,M28)/((M27<>"NA")*$F$27+(M28<>"NA")*$F$28)*$F26)))
A27: DPG2a | B27: =VLOOKUP($A27,'PARASTATAL Questions'!$A:$J,3,0)&"" | C27: =VLOOKUP($A27,'PARASTATAL Questions'!$A:$J,4,0)&"" | D27: =VLOOKUP($A27,'PARASTATAL Questions'!$A:$J,5,0)&"" | E27: =VLOOKUP($A27,'PARASTATAL Questions'!$A:$J,7,0)&"" | F27: =VLOOKUP($A27,'PARASTATAL Questions'!$A:$J,6,0) | G27: =IF($F27=0,"NA",IF($A27=INDIRECT("'"&$A27&"'!$B$1"),IF(VLOOKUP(G$1,INDIRECT("'"&$A27&"'!$A$12:$Z$19"),MATCH("Points (Auto-generate)",INDIRECT("'"&$A27&"'!$A$12:$Z$12"),0),0)="","?",VLOOKUP(G$1,INDIRECT("'"&$A27&"'!$A$12:$Z$19"),MATCH("Points (Auto-generate)",INDIRECT("'"&$A27&"'!$A$12:$Z$12"),0),0)),"ER")) | H27: =IF($F27=0,"NA",IF($A27=INDIRECT("'"&$A27&"'!$B$1"),IF(VLOOKUP(H$1,INDIRECT("'"&$A27&"'!$A$12:$Z$19"),MATCH("Points (Auto-generate)",INDIRECT("'"&$A27&"'!$A$12:$Z$12"),0),0)="","?",VLOOKUP(H$1,INDIRECT("'"&$A27&"'!$A$12:$Z$19"),MATCH("Points (Auto-generate)",INDIRECT("'"&$A27&"'!$A$12:$Z$12"),0),0)),"ER")) | I27: =IF($F27=0,"NA",IF($A27=INDIRECT("'"&$A27&"'!$B$1"),IF(VLOOKUP(I$1,INDIRECT("'"&$A27&"'!$A$12:$Z$19"),MATCH("Points (Auto-generate)",INDIRECT("'"&$A27&"'!$A$12:$Z$12"),0),0)="","?",VLOOKUP(I$1,INDIRECT("'"&$A27&"'!$A$12:$Z$19"),MATCH("Points (Auto-generate)",INDIRECT("'"&$A27&"'!$A$12:$Z$12"),0),0)),"ER")) | J27: =IF($F27=0,"NA",IF($A27=INDIRECT("'"&$A27&"'!$B$1"),IF(VLOOKUP(J$1,INDIRECT("'"&$A27&"'!$A$12:$Z$19"),MATCH("Points (Auto-generate)",INDIRECT("'"&$A27&"'!$A$12:$Z$12"),0),0)="","?",VLOOKUP(J$1,INDIRECT("'"&$A27&"'!$A$12:$Z$19"),MATCH("Points (Auto-generate)",INDIRECT("'"&$A27&"'!$A$12:$Z$12"),0),0)),"ER")) | K27: =IF($F27=0,"NA",IF($A27=INDIRECT("'"&$A27&"'!$B$1"),IF(VLOOKUP(K$1,INDIRECT("'"&$A27&"'!$A$12:$Z$19"),MATCH("Points (Auto-generate)",INDIRECT("'"&$A27&"'!$A$12:$Z$12"),0),0)="","?",VLOOKUP(K$1,INDIRECT("'"&$A27&"'!$A$12:$Z$19"),MATCH("Points (Auto-generate)",INDIRECT("'"&$A27&"'!$A$12:$Z$12"),0),0)),"ER")) | L27: =IF($F27=0,"NA",IF($A27=INDIRECT("'"&$A27&"'!$B$1"),IF(VLOOKUP(L$1,INDIRECT("'"&$A27&"'!$A$12:$Z$19"),MATCH("Points (Auto-generate)",INDIRECT("'"&$A27&"'!$A$12:$Z$12"),0),0)="","?",VLOOKUP(L$1,INDIRECT("'"&$A27&"'!$A$12:$Z$19"),MATCH("Points (Auto-generate)",INDIRECT("'"&$A27&"'!$A$12:$Z$12"),0),0)),"ER")) | M27: =IF($F27=0,"NA",IF($A27=INDIRECT("'"&$A27&"'!$B$1"),IF(VLOOKUP(M$1,INDIRECT("'"&$A27&"'!$A$12:$Z$19"),MATCH("Points (Auto-generate)",INDIRECT("'"&$A27&"'!$A$12:$Z$12"),0),0)="","?",VLOOKUP(M$1,INDIRECT("'"&$A27&"'!$A$12:$Z$19"),MATCH("Points (Auto-generate)",INDIRECT("'"&$A27&"'!$A$12:$Z$12"),0),0)),"ER"))
A28: DPG2b | B28: =VLOOKUP($A28,'PARASTATAL Questions'!$A:$J,3,0)&"" | C28: =VLOOKUP($A28,'PARASTATAL Questions'!$A:$J,4,0)&"" | D28: =VLOOKUP($A28,'PARASTATAL Questions'!$A:$J,5,0)&"" | E28: =VLOOKUP($A28,'PARASTATAL Questions'!$A:$J,7,0)&"" | F28: =VLOOKUP($A28,'PARASTATAL Questions'!$A:$J,6,0) | G28: =IF($F28=0,"NA",IF($A28=INDIRECT("'"&$A28&"'!$B$1"),IF(VLOOKUP(G$1,INDIRECT("'"&$A28&"'!$A$12:$Z$19"),MATCH("Points (Auto-generate)",INDIRECT("'"&$A28&"'!$A$12:$Z$12"),0),0)="","?",VLOOKUP(G$1,INDIRECT("'"&$A28&"'!$A$12:$Z$19"),MATCH("Points (Auto-generate)",INDIRECT("'"&$A28&"'!$A$12:$Z$12"),0),0)),"ER")) | H28: =IF($F28=0,"NA",IF($A28=INDIRECT("'"&$A28&"'!$B$1"),IF(VLOOKUP(H$1,INDIRECT("'"&$A28&"'!$A$12:$Z$19"),MATCH("Points (Auto-generate)",INDIRECT("'"&$A28&"'!$A$12:$Z$12"),0),0)="","?",VLOOKUP(H$1,INDIRECT("'"&$A28&"'!$A$12:$Z$19"),MATCH("Points (Auto-generate)",INDIRECT("'"&$A28&"'!$A$12:$Z$12"),0),0)),"ER")) | I28: =IF($F28=0,"NA",IF($A28=INDIRECT("'"&$A28&"'!$B$1"),IF(VLOOKUP(I$1,INDIRECT("'"&$A28&"'!$A$12:$Z$19"),MATCH("Points (Auto-generate)",INDIRECT("'"&$A28&"'!$A$12:$Z$12"),0),0)="","?",VLOOKUP(I$1,INDIRECT("'"&$A28&"'!$A$12:$Z$19"),MATCH("Points (Auto-generate)",INDIRECT("'"&$A28&"'!$A$12:$Z$12"),0),0)),"ER")) | J28: =IF($F28=0,"NA",IF($A28=INDIRECT("'"&$A28&"'!$B$1"),IF(VLOOKUP(J$1,INDIRECT("'"&$A28&"'!$A$12:$Z$19"),MATCH("Points (Auto-generate)",INDIRECT("'"&$A28&"'!$A$12:$Z$12"),0),0)="","?",VLOOKUP(J$1,INDIRECT("'"&$A28&"'!$A$12:$Z$19"),MATCH("Points (Auto-generate)",INDIRECT("'"&$A28&"'!$A$12:$Z$12"),0),0)),"ER")) | K28: =IF($F28=0,"NA",IF($A28=INDIRECT("'"&$A28&"'!$B$1"),IF(VLOOKUP(K$1,INDIRECT("'"&$A28&"'!$A$12:$Z$19"),MATCH("Points (Auto-generate)",INDIRECT("'"&$A28&"'!$A$12:$Z$12"),0),0)="","?",VLOOKUP(K$1,INDIRECT("'"&$A28&"'!$A$12:$Z$19"),MATCH("Points (Auto-generate)",INDIRECT("'"&$A28&"'!$A$12:$Z$12"),0),0)),"ER")) | L28: =IF($F28=0,"NA",IF($A28=INDIRECT("'"&$A28&"'!$B$1"),IF(VLOOKUP(L$1,INDIRECT("'"&$A28&"'!$A$12:$Z$19"),MATCH("Points (Auto-generate)",INDIRECT("'"&$A28&"'!$A$12:$Z$12"),0),0)="","?",VLOOKUP(L$1,INDIRECT("'"&$A28&"'!$A$12:$Z$19"),MATCH("Points (Auto-generate)",INDIRECT("'"&$A28&"'!$A$12:$Z$12"),0),0)),"ER")) | M28: =IF($F28=0,"NA",IF($A28=INDIRECT("'"&$A28&"'!$B$1"),IF(VLOOKUP(M$1,INDIRECT("'"&$A28&"'!$A$12:$Z$19"),MATCH("Points (Auto-generate)",INDIRECT("'"&$A28&"'!$A$12:$Z$12"),0),0)="","?",VLOOKUP(M$1,INDIRECT("'"&$A28&"'!$A$12:$Z$19"),MATCH("Points (Auto-generate)",INDIRECT("'"&$A28&"'!$A$12:$Z$12"),0),0)),"ER"))
