Workbook

Sheet Scores (start here)
A1: Question | B1: Row | C1: Question text | D1: AI score | E1: Max score | F1: ★ Your score | G1: ★ Your comments | H1: Agrees with AI? | I1: Final score | J1: Score used | K1: Status | L1: Step 2 status | M1: Step 2 answer | N1: Citation | O1: Link | P1: Quote | Q1: AI's reasoning | R1: Why left for a person
A2: UPD1a | B2: Bengaluru – BWSSB | D2: =IFERROR(UPD1a!L13,"") -> 1.25 | H2: =IF(OR(F2="",NOT(ISNUMBER(D2))),"",IF(ABS(F2-D2)<0.001,"Yes","No")) | I2: =IF(ISNUMBER(F2),F2,D2) -> 1.25 | J2: =IF(ISNUMBER(F2),"Expert (overrides AI)",IF(ISNUMBER(D2),"AI","Not scored yet")) -> AI | K2: Left for a person | L2: Partially Answered | M2: ANSWER: In the sources available, I found no provision that requires BWSSB to prepare its water supply or sewerage plans or schemes jointly with, in consultation with, or with the approval of the ULG (the Greater Bengaluru Authority (GBA) and its City Corporations). On BWSSB's side, the Act gives the Board its own duty to prepare schemes. The approval it requires for big schemes comes from the State Government, not the ULG. The only ULG link is a Consultative Committee set up by the State Government that advises the Board on 'major schemes'. ULG involvement in that committee is at the State's discretion. On the ULG's side, the Greater Bengaluru Governance Act gives GBA wide powers to supervise and coordinate public authorities, including BWSSB, through binding directions. It does not require BWSSB to prepare its own plans in coordination with the ULG. The Karnataka Town and Country Planning Act is not in the Citation Sheet, so the answer is incomplete. | EVIDENCE: (1) BWSSB Act 1964 (BWSSB-02, PRS consolidated copy): s.15(2)(b)-(c) says it is the Board's duty to take steps 'for preparing and carrying out schemes' for water supply and sewerage. The s.15(2) proviso says no scheme 'estimated to cost more than a crore of rupees shall be carried out by the Board except with the approval of the State Government' (State approval, not ULG). s.14: 'The State Government shall constitute a Consultative Committee'. Its other members are appointed 'after consultation with such representat | N2: The Bangalore Water Supply and Sewerage Act, 1964 [BWSSB-02] | O2: https://prsindia.org/files/bills_acts/acts_states/karnataka/1964/1964KR36.pdf | P2: (i) to advise the Board on major questions of policy and major schemes; | Q2: I left the Score blank for three reasons. (1) SCALE-MISMATCH. The Step 2 notes say the rubric bands run from 0 to 10, but the Max Score is 5. The detailed methodology and band wording were not in my task input, so I could not check the bands or match the evidence to one. A person needs to confirm the scale. (2) The evidence fits no band without a team decision (RUBRIC-GAP). The two possible bands are 2.5 and 0. - BWSSB Act 1964 (BWSSB-02, PRS consolidated copy, amended up to Act 29 of 2021). Under s.15(2)(b)-(c) the Board prepares its own water supply and sewerage schemes. Under the s.15(2) proviso, schemes costing more than Rs 1 crore need approval from the State Government, not the city government. - The only link to the city government is s.14. The State 'shall constitute' a Consultative Committee, and it consults bodies representing the city corporation (still named as the Bruhat Bangalore Mahanagara Palike) only 'as the State Government thinks fit'. The committee's role is to 'advise the Board on major questions of policy and major schemes'. That is advice, not approval, and nothing requires the Board to follow it. - On the city government's side, the Greater Bengaluru Governance Act (BWSSB-04, Act 36 of 2025, as enacted, GBA era) gives the Greater Bengaluru Authority (GBA) several powers: - s.14(4): 'Integrating and supervising the activities of public authorities like ... the Bengaluru Water Supply and Sewerage Board ... issuing directions for the same which shall be binding'. - s.14(3)(b): coordinating the execution of schemes that implement plans prepared by GBA. - s.15(1): GBA makes the master plan and mobility plans. These are general powers to supervise and direct. None of them makes city government consultation or approval a required step when BWSSB prepares its own plans. The team must decide whether these powers count as 'coordination' for UPD1a. (3) I cannot show affirmative absence, so a 0 is not supported. The Karnataka Town and Country Planning Act 1961 is not in the Citation Sheet; I searched and found nothing. No BWSSB Rules (s.87), Regulations (s.88) or s.14(4)(iv) Rules are in the sheet either. I checked BWSSB-02 ss.12-15, BWSSB-04 ss.14-15 and the definition of 'public authority' in s.2(54), and the Step 2 review of BWSSB-23 and BWSSB-28 (these are bills, not enacted law). Also flagged: the BWSSB Act still names BBMP. No source in the sheet shows GBA or the City Corporations substituted for it. | R2: The citation didn't settle every input. "Score" left blank: the Citation Sheet doesn't decide it.
A3: UPD1a | B3: Bengaluru – BMTC | D3: =IFERROR(UPD1a!L14,"") | H3: =IF(OR(F3="",NOT(ISNUMBER(D3))),"",IF(ABS(F3-D3)<0.001,"Yes","No")) | I3: =IF(ISNUMBER(F3),F3,D3) | J3: =IF(ISNUMBER(F3),"Expert (overrides AI)",IF(ISNUMBER(D3),"AI","Not scored yet")) -> Not scored yet | K3: Left for a person | L3: Partially Answered | M3: ANSWER: None of the sources in the Citation Sheet requires BMTC to prepare its own spatial or sectoral plans together with, in consultation with, or with the approval of the Greater Bengaluru Authority (GBA) or its City Corporations. What exists runs mainly the other way. (i) The GBA's own law gives the GBA a general power to integrate and supervise BMTC's activities. Its directions are binding, BMTC must obey them, and BMTC must write the GBA's coordinating role into its Memorandum of Association. (ii) The GBA must make the master plan and the mobility plans for the Greater Bengaluru Area. (iii) The GBA may hand the planning of major infrastructure projects to public authorities, and those authorities must help when asked. (iv) Under the transport authority's Act (BMLTA), BMTC, as an 'Urban Transport Agency', must prepare its Sectoral Mobility Investment Program 'in consultation with' the BMLTA. The BMLTA is a state authority, not the city government, although the 2025 amendment bill (BMTC-24) adds the five City Corporation Mayors and Commissioners and the GBA Chief Commissioner to it and its Executive Committee. Whether the GBA's general power to supervise and direct counts as 'approval/concurrence' or fits no band at all is a judgement for the team. | EVIDENCE: BMTC's side. Road Transport Corporations Act, 1950 (BMTC-02): s.18 sets a general duty to provide an 'efficient, adequate, economical and properly co-ordinated system of road transport services'. s.19 lists BMTC's p | N3: The Greater Bengaluru Governance Act, 2024 Act No. 36 of 2025 [BMTC-04] | O3: https://prsindia.org/files/bills_acts/acts_states/karnataka/2025/Act36of2025KA.pdf | P3: Integrating and supervising the activities of public authorities like the Bangalore Development Authority, the Bengaluru Water Supply and Sewerage Board, Bangalore Metropolitan Transport Corporation, Bengaluru Solid Waste Management Corporation, Bengaluru Metro Rail Corporation Limited, the Bangalore Electricity Supply Company and such other bodies connected with municipal activities in the Greater Bengaluru Area in such a manner that all functions are streamlined and implemented in a citizen-friendly manner and issuing directions for the same which shall be binding; | Q3: Score left blank for three reasons. (1) SCALE-MISMATCH. Step 2 reports that the UPD1a rubric bands run 0-10, but this input allows only 0-5. The highest band is neither the Max Score nor a sum of components, so I have not scaled a band down. The team should confirm the scale. (2) RUBRIC-GAP / band undetermined. I checked the Step 2 answer against the source and it is accurate. The Greater Bengaluru Governance Act, 2024 (BMTC-04) gives the GBA (the city government) a general, binding power to integrate, supervise and direct BMTC's 'activities' (s.14(4)). BMTC must obey those directions and must add the GBA's coordinating role to its Memorandum of Association. But no provision requires BMTC to prepare its own spatial or sectoral plans in consultation with, or with the approval of, the GBA or the City Corporations. Other provisions read: - s.15(1): the GBA makes the master plan and mobility plans itself. - s.15(5): the GBA 'may' assign the planning of major infrastructure projects to public authorities. This is a discretionary power, not a duty on BMTC. - s.14(3)(b): covers schemes for plans prepared by the GBA, not BMTC's own plans. - BMLTA Act s.24(b) (BMTC-06): requires consultation with the BMLTA, a state authority, not the city government. Whether a general power to direct counts as 'approval/concurrence' is a judgement for the team. I have not interpolated a band. (3) No affirmative absence, so 0 cannot be scored. Not in the Citation Sheet: - BMTC's Memorandum and Articles of Association - Rules or Regulations under the Road Transport Corporations Act, 1950 or the BMLTA Act - GBA regulations or directions under s.14(4) Checked: - BMTC-04: s.8, s.9, s.13, s.14(2)-(4), s.15 - BMTC-05: the GBA amendment bill. Its amendments to s.8(2) and s.14(1) clarify the GBA's functions. They do not touch s.14(4) or add any duty on BMTC's plans. - BMTC-02, BMTC-06, BMTC-07, BMTC-22, BMTC-24: as reported in Step 2. - Sheet-wide search for BMTC plans with GBA approval or consultation: found nothing new. For the team to check: - BMTC's legal form. The GBA Act calls it 'Bangalore Metropolitan Transport Corporation Limited', which conflicts with the Road Transport Corporations Act, 1950 being listed as its enabling Act. - Whether the BMLTA amendment (BMTC-24 bill; Act 10 of 2026) is in force. The UPD1a Detailed Methodology text was not supplied in this task, which also prevents scoring. | R3: The citation didn't settle every input. "Score" left blank: the Citation Sheet doesn't decide it.
A4: UPD1a | B4: Bengaluru – BDA | D4: =IFERROR(UPD1a!L15,"") -> 3.75 | H4: =IF(OR(F4="",NOT(ISNUMBER(D4))),"",IF(ABS(F4-D4)<0.001,"Yes","No")) | I4: =IF(ISNUMBER(F4),F4,D4) -> 3.75 | J4: =IF(ISNUMBER(F4),"Expert (overrides AI)",IF(ISNUMBER(D4),"AI","Not scored yet")) -> AI | K4: Left for a person | L4: Partially Answered | M4: ANSWER: The answer depends on the type of plan, so I have not given a single band. (1) BDA's development schemes: the law requires BDA to send each scheme notification to 'the Corporation'. The Corporation has 30 days to make representations. Representations go to the Government through BDA, and BDA must consider them before submitting the scheme for sanction. If no representation arrives in time, the Corporation's concurrence is deemed given. This is mandatory consultation with a duty to consider, not a real right of approval: the Corporation's silence counts as consent, and a representation does not stop the scheme going forward. (2) Works for further development: the Corporation 'shall be consulted' if the area lies within the City limits. This is mandatory consultation with no duty to respond. (3) Private layouts within Corporation limits: BDA needs the Corporation's concurrence. If they disagree, the Government decides. This is a sanction of private layouts, not a plan BDA prepares itself. (4) Master plan under the T&CP Act: the sections I read give the local authority no role in preparing the master plan, only public notice and public comments. On top of this, the Greater Bengaluru Governance Act makes GBA itself the Planning Authority for the Greater Bengaluru Area 'notwithstanding anything contained in any other law'. GBA can also issue binding directions to BDA. These are ULG powers over BDA, but they are not a duty on BDA to prepare its plans jointly with GBA. | EVI | N4: The Bangalore Development Authority Act, 1976 (Act 12 of 1976) – PRS copy, 'Amendments appended: 19 of 2002, 19 of 2005, 27 of 2020, 42 of 2026' [BDA-02] | O4: https://prsindia.org/files/bills_acts/acts_states/karnataka/1976/1976Karnataka12.pdf | P4: (2) A copy of the said notification shall be sent to the Corporation which shall, within thirty days from the date of receipt thereof, forward to the Authority for transmission to the Government as hereinafter provided, any representation which the Corporation may think fit to make with regard to the scheme. | Q4: I have left the Score blank for three reasons. (1) SCALE-MISMATCH. The rubric bands described for UPD1a run from 0 to 10, but the Score column allows only 0 to 5. The Detailed Methodology text was not given to me in this task. Without it I cannot confirm how a band converts to the 0-5 input, so I have not scored. Possible raw band values, recorded only so a person can check them: 7.5 or 10 for development schemes, 5 for s.25 works, 10 for s.32 layouts. (2) Plan-scope question for the team. I checked Step 2's evidence against BDA-02 (PRS copy, amended up to Act 42 of 2026), and it is accurate. The wording supports these readings: - s.17(2): the Corporation must be sent the scheme notification and may make representations within 30 days. Its representations go to the Government through BDA. - s.17(4): if the Corporation sends nothing, its concurrence is 'deemed to have been given'. - s.18(1): BDA 'shall submit' the scheme to the Government 'after consideration of representations, if any', with any changes it 'may think fit'. So BDA must consider the representations but need not accept them. This is not a veto. - s.25(1) proviso: for works inside City limits, the Corporation 'shall be consulted'. This is consultation only. - s.32(1) provisos: BDA needs the Corporation's concurrence to sanction private layouts, but these are not plans BDA prepares itself. - s.26: schemes made 'on the recommendation of the Corporation' are optional. For the master plan under the KTCP Act (BDA-06), the sections Step 2 read show only public notice and comments. The KTCP Rules and the BDA Rules are not in the Citation Sheet, so I cannot claim affirmative absence of a ULG role at master-plan level. The team needs to decide whether scheme-level and layout-level mechanisms count as 'spatial/sectoral plans' for this question. (3) Jurisdiction and successor-body question. BDA-03 (GBGA 2024, Act 36 of 2025): - s.14(2)(a): 'Notwithstanding anything contained in any other law', GBA is the KTCP 'Planning Authority' for the Greater Bengaluru Area. - s.14(4): GBA integrates and supervises 'the Bangalore Development Authority', and its directions are binding. - s.15(1): GBA makes the master plan and mobility plans. BDA-05 (KTCP Amendment Bill 2025, as passed by the Assembly only) would limit BDA to the Bengaluru Metropolitan Area 'excluding the Greater Bengaluru Area'. Its s.1(2) says it comes into force on a date the State notifies, and no commencement notification is in the Citation Sheet. The BDA Act still says 'Corporation of the City of Bangalore' (s.2(i)). No source shows GBA or the City Corporations formally substituted. For a person to check: (a) the UPD1a methodology and how its bands convert to the 0-5 Score; (b) whether scheme or layout mechanisms count as plans; (c) whether BDA still plans any area inside a ULG; (d) whether the KTCP Amendment 2025 has commenced; (e) the KTCP and BDA Rules, which are needed before anyone can claim affirmative absence at master-plan level. Only PRS copies of the Acts were available. | R4: The citation didn't settle every input. "Score" left blank: the Citation Sheet doesn't decide it.
A5: UPD1a | B5: Bengaluru – BMRCL | D5: =IFERROR(UPD1a!L16,"") -> 0 | H5: =IF(OR(F5="",NOT(ISNUMBER(D5))),"",IF(ABS(F5-D5)<0.001,"Yes","No")) | I5: =IF(ISNUMBER(F5),F5,D5) -> 0 | J5: =IF(ISNUMBER(F5),"Expert (overrides AI)",IF(ISNUMBER(D5),"AI","Not scored yet")) -> AI | K5: Left for a person | L5: Partially Answered | M5: ANSWER: No source in the Citation Sheet requires BMRCL to prepare its own spatial or sectoral plans together with the ULG (the Greater Bengaluru Authority (GBA) and its City Corporations). The Sheet contains no Act that constitutes BMRCL, because BMRCL is a company. The planning relationship runs the other way, from the ULG to BMRCL. Under the GBA Act, the GBA makes the master plan and mobility plans for the Greater Bengaluru Area. It also integrates and supervises 'public authorities', naming BMRCL, and its directions to them are binding. It may give public authorities the job of planning major infrastructure projects, and they must assist it. Separately, the BMLTA Act makes BMRCL-type transport agencies consult BMLTA, a state transport authority and not the ULG, when preparing their investment programmes. None of this is a duty on BMRCL to consult the ULG, obtain its concurrence or plan jointly with it. Not every legal layer is in the Sheet, so I cannot show that such a duty is affirmatively absent. | EVIDENCE: ULG side: Greater Bengaluru Governance Act, 2024 (Act 36 of 2025), PRS text [BMRCL-02]. (1) s.2(54) names 'Bengaluru Metro Rail Corporation Limited' as a 'Public authority'. (2) s.14(4) 'Co-ordination and Supervision of Public Authorities': GBA integrates and supervises BMRCL and others, 'issuing directions for the same which shall be binding'. Public authorities 'shall cooperate ... and obey its directions'. This is a general supervisory power that a ULG body can ex | N5: The Greater Bengaluru Governance Act, 2024 Act No. 36 of 2025 [BMRCL-02] | O5: https://prsindia.org/files/bills_acts/acts_states/karnataka/2025/Act36of2025KA.pdf | P5: The Greater Bengaluru Authority may assign the task of planning the major infrastructural projects in the Greater Bengaluru Area to such public authorities or any other agencies, bodies carrying out civic functions in the Greater Bengaluru Area or take such assistance from these agencies as is necessary for successful execution of the projects. The agencies shall be bound to assist the Greater Bengaluru Authority when called up on to do so. | Q5: I left the Score blank for four reasons. (1) SCALE-MISMATCH. The Step 2 record says the UPD1a rubric bands run 0-10 but the Max Score is 5. The input asks for a number from 0 to 5. The full rubric text and Detailed Methodology were not in the task material, so I cannot choose a band or convert one. A person needs to confirm the band and the conversion. (2) RUBRIC-GAP / relationship judgement. I re-read BMRCL-02 (Greater Bengaluru Governance Act, Act 36 of 2025, as enacted, GBA era). It confirms these provisions: - s.2(54) names BMRCL as a 'Public authority'. - s.14(4): GBA integrates and supervises BMRCL's activities through directions 'which shall be binding'. Public authorities 'shall cooperate ... and obey its directions'. - s.15(1): GBA 'shall be responsible to make master plan and mobility plans'. - s.15(5): GBA 'may' give public authorities the job of planning major infrastructure projects. The agencies 'shall be bound to assist' when called on. - s.13(1)(j): BMRCL's MD sits on the GBA Executive Committee. These are ULG powers over BMRCL, plus a duty on BMRCL to assist when asked. None of them requires BMRCL to prepare its own plans in consultation with the ULG or with its concurrence. Whether they count as 'coordination with the ULG' is a methodological question for a person to decide. On the other side, the BMLTA Act s.24(b) [BMRCL-08] makes consultation mandatory ('shall be prepared in consultation with the Authority'). But that Authority is BMLTA, a state transport authority, not the ULG. ULG Mayors and Commissioners sit on BMLTA only under the 2025 Amendment Bill [BMRCL-38], and the Sheet does not show that Bill enacted. (3) No affirmative absence, so I cannot give 0. These instruments are missing from the Citation Sheet: - the Metro Railways (Construction of Works) Act, 1978 (only the 2009 amending Bill, BMRCL-37, is present) - BMRCL's Memorandum and Articles of Association - GBA Rules and Regulations - BMLTA Regulations - the notification extending the Metro Railways (O&M) Act to Bengaluru - a consolidated, current KTCP Act (4) What was checked: BMRCL-02, BMRCL-03, BMRCL-04, BMRCL-06, BMRCL-08, BMRCL-09 and BMRCL-38, as recorded in Step 2, and I re-read BMRCL-02 ss.14-15 myself. The Step 2 answer matches the source text. A person should check: (a) the band and the 0-10 to 5 conversion; (b) whether ss.14(4) and 15(5) earn credit as coordination; (c) the missing instruments listed in (3); (d) whether the BMLTA Amendment Bill 2025 has been enacted. | R5: The citation didn't settle every input. "Score" left blank: the Citation Sheet doesn't decide it.
A6: UPD1a | B6: Bengaluru – BMRDA | D6: =IFERROR(UPD1a!L17,"") -> 0 | H6: =IF(OR(F6="",NOT(ISNUMBER(D6))),"",IF(ABS(F6-D6)<0.001,"Yes","No")) | I6: =IF(ISNUMBER(F6),F6,D6) -> 0 | J6: =IF(ISNUMBER(F6),"Expert (overrides AI)",IF(ISNUMBER(D6),"AI","Not scored yet")) -> AI | K6: Left for a person | L6: Partially Answered | M6: ANSWER: I can't settle this from the Citation Sheet. The operative text of the BMRDA Act, 1985 on how the Structure Plan is prepared, and on who sits on the Authority, is not in the sheet. Nothing in the sources I read requires BMRDA to prepare its Structure Plan or schemes jointly with the ULG (GBA and its City Corporations), with ULG concurrence, or after consulting the ULG. The links that do exist run the other way. BMRDA has a duty to coordinate the city government's activities. Under the state planning Act (KTCP Act), Planning Authorities in the region must send their master plans to the State Government through BMRDA, which acts as Director of Town Planning for those plans. Neither of these is the ULG taking part in BMRDA's own plans. | EVIDENCE: (1) BMRDA side. The functions page on BMRDA's website (BMRDA-02) paraphrases the Act and is not the Act's own text. It lists: "To prepare a structure plan for thent [sic] of the Bangalore Metropolitan Region"; "To entrust to any local authority the work of execution of any development plan or town planning scheme"; "To co-ordinate the activities of the Bangalore Development Authority, the Corporation of the City of Bangalore, the Bangalore WaterSupply and Sewerage Board...". BMRDA's 2022-23 Annual Report (BMRDA-03, p.10) says these functions sit in s.9 of the Act. In this list BMRDA coordinates the ULG and may extend assistance to or entrust work to local authorities. None of the listed functions requires ULG consultation or co | N6: Annual Report of Bangalore Metropolitan Region Development Authority for the year 2022-2023 [01-04-2022 to 31-03-2023] [BMRDA-03] | O6: https://kla.kar.nic.in/council/house/Paperlaid/152/37.pdf | P6: The Executive Committee is chaired by the Minister for Urban Development, while the Metropolitan Commissioner is the Vice Chairman and the Mayor of Bangalore, the Secretaries to Government and heads of several related departments/ organisations are the Members. | Q6: I left the score blank for two separate reasons. (1) SCALE-MISMATCH. The Step 2 record says the rubric bands are 0/2.5/5/7.5/10, but the Max Score is 5. Under the v2 rules I can't map or interpolate a band, so the research team needs to confirm the scale before anyone scores this. (2) The evidence is incomplete, so I can't show affirmative absence. The Citation Sheet does not contain the text of the BMRDA Act 1985 itself (its Structure Plan preparation, publication and approval sections, or its membership provisions). It also lacks the BMRDA Rules and Regulations. Correction to Step 2: Step 2 says it found no ULG role. But the BMRDA 2022-23 Annual Report (BMRDA-03, p.10, Item 3) shows a formal ULG presence on BMRDA's governing bodies: - The Mayor of Bangalore sits on the Executive Committee. - The Act provides for the Government to nominate representatives of the Local Authorities from the Region to the Authority. However, the report says these nominated seats have been vacant since July 2005. This is the Annual Report's paraphrase, not the Act's text. It also predates GBA: the Mayor post and BBMP have since been replaced by GBA and its City Corporations. Someone needs to check: - whether the Executive Committee or the Authority approves the Structure Plan (the Revised Structure Plan-2031 was approved by Government order UDD/149/BMR/2014 dated 08/05/2017, per p.11); - whether a GBA-era official has replaced the Mayor. So a rubric 0 ('no formal role') is not supported. A positive band can't be set without the Act's text and the rubric definitions either. What else I checked: - BMRDA-02, the website functions page. It is a paraphrase of s.9. BMRDA coordinates the ULG and may entrust work to or assist local authorities. It does not mention ULG consultation or concurrence on the Structure Plan. - BMRDA-08, KTCP Act s.81-C. Master plans of Planning Authorities in the region are sent through BMRDA. This runs the opposite way: BMRDA has a role in their plans, not the ULG in BMRDA's. - BMRDA-10, the GBA Act (functions section, the BMPC under Art. 243ZE). BMRDA is not named in the GBA coordination list. I could not read the full BMPC clause. - BMRDA-11, BMLTA Act s.22. This concerns BMLTA, not a ULG role in BMRDA's plans. A person should obtain the BMRDA Act 1985 (sections on composition, the Executive Committee and the Structure Plan) and the BMRDA Rules. They should then confirm the rubric scale and score this. | R6: The citation didn't settle every input. "Score" left blank: the Citation Sheet doesn't decide it.
A7: UPD1a | B7: Surat – SUDA | D7: =IFERROR(UPD1a!L18,"") | H7: =IF(OR(F7="",NOT(ISNUMBER(D7))),"",IF(ABS(F7-D7)<0.001,"Yes","No")) | I7: =IF(ISNUMBER(F7),F7,D7) | J7: =IF(ISNUMBER(F7),"Expert (overrides AI)",IF(ISNUMBER(D7),"AI","Not scored yet")) -> Not scored yet | K7: Left for a person | L7: Insufficient Evidence | R7: Step 2 found no evidence: a source needs to be found and added. Step 2 found no evidence (Insufficient Evidence). Source needed: The full current consolidated text of the Gujarat Town Planning and Urban Development Act, 1976, specifically ss.9-17 and 19-22 on preparing, publishing, revising and sanctioning development plans and on UDA board composition, plus the town planning scheme sections, from an official Gujarat legislative or Urban Development Department source. Also the Gujarat Metropolitan Planning Committees Act, 2008, and the full GPMC Act 1949, to check for any ULG approval or consultation role in SUDA's plans.
A8: UPD1a | B8: Surat – GMRC | D8: =IFERROR(UPD1a!L19,"") | H8: =IF(OR(F8="",NOT(ISNUMBER(D8))),"",IF(ABS(F8-D8)<0.001,"Yes","No")) | I8: =IF(ISNUMBER(F8),F8,D8) | J8: =IF(ISNUMBER(F8),"Expert (overrides AI)",IF(ISNUMBER(D8),"AI","Not scored yet")) -> Not scored yet | K8: Left for a person | L8: Insufficient Evidence | R8: Step 2 found no evidence: a source needs to be found and added. Step 2 found no evidence (Insufficient Evidence). Source needed: Needed: the full text of the Metro Railways (Construction of Works) Act 1978 and the Metro Railways (Operation & Maintenance) Act 2002 (as amended in 2009), plus the central notification applying them to Surat, from an official Government of India source; GMRC's Memorandum and Articles of Association and the tripartite GoI–GoG–GMRC MoU; any Gujarat UMTA Act or notification; the current consolidated Gujarat Town Planning and Urban Development Act 1976 from the Gujarat Legislative Department; any Gujarat GO or Rules on metro-corridor or TOD planning that give Surat Municipal Corporation a consultation or concurrence role.
A9: UPD1b | B9: Bengaluru – BWSSB | D9: =IFERROR(UPD1b!L13,"") -> 5 | H9: =IF(OR(F9="",NOT(ISNUMBER(D9))),"",IF(ABS(F9-D9)<0.001,"Yes","No")) | I9: =IF(ISNUMBER(F9),F9,D9) -> 5 | J9: =IF(ISNUMBER(F9),"Expert (overrides AI)",IF(ISNUMBER(D9),"AI","Not scored yet")) -> AI | K9: Left for a person | L9: Insufficient Evidence | R9: Step 2 found no evidence: a source needs to be found and added. Step 2 found no evidence (Insufficient Evidence). Source needed: Any of these would answer the question: the BWSSB Vision Document / strategic Master plan 2050 itself, including its preparation, stakeholder-consultation and approval chapters; minutes of the BWSSB Board meeting and Consultative Committee (s.14) meetings that considered or approved it, with attendance and any GBA or City Corporation input; GBA or City Corporation council or Executive Committee resolutions or letters commenting on BWSSB plans; or a recent BWSSB annual report (after 2016-17) describing how the plan was prepared.
A10: UPD1b | B10: Bengaluru – BMTC | D10: =IFERROR(UPD1b!L14,"") | H10: =IF(OR(F10="",NOT(ISNUMBER(D10))),"",IF(ABS(F10-D10)<0.001,"Yes","No")) | I10: =IF(ISNUMBER(F10),F10,D10) | J10: =IF(ISNUMBER(F10),"Expert (overrides AI)",IF(ISNUMBER(D10),"AI","Not scored yet")) -> Not scored yet | K10: Left for a person | L10: Insufficient Evidence | R10: Step 2 found no evidence: a source needs to be found and added. Step 2 found no evidence (Insufficient Evidence). Source needed: BMTC's latest plan document (annual development plan, business or fleet plan, or route rationalisation plan) showing ULG inputs or concurrence. BMTC Board minutes recording GBA/City Corporation (or earlier BBMP) participation. GBA or City Corporation council or standing-committee resolutions or letters commenting on BMTC plans, and any BMTC replies. For Bengaluru bus priority lanes specifically: the joint ULB-BMTC proposal or DULT sanction record naming the ULG as co-applicant.
A11: UPD1b | B11: Bengaluru – BDA | D11: =IFERROR(UPD1b!L15,"") | H11: =IF(OR(F11="",NOT(ISNUMBER(D11))),"",IF(ABS(F11-D11)<0.001,"Yes","No")) | I11: =IF(ISNUMBER(F11),F11,D11) | J11: =IF(ISNUMBER(F11),"Expert (overrides AI)",IF(ISNUMBER(D11),"AI","Not scored yet")) -> Not scored yet | K11: Left for a person | L11: Insufficient Evidence | R11: Step 2 found no evidence: a source needs to be found and added. Step 2 found no evidence (Insufficient Evidence). Source needed: The documents from BDA's latest plan-making cycle: the latest Revised Master Plan or draft master plan and its report, especially any chapter on stakeholder or agency consultation. Also BDA Authority meeting minutes approving the draft plan; BBMP, GBA or City Corporation council or standing-committee resolutions, or letters commenting on the BDA draft plan; and any BDA record of how it considered and answered those ULG comments. A government notification or official statement would also be needed to show which body runs the current master-plan cycle for the Greater Bengaluru Area, and whether the KTCP (Amendment) 2025 has come into force.
A12: UPD1b | B12: Bengaluru – BMRCL | D12: =IFERROR(UPD1b!L16,"") | H12: =IF(OR(F12="",NOT(ISNUMBER(D12))),"",IF(ABS(F12-D12)<0.001,"Yes","No")) | I12: =IF(ISNUMBER(F12),F12,D12) | J12: =IF(ISNUMBER(F12),"Expert (overrides AI)",IF(ISNUMBER(D12),"AI","Not scored yet")) -> Not scored yet | K12: Left for a person | L12: Insufficient Evidence | R12: Step 2 found no evidence: a source needs to be found and added. Step 2 found no evidence (Insufficient Evidence). Source needed: Records from BMRCL's latest plan-making cycle showing what the ULG did: (a) the latest DPR (e.g. Phase-3 or later) with its stakeholder-consultation annex; (b) BMRCL letters asking BBMP, GBA or the City Corporations for comments, and their replies; (c) minutes of GBA authority meetings or City Corporation council or standing-committee meetings that discussed BMRCL plans (e.g. the Parking Policy or new corridors); (d) a GO or Board approval note for the Metro Parking Policy 2025 listing who was consulted; (e) a recent BMRCL annual report (FY2023-24 or later) describing coordination with the ULG.
A13: UPD1b | B13: Bengaluru – BMRDA | D13: =IFERROR(UPD1b!L17,"") | H13: =IF(OR(F13="",NOT(ISNUMBER(D13))),"",IF(ABS(F13-D13)<0.001,"Yes","No")) | I13: =IF(ISNUMBER(F13),F13,D13) | J13: =IF(ISNUMBER(F13),"Expert (overrides AI)",IF(ISNUMBER(D13),"AI","Not scored yet")) -> Not scored yet | K13: Left for a person | L13: Insufficient Evidence | R13: Step 2 found no evidence: a source needs to be found and added. Step 2 found no evidence (Insufficient Evidence). Source needed: Any of these would answer it: the RSP-2031 report (draft or final), especially any chapter on stakeholder consultation; BMRDA Authority or Executive Committee minutes from the RSP-2031 preparation and approval (2014-2017) showing BBMP or Mayor inputs; BBMP council or standing committee resolutions or letters commenting on the draft Structure Plan, and BMRDA's responses; or, if a new Structure Plan cycle has started, GBA-era consultation records.
A14: UPD1b | B14: Surat – SUDA | D14: =IFERROR(UPD1b!L18,"") | H14: =IF(OR(F14="",NOT(ISNUMBER(D14))),"",IF(ABS(F14-D14)<0.001,"Yes","No")) | I14: =IF(ISNUMBER(F14),F14,D14) | J14: =IF(ISNUMBER(F14),"Expert (overrides AI)",IF(ISNUMBER(D14),"AI","Not scored yet")) -> Not scored yet | K14: Left for a person | L14: Answered — Verified Source | M14: ANSWER: Yes, at the level of formal consultation. In SUDA's latest plan cycle in the Citation Sheet, the Development Plan 2035 (2013-2017), the Mayor of Surat Municipal Corporation (SMC) was formally invited on 22.04.2016 to discuss the plan, together with all MPs, MLAs and the Surat Zilla Panchayat President, and their suggestions were invited. The plan document gives no record of what SMC itself said or how SUDA considered or answered SMC's inputs. It also shows no joint preparation with SMC and no concurrence or approval by SMC. This matches the 5 band ('formally consulted or invited to provide inputs, but no evidence of how these inputs were considered'). | EVIDENCE: (1) SUDA-14, DP 2035 (2017), Ch.16 'Stakeholders Consultation', p.183 (doc p.166): 'All MP, MLA, Surat Zilla Panchayat President and Mayor (SMC) were invited on 22.04.2016 for detailed discussion on Development Plan 2035... their suggestions on the same were invited.' Table 116 (p.184 / doc p.167) gives only a combined count of 136 suggestions from all elected representatives, split by topic (Zoning 42, Road 39, Reservation 23, GDCR 16, SUDA Extension 7, Others 9). It does not say which came from the Mayor or SMC, and gives no response to them. (2) SUDA-14 §2.2 (pp.31-32): study groups, eight sub-committees and a Core Committee were formed. Ch.16 (p.183) says these committees 'included internal as well as external members' and that about 60 meetings were held. Members are not named, so no SMC role on these co | N14: DEVELOPMENT PLAN 2035 2017 SURAT URBAN DEVELOPMENT AUTHORITY [SUDA-14] | O14: https://www.sudaonline.org/wp-content/uploads/2017/03/SUDA-DP-2035-report-final-22.02.2017.pdf | P14: All MP, MLA, Surat Zilla Panchayat President and Mayor (SMC) were invited on 22.04.2016 for detailed discussion on Development Plan 2035. Discussion on various issues were carried out and their suggestions on the same were invited. | Q14: SCALE-MISMATCH. The Step 2 answer says the rubric runs 0-10 (top band 10 = substantive participation; band 5 = formally consulted or invited to give inputs, with no evidence of how they were considered). The Max Score is 5, and the input column also asks for 0-5. The question-bank anomaly rule says not to score a scale mismatch, so the Score is left blank. RAW BAND = 5 on the 0-10 rubric. A reviewer must decide how this maps to the 0-5 workbook scale. Do not just enter 5 or halve it to 2.5 without confirmation. The source supports Step 2's band reading: (1) SUDA-14 Ch.16, p.183: SMC's Mayor was invited on 22.04.2016, together with MPs, MLAs and the Zilla Panchayat President, to discuss DP 2035, and their suggestions were invited. (2) Table 116 gives only a combined count of 136 suggestions from all elected representatives. Nothing is attributed to SMC, and there is no record of how SUDA answered them. (3) §2.2 and Ch.16: the Core Committee and the eight sub-committees had 'internal as well as external members', but members are not named, so no SMC role is shown. (4) The SUDA Board in the 2016 SUDA Board list (§1.4.1, Table 5 in SUDA-14) includes SMC's Standing Committee Chairman, Municipal Commissioner and City Engineer. This is institutional design only. No Board minutes approving DP 2035 are in the Sheet. (5) The general public notice under s.13 is not ULG consultation. Please check: (a) how the 0-10 rubric maps to the 0-5 Max Score; (b) whether a mixed meeting of elected representatives that included the Mayor counts as formal ULG consultation; (c) whether SUDA Board or Core Committee minutes exist that could support a higher band. The Sheet has no SMC resolution or comments on DP 2035 and no SUDA response to SMC inputs. | R14: The citation didn't settle every input. "Score" left blank: the Citation Sheet doesn't decide it.
A15: UPD1b | B15: Surat – GMRC | D15: =IFERROR(UPD1b!L19,"") | H15: =IF(OR(F15="",NOT(ISNUMBER(D15))),"",IF(ABS(F15-D15)<0.001,"Yes","No")) | I15: =IF(ISNUMBER(F15),F15,D15) | J15: =IF(ISNUMBER(F15),"Expert (overrides AI)",IF(ISNUMBER(D15),"AI","Not scored yet")) -> Not scored yet | K15: Left for a person | L15: Answered — Verified Source | M15: ANSWER: Yes, for the latest plan cycle in the Citation Sheet (the Surat Metro Rail Phase-I DPR, December 2018), the DPR records substantive participation by Surat Municipal Corporation (SMC). SMC commissioned the Comprehensive Mobility Plan (CMP) and the travel-demand study the DPR is built on. Corridor options were presented to SMC authorities 'on various occasions', and the three corridors sent to the High Powered Committee were shortlisted 'on the suggestions of SMC & CEPT'. SMC's TOD revenue figures, land rates and its decision on the railway-station hub (MMTH) tunnel road were written into the DPR. This is documented consideration of, and response to, ULG input, which fits the top band ('substantive participation'). | EVIDENCE: (1) GMRC-08 DPR Ch.1 p.92: alignment options were 'presented before the concerned authorities of Surat Municipal Corporation (SMC) on various occasions', and 'on the suggestions of SMC & CEPT, following three corridors were shortlisted and presented before High Powered Committee (HPC)' on 13.01.2017. The HPC then approved 2 corridors (MoM letter GUDC/METRO/HPC/2017/182 dt 23.01.2017). (2) GMRC-08 Exec Summary pp.8-9 and Ch.2 pp.98-102: the CMP 2017 'got completed by Surat Municipal Corporation (SMC) through ... CEPT'. The demand estimate for Phase-I corridors was done by CEPT, 'entrusted this assignment by Surat Municipal Corporation (SMC) vide their letter No. CE.Spl.Cell/Out/339 dated 31.08.2016'. A gist of the CMP is included in the DPR. (3) GM | N15: DPR for Metro Rail Project in Surat, Gujarat (December 2018) [GMRC-08] | O15: https://www.gujaratmetrorail.com/wp-content/uploads/DPR/Surat-DPR-2020_opt.pdf | P15: Subsequently, on the suggestions of SMC & CEPT, following three corridors were shortlisted and presented before High Powered Committee (HPC) in a meeting held on 13.01.2017 at Ahmedabad | Q15: I left the Score blank because of SCALE-MISMATCH. Step 2 and the question-bank anomaly note for UPD 1b both say the top rubric band is 'raw 10', while the input runs 0 to 5. The top band is not the Max Score and is not a sum of components, so I am not converting it. The team needs to confirm how the 10-point rubric maps onto the 0-5 input. The evidence itself fits the top band ('substantive ULG participation: documented consideration of and response to ULG inputs'). I checked these points against GMRC-08 (DPR, December 2018, Phase-I): (1) The alignment options were presented to SMC 'on various occasions'. The three corridors sent to the HPC were then shortlisted 'on the suggestions of SMC & CEPT' (Ch.1 p.92). (2) SMC commissioned the CMP 2017 and the CEPT demand study (letter CE.Spl.Cell/Out/339 dated 31.08.2016). The DPR says it was prepared 'in line with' that study (Exec Summary §0.2.1, §0.3; Ch.2 §2.3.1). (3) The MMTH integration and tunnel-road decision came out of 'a series of meetings ... in the office of The Commissioner, Surat Municipal Corporation'. SMC supplied the cost estimate, and the executing agency is to be decided 'in consultation with SMC' (§0.19.2; Ch.19 §19.13). (4) SMC's TOD revenue figures (letter dated 22-12-2017) were written into the DPR (Ch.18 p.692). Points a person should check: (a) Final corridor approval came from a state HPC, not SMC. SMC shaped the inputs and the shortlist but did not concur or approve. (b) The DPR was prepared by DMRC at the request of GoG/MEGA. GMRC-25 says MEGA is GMRC's former name, which is what ties this plan to GMRC. (c) I could not see Annexure-A / Table 1.7, the list of SMC presentations. (d) The Citation Sheet has no Phase-II plan, so it is unconfirmed that this is the latest plan cycle. (e) The task input leaves the ULG blank. Only the DPR names SMC as the city corporation. (f) GMRC-09, -10 and -11 record consultations with communities and the public, not with the ULG. If the team confirms the top band maps to the Max Score, the evidence would support 5, subject to points (d) and (e). | R15: The citation didn't settle every input. "Score" left blank: the Citation Sheet doesn't decide it.
A16: UPD2a | B16: Bengaluru – BWSSB | D16: =IFERROR(UPD2a!L13,"") -> 0 | H16: =IF(OR(F16="",NOT(ISNUMBER(D16))),"",IF(ABS(F16-D16)<0.001,"Yes","No")) | I16: =IF(ISNUMBER(F16),F16,D16) -> 0 | J16: =IF(ISNUMBER(F16),"Expert (overrides AI)",IF(ISNUMBER(D16),"AI","Not scored yet")) -> AI | K16: Left for a person | L16: Partially Answered | M16: ANSWER: I can't confirm or rule out a mandate from the Citation Sheet. The BWSSB Act says nothing about it: it contains no provision, with either 'shall' or 'may', requiring BWSSB's water supply or sewerage schemes to conform to or be consistent with a city, metropolitan or regional master plan or development plan. On the city government (ULG) side, the Greater Bengaluru Governance Act gives the Greater Bengaluru Authority (GBA) binding coordination and direction powers over BWSSB. It does not state a duty on BWSSB to make its plans consistent with the master plan. The Karnataka Town and Country Planning Act, 1961, which the methodology says to review, is not in the Citation Sheet. So I can't establish that no such provision exists, which a score of 0 would require. | EVIDENCE: (1) BWSSB Act 1964 (BWSSB-02). s.15(1) gives the general duty to supply water and provide sewerage in the Bangalore Metropolitan Area. Under s.15(2)(b)-(c) 'it shall be the duty of the Board to take steps from time to time' to prepare and carry out water supply and sewerage schemes. The proviso says schemes costing over Rs 1 crore need 'the approval of the State Government'. s.15(3) sets what schemes must contain (piped supply to every part with houses, and so on). None of these refers to a master plan or development plan. Other provisions: s.14 creates an advisory Consultative Committee (advises on 'major questions of policy and major schemes'), which is advice, not a consistency duty. Under s.89 the | N16: The Greater Bengaluru Governance Act, 2024 Act No. 36 of 2025 [BWSSB-04] | O16: https://prsindia.org/files/bills_acts/acts_states/karnataka/2025/Act36of2025KA.pdf | P16: issuing directions for the same which shall be binding; and all the public authorities shall cooperate with the Greater Bengaluru Authority for successful coordination and obey its directions issued, in discharge of functions assigned in this Act. | Q16: I left the score blank. The Citation Sheet doesn't show whether there is a legal requirement for BWSSB's plans to be consistent with a city, metropolitan or regional master plan or development plan, and a 0 needs affirmative absence, which I can't show. I agree with the Step 2 answer. (1) BWSSB Act 1964 (BWSSB-02), PRS copy as amended up to 2010. I re-read s.15(1)-(7), the general duties and schemes. s.15(2)(b)-(c) say 'it shall be the duty of the Board to take steps from time to time' to prepare and carry out water supply and sewerage schemes. The proviso requires State Government approval for schemes over Rs 1 crore. s.15(3) sets what schemes must contain. None of these refers to a master plan or development plan. The Step 2 answer also reports that s.14 (advisory Consultative Committee) and s.89 (State directions) have no conformity clause. (2) Greater Bengaluru Governance Act 2024, Act 36 of 2025 (BWSSB-04), which is the city government (ULG) side, GBA era. s.14(2)(a) makes GBA the Planning Authority under the KTCP Act 1961. s.14(3)(b) gives GBA binding directions for coordinating the execution of schemes that implement GBA plans. s.14(4) names BWSSB among the public authorities GBA integrates and supervises, and those authorities 'shall cooperate... and obey its directions'. s.15(1) puts the master plan on GBA. The duty to 'incorporate the infrastructure development plan' falls on the City Corporations, not BWSSB. s.15(5) says agencies are 'bound to assist'. s.19 covers State Government directions. These are binding direction and coordination powers held by GBA and the State. None of them is an express requirement that BWSSB's own plans or schemes conform to the master plan. Whether a binding direction power counts as the middle band (alignment that is discretionary or not mandated) is a judgement for the team: CONFIRM. (3) Missing layers: the Karnataka Town and Country Planning Act 1961 isn't in the Sheet. It is the instrument most likely to make master plans or development plans binding on public authorities or their works, and the methodology says to review it. BWSSB Rules (s.87), BWSSB Regulations (s.88) and any GO on BWSSB planning are also not in the Sheet. Searches of the Sheet for 'master plan conform consistent development plan public authorities' and 'Town and Country Planning Act comprehensive development plan Board schemes' found nothing beyond the GBA Act provisions above. (4) Era: the PRS copy of the BWSSB Act still names the Bruhat Bangalore Mahanagara Palike. No source in the Sheet shows GBA or the City Corporations substituted into the BWSSB Act: CONFIRM. To score this, the team needs to add the official text of the KTCP Act 1961 (current amended version), especially the provisions on the effect of master plans on public authorities and their development, and confirm the band for the GBA direction powers. | R16: The citation didn't settle every input. "Score" left blank: the Citation Sheet doesn't decide it.
A17: UPD2b | B17: Bengaluru – BWSSB | D17: =IFERROR(UPD2b!L13,"") | H17: =IF(OR(F17="",NOT(ISNUMBER(D17))),"",IF(ABS(F17-D17)<0.001,"Yes","No")) | I17: =IF(ISNUMBER(F17),F17,D17) | J17: =IF(ISNUMBER(F17),"Expert (overrides AI)",IF(ISNUMBER(D17),"AI","Not scored yet")) -> Not scored yet | K17: Left for a person | L17: Insufficient Evidence | R17: Step 2 found no evidence: a source needs to be found and added. Step 2 found no evidence (Insufficient Evidence). Source needed: (1) BWSSB's current water supply and sewerage master plan or 2050 vision and strategic master plan document, showing its population source and how it sets service areas and sites major works (treatment plants, pumping stations, reservoirs, trunk mains). (2) The applicable statutory spatial plan for the same area: the BDA Revised Master Plan in force, or any GBA- or BMRDA-era development or regional plan, with its land-use and growth framework and population projections. (3) Where readily available, land-use conversion or regularisation orders or records for major BWSSB treatment plants or trunk infrastructure.
A18: UPD2c | B18: Bengaluru – BMTC | D18: =IFERROR(UPD2c!L14,"") -> 2.5 | H18: =IF(OR(F18="",NOT(ISNUMBER(D18))),"",IF(ABS(F18-D18)<0.001,"Yes","No")) | I18: =IF(ISNUMBER(F18),F18,D18) -> 2.5 | J18: =IF(ISNUMBER(F18),"Expert (overrides AI)",IF(ISNUMBER(D18),"AI","Not scored yet")) -> AI | K18: Left for a person | L18: Partially Answered | M18: ANSWER: No source in the Citation Sheet says that BMTC 'shall' (or 'may') make its own spatial or sectoral plan consistent with the city master plan or the metropolitan/regional plan. The only binding consistency duty found is indirect, and it ties BMTC to the Comprehensive Mobility Plan (CMP), not to a master plan. Under the Bengaluru Metropolitan Land Transport Authority (BMLTA) Act, an 'Urban Transport Agency' such as BMTC needs BMLTA approval for major urban transport projects, judged on consistency with the CMP. BMLTA prepares the CMP 'in conjunction with' the applicable land use plan. Whether this two-step chain, or the general Town and Country Planning (T&CP) rule that all development must conform to the master plan, counts for this question is a methodology call. Score left blank. | EVIDENCE: (1) Parastatal Act: Road Transport Corporations Act, 1950 (BMTC-02). s.3 (setting up corporations: coordination with other transport), s.5 (Board), s.18 (general duty: 'efficient, adequate, economical and properly co-ordinated system of road transport services'), s.19 (powers), s.20 (route extension schemes). None of these mentions a master plan, a development plan or a land-use plan. (2) BMLTA Act, 2022 (Karnataka Act 6 of 2023; PRS text with Act 10 of 2026 appended) (BMTC-06). s.2(ff): 'Urban Transport Agency' means 'both the private and public agencies engaged in providing of Urban Mobility'. The Statement of Objects names the Bengaluru Metropolitan Transport Corporation among | N18: The Bengaluru Metropolitan Land Transport Authority Act, 2022 Act No. 6 of 2023 (Amendment appended: 10 of 2026) [BMTC-06] | O18: https://prsindia.org/files/bills_acts/acts_states/karnataka/2023/Act6of2023Karnataka.pdf | P18: (a) The Sectoral Mobility Investment Program shall be aligned with the goals of the Comprehensive Mobility Plan; (b) The Sectoral Mobility Investment Program shall be prepared in consultation with the Authority; | Q18: Score left blank. The Citation Sheet does not support 2.5 (BMTC 'shall' make its plans consistent with the master/metropolitan plan) or 1.25 (a 'may' provision). It also does not establish affirmative absence, so 0 cannot be given. I checked the Step 2 answer against the sources and add these findings. (1) BMTC-06 s.24(a) is a binding 'shall', but it ties the Sectoral Mobility Investment Program of each Urban Transport Agency to the goals of the Comprehensive Mobility Plan (CMP), not to the master plan. Step 2 had not read s.24; this is the strongest provision found. s.25(1)(c) also requires extra Annual Implementation Plan projects to 'align with the Comprehensive Mobility Plan goals'. s.19(1) adds project approval 'from the perspective of consistency with the Comprehensive Mobility Plan'. The CMP is prepared by BMLTA 'in conjunction with ... the land use plan' (s.21(2)), so the link to the master plan is indirect and is BMLTA's duty, not BMTC's. (2) BMTC-04 (GBA Act 36 of 2025): s.14(4) names BMTC among the public authorities that GBA integrates and supervises. GBA's directions are binding, and BMTC must incorporate GBA's coordinating role in its Memorandum of Association. s.14(3)(b) makes GBA directions binding when it coordinates schemes that implement plans prepared by GBA. s.15(1) makes GBA responsible for the 'master plan and mobility plans', but only the City Corporations are told they 'shall incorporate' GBA's infrastructure development plan; BMTC is not. These are coordination and direction powers, not a mandate that BMTC's own plans be consistent with the master plan. (3) BMTC-07, Karnataka Town and Country Planning (KTCP) Act s.14(1): every development must conform to the Master Plan. This is general development control, not plan consistency, and BMLTA s.60(2) may override it. (4) BMTC-02, Road Transport Corporations Act 1950 (s.3, 5, 18, 19, 20): no mention of a master plan. Gaps: there are no Karnataka rules under the 1950 Act, no BMLTA Rules or Regulations (s.54(ix) leaves the procedure for the City Mobility Investment Program (CMIP) and Sectoral Mobility Investment Programs to regulations), and no BMTC MoA (which s.14(4) of the GBA Act requires to be amended). BMTC-20 (BMTC 'Rules And Regulations' page) was not shown to me. FOR THE TEAM: (a) Does a binding 'shall align with the CMP' duty (BMLTA s.24(a)) meet the 2.5 band, when the CMP is a metropolitan mobility plan prepared with the land use plan? If yes, 2.5 is supported by BMTC-06 s.24(a). If the question requires conformity with the statutory master, metropolitan or regional spatial plan, the result stays 'not found' until the Rules, Regulations and MoA are checked. (b) Please confirm BMTC is an 'Urban Transport Agency' under s.2(ff); BMTC is named only in the Statement of Objects. Source is the PRS text (Act 6 of 2023, with Amendment Act 10 of 2026 appended); this is a secondary source. | R18: The citation didn't settle every input. "Score" left blank: the Citation Sheet doesn't decide it.
A19: UPD2d | B19: Bengaluru – BMTC | D19: =IFERROR(UPD2d!L14,"") | H19: =IF(OR(F19="",NOT(ISNUMBER(D19))),"",IF(ABS(F19-D19)<0.001,"Yes","No")) | I19: =IF(ISNUMBER(F19),F19,D19) | J19: =IF(ISNUMBER(F19),"Expert (overrides AI)",IF(ISNUMBER(D19),"AI","Not scored yet")) -> Not scored yet | K19: Left for a person | L19: Insufficient Evidence | R19: Step 2 found no evidence: a source needs to be found and added. Step 2 found no evidence (Insufficient Evidence). Source needed: Needed: (1) BMTC's current network or route-rationalisation plan, fleet and depot expansion plan, Sectoral Mobility Investment Programme or Annual Implementation Plan under the BMLTA Act ss.24-25, or the 'BMTC Vision 2025' document itself. Any of these should show whether master-plan growth corridors, land use or density projections decide where routes, depots and terminals go. (2) The applicable statutory master plan for Bengaluru: the current revised master plan, or any GBA or BMPC development plan. (3) The Bengaluru Comprehensive Mobility Plan, if BMTC's planning flows through it. (4) For the context check, which does not affect the score: land-use conversion or regularisation records, or BMTC annual report or board notes, for major depots and TTMCs.
A20: UPD3a | B20: Bengaluru – BWSSB | D20: =IFERROR(UPD3a!L13,"") -> 2.5 | H20: =IF(OR(F20="",NOT(ISNUMBER(D20))),"",IF(ABS(F20-D20)<0.001,"Yes","No")) | I20: =IF(ISNUMBER(F20),F20,D20) -> 2.5 | J20: =IF(ISNUMBER(F20),"Expert (overrides AI)",IF(ISNUMBER(D20),"AI","Not scored yet")) -> AI | K20: Left for a person | L20: Partially Answered | M20: ANSWER: Only partly answered. The BWSSB Act contains one binding, general access duty: water supply schemes 'shall' provide piped water to every part of the Bangalore Metropolitan Area that has houses. Where pipes are not practicable at reasonable cost, the scheme must provide a public supply within a reasonable distance of every house. That duty is limited by reasonable cost and covers only water supply schemes, not sewerage. No source in the Citation Sheet sets an explicit requirement on women, the urban poor or slums, persons with disabilities, affordability or concessional tariffs, a minimum or lifeline supply, or access regardless of land tenure. The tariff regulations and the water supply regulations are not in the Citation Sheet, so the score is not decided. | EVIDENCE: (1) BWSSB Act 1964 (PRS text), s.15(2)(b) and s.15(3)(a)-(b), parastatal side: a scheme 'shall inter alia make provision' for piped wholesome water to every part with houses, 'at a reasonable cost'. Where piping is impracticable and the existing supply endangers health, it must provide a supply 'as far as possible' within 'a reasonable distance of every house'. Under s.15(4) the State Government settles any dispute on 'reasonable cost'. s.15(5): the Board 'shall', 'as far as is reasonably practicable', make sure every house has enough water, by using its powers over house owners. (2) s.38(1): the Board 'may', subject to payment by the city corporation (BBMP), 'provide gratuitous supply of wholesome wate | N20: The Bangalore Water Supply and Sewerage Act, 1964 [BWSSB-02] | O20: https://prsindia.org/files/bills_acts/acts_states/karnataka/1964/1964KR36.pdf | P20: A scheme under clause (b) of sub-section (2) shall inter alia make provision,— (a) for a supply of wholesome water in pipes to every part of the Bangalore Metropolitan Area in which there are houses, for the domestic purposes of the occupants thereof | Q20: SCORE LEFT BLANK. This prompt did not give me the question text, the Detailed Methodology or the rubric bands for UPD3a, so I cannot match the evidence to a band. A person must apply the rubric. I checked the Step 2 answer against the source and it holds: (1) BWSSB-02, s.15(3)(a)-(b): a binding 'shall' duty. Water supply schemes must provide piped water to every part of the Bangalore Metropolitan Area that has houses. Where pipes are not practicable at reasonable cost, they must provide a public supply within a reasonable distance of every house. The duty is limited by reasonable cost and practicability (s.15(4): the State Government decides those questions). It covers water supply only, not sewerage. (2) s.38(1) (free public supply through hydrants) and s.61A(d) (bye-laws for 'equitable distribution of water supplied to occupiers') both say 'may', so they are discretionary. (3) The Act has no provision on women, the urban poor or slums, persons with disabilities, lifeline or concessional tariffs, or access regardless of land tenure. (4) BWSSB-13 (website 'Our Services', undated) describes services for the urban poor: lower connection charges (Rs.550 for houses up to 150 sq.ft.; Rs.800 for 151-600 sq.ft.), payment in two instalments, any proof of residence accepted, and shared connections for communities without tenure security. The page cites no regulation, Board resolution or GO for these measures. It describes a programme that dates from 2003-2006 and the JICA project. It is not a binding instrument. I searched the Citation Sheet for tariff, lifeline, slum and concession provisions. None of the BWSS water supply/sewerage regulations (the website cites 'regulation 5.1'), tariff notifications, Board resolutions or GOs is in the sheet. This is the regulations and tariff layer. A 0 is not supportable for two reasons: there is no affirmative absence, and the s.15(3) universal-access duty exists. The top band cannot be judged until the regulations and tariff layer is seen. Step 2 gave a provisional 2.5, which depends on two things the team must confirm: whether that band exists in the rubric (a SCALE-MISMATCH or RUBRIC-GAP check), and whether a general universal-supply duty counts as an equity requirement. Period: the Act text is the PRS copy, as amended up to Act 15 of 2010. Later amendments were not verified. The Act still names BBMP. Whether GBA or the city corporations have been substituted is not verified and should be flagged for the team. | R20: The citation didn't settle every input. "Score" left blank: the Citation Sheet doesn't decide it.
