Workbook

Sheet Scores (start here)
A1: Question | B1: Row | C1: Question text | D1: AI score | E1: Max score | F1: ★ Your score | G1: ★ Your comments | H1: Agrees with AI? | I1: Final score | J1: Score used | K1: Status | L1: Step 2 status | M1: Step 2 answer | N1: Citation | O1: Link | P1: Quote | Q1: AI's reasoning | R1: Why left for a person
A2: UPD1 | B2: Bangalore | C2: Is there a provision for a State Spatial Planning Board which is mandated with planning policies and reforms for the state? | D2: =IFERROR('UPD1'!L14,"") | E2: 10 | H2: =IF(OR(F2="",NOT(ISNUMBER(D2))),"",IF(ABS(F2-D2)<0.001,"Yes","No")) | I2: =IF(ISNUMBER(F2),F2,D2) | J2: =IF(ISNUMBER(F2),"Expert (overrides AI)",IF(ISNUMBER(D2),"AI","Not scored yet")) -> Not scored yet | K2: Left for a person | L2: Partially Answered | M2: ANSWER: Partly answered. The Karnataka Town and Country Planning Act, 1961 does provide for a State Town-Planning Board. But section 4 only enables it: the State Government "may" set it up by notification. It is not a "shall" provision. Under the methodology, a "may" provision earns Part A only if the Board has actually been set up by a government notification or order, or this is shown on an official state department website. No such notification, order or website is in the Citation Sheet, so Part A cannot be decided. If Part A were met, Part B would be supported: s.4 gives the Board a stated mandate to advise the State on planning and development and to set principles and policies for the State as a whole. | EVIDENCE: (1) KTCP Act 1961, s.4 (ULG-02, PRS compilation, p.21-22): "The State Government may, by notification, constitute a State Town-Planning Board for the State ... for advising the State Government regarding planning and development and for determining principles and policies for achieving the balanced development of the State as a whole." (2) s.2(1a): "'Board' means the State Town Planning Board constituted under this Act". (3) The Act also says the State Government must consult "the Board" before amalgamating or sub-dividing planning areas (s.4A(3)), framing schemes for funds and assets (s.4A(5), s.4B(2)(ii)) and setting up Planning Authorities (s.4C(1)). These sections assume a Board exists, but they do not prove it was ever set up. (4) s.3 makes appointing a D | N2: The Karnataka Town and Country Planning Act, 1961 (Karnataka Act 11 of 1963), PRS compilation with amendments up to Act 38 of 2015 [ULG-02] | O2: https://prsindia.org/files/bills_acts/acts_states/karnataka/1963/1963KR11.pdf | P2: 4. State Town-Planning Board. —The State Government may, by notification, constitute a State Town-Planning Board for the State with such members and in such manner as may be prescribed for advising the State Government regarding planning and development and for determining principles and policies for achieving the balanced development of the State as a whole. | Q2: Part A is left blank because the evidence is not found, not because the Board is absent. Section 4 of the Karnataka Town and Country Planning (KTCP) Act 1961 (ULG-02, PRS compilation, amended up to Act 38 of 2015) only enables a State Town-Planning Board: the State Government "may, by notification, constitute" it. It is not a 'shall' provision. The methodology says a 'may' provision earns Part A only if a government notification or order, or an official department or planning-body website, shows the Board was actually set up. No such notification, order or web page is in the Citation Sheet. Other sections require consulting "the Board": s.4A(3) and (5), s.4B(2)(ii) and s.4C(1). Section 2(1a) defines the Board as "constituted under this Act". These sections assume a Board exists but do not prove it was set up, so they are not enough. I did not score NO, because there is no affirmative absence: the Board may well exist and the sheet simply lacks the proof. What I checked: KTCP Act sections 2(1a), 3, 4, 4A-4H and 51 (ULG-02). Section 3 (the Director of Town Planning, a 'shall' duty) is an official, not a board. Section 51 Joint Town Planning Boards are local bodies, not a state-level body. I also checked the KTCP Amendment Bill 2025 (ULG-03). It creates a Commissionerate and Commissioner (new ss.2A-2B) and makes the Greater Bengaluru Authority the planning authority (new s.81-G). It leaves s.4 unchanged and does not say the Board exists. It is also a Bill: its commencement depends on a notification, which is not in the sheet. I found nothing relevant in the Greater Bengaluru Governance Act 2024 (ULG-01), the GBG Amendment Bill (ULG-05), the BBMP Act 2020 (ULG-19), the BDA Act (ULG-04), the BMLTA Act (ULG-18) or the BMRDA pages (ULG-10/20/21). A sheet-wide search for 'State Town Planning Board' returned only ULG-02. Part B = YES. Section 4 explicitly gives the Board the job of "advising the State Government regarding planning and development and for determining principles and policies for achieving the balanced development of the State as a whole". That is a state-level planning-policy mandate. The word 'reforms' is not used, but under the scorer notes the Board's functions match the intent of the question. Per the column, Part B counts only if Part A = YES. To confirm: find the notification or GO constituting the State Town-Planning Board under s.4, or the official department web page showing it. Also find the KTCP Rules that set its membership. If either is found, Part A = YES and the score would be 10/10. Also check the official law department or gazette text and any amendments after 2015 (the Act text here is a PRS republication, a secondary source). | R2: The citation didn't settle every input. "Part A: State planning board provided / constituted" left blank: the Citation Sheet doesn't decide it.
A3: UPD1 | B3: Surat | C3: Is there a provision for a State Spatial Planning Board which is mandated with planning policies and reforms for the state? | D3: =IFERROR('UPD1'!L33,"") | E3: 10 | H3: =IF(OR(F3="",NOT(ISNUMBER(D3))),"",IF(ABS(F3-D3)<0.001,"Yes","No")) | I3: =IF(ISNUMBER(F3),F3,D3) | J3: =IF(ISNUMBER(F3),"Expert (overrides AI)",IF(ISNUMBER(D3),"AI","Not scored yet")) -> Not scored yet | K3: Left for a person | L3: Insufficient Evidence | R3: Step 2 found no evidence: a source needs to be found and added. Step 2 found no evidence (Insufficient Evidence). Source needed: A readable consolidated text of the Gujarat Town Planning and Urban Development Act, 1976 (official Legislative and Parliamentary Affairs Department or UD&UHD copy), checked section by section for any state town planning or spatial planning board. If the Act only says the government 'may' set one up, a Gujarat government notification or order constituting it, or the UD&UHD / Chief Town Planner page describing it and its functions.
A4: UPD2 | B4: Bangalore | C4: Is there a provision for the establishment of Planning Authorities for notified new towns or special developments? | D4: =IFERROR('UPD2'!K14,"") -> 10 | E4: 10 | H4: =IF(OR(F4="",NOT(ISNUMBER(D4))),"",IF(ABS(F4-D4)<0.001,"Yes","No")) | I4: =IF(ISNUMBER(F4),F4,D4) -> 10 | J4: =IF(ISNUMBER(F4),"Expert (overrides AI)",IF(ISNUMBER(D4),"AI","Not scored yet")) -> AI | K4: Scored by AI | L4: Answered — Verified Source | M4: ANSWER: Yes. Karnataka's town planning law, the Karnataka Town and Country Planning (KTCP) Act, 1961, lets the State Government notify any area in the state as a Local Planning Area under s.4A(1). Once it has done so, s.4C(1) lets it set up a 'Planning Authority' for that area by gazette notification. The Act can also extend an existing planning area to cover an adjacent area. Every Planning Authority must then prepare a master plan for its area within two years of the area being declared (s.9(1)). The provision covers any newly notified area. The Act has no separate 'new town' or 'special development' authority clause. The power to set up an authority is discretionary ('may'), not a duty. | EVIDENCE: (1) KTCP Act 1961 (ULG-02, PRS text with amendments up to Act 38 of 2015), Chapter IA. s.4A(1): 'The State Government may by notification declare any area in the State to be a Local Planning Area for the purposes of this Act, or include within such local planning area, any area adjacent thereto'. s.4A(2): the notification must define the area's limits. s.4A(3): areas can be amalgamated or sub-divided after consulting the State Town-Planning Board. s.4C(1): 'As soon as may be, after declaration of a local planning area, the State Government in consultation with the Board, may, by notification in the official Gazette, constitute ... an authority to be called the "Planning Authority" of that area'. s.4C(2)-(3): the authority is a body corporate, with a Chairman and a Town Planning | N4: The Karnataka Town and Country Planning Act, 1961 (Karnataka Act 11 of 1963), PRS compilation with amendments up to Act 38 of 2015 [ULG-02] | O4: https://prsindia.org/files/bills_acts/acts_states/karnataka/1963/1963KR11.pdf | P4: As soon as may be, after declaration of a local planning area, the State Government in consultation with the Board, may, by notification in the official Gazette, constitute for the purposes of the performance of the functions assigned to it, an authority to be called the “Planning Authority” of that area, having jurisdiction over that area. | Q4: I checked the Step 2 answer against the text of ULG-02 and the source supports it. The source is the KTCP Act 1961, Karnataka Act 11 of 1963, in a PRS compilation with amendments up to Act 38 of 2015. Three provisions decide the answer. s.4A(1) says 'The State Government may by notification declare any area in the State to be a Local Planning Area for the purposes of this Act, or include within such local planning area, any area adjacent thereto'. s.4C(1) lets the State set up a 'Planning Authority' for that area by Gazette notification, as a body corporate with set membership (s.4C(2)-(3)). s.9(1), substituted by Act 1 of 2005, says 'Every planning authority shall ... not later than two years from the date of declaration of the local planning area, prepare and publish ... a master plan for such area'. Taken together, the Act provides for setting up a Planning Authority for any newly notified area. It also covers the methodology's other route: an adjacent area added to an existing planning area must be planned by that area's authority. On that basis the answer is YES. Points for a reviewer: (1) s.4C uses 'may', so setting up an authority is discretionary. The methodology only asks whether a provision exists, so this still counts as YES. (2) The Act has no clause naming 'new towns' or 'special developments'. The general power to notify a new Local Planning Area and set up its authority is what meets the test. (3) ULG-02 is a PRS compilation, a secondary source. Amendments after 2015 are not in the Citation Sheet. The 2025 KTCP Amendment Bill (ULG-03) is not shown to be enacted, so I did not rely on it. (4) The KTCP Rules and the Karnataka Urban Development Authorities Act 1987 are not in the Citation Sheet. They are not needed for a YES. Context only, not used for scoring: ULG-01 (GBA Act 2024) makes GBA the Planning Authority under the KTCP Act for the Greater Bengaluru Area, and ULG-04 (BDA Act s.67, which inserted KTCP s.81-B) does the same for BDA in the City of Bangalore.
A5: UPD2 | B5: Surat | C5: Is there a provision for the establishment of Planning Authorities for notified new towns or special developments? | D5: =IFERROR('UPD2'!K33,"") -> 10 | E5: 10 | H5: =IF(OR(F5="",NOT(ISNUMBER(D5))),"",IF(ABS(F5-D5)<0.001,"Yes","No")) | I5: =IF(ISNUMBER(F5),F5,D5) -> 10 | J5: =IF(ISNUMBER(F5),"Expert (overrides AI)",IF(ISNUMBER(D5),"AI","Not scored yet")) -> AI | K5: Scored by AI | L5: Partially Answered | M5: ANSWER: Very likely yes, but the provision itself cannot be read in the Citation Sheet. Three official sources say that the Gujarat Town Planning and Urban Development Act, 1976 (GTPUD Act) lets the State constitute Area Development Authorities (s.5) and Urban Development Authorities (s.22) for areas declared as development areas. The development plan for such an area is prepared by that authority or by an officer the State authorises. However, the Citation Sheet copy of the Act (ULG-01, PRS) has no readable text for the principal Act (pages 2-86 are blank or scanned). So the actual wording of ss.3, 5 and 22 (the trigger, 'shall' or 'may', and whether new towns or special developments are covered) cannot be quoted or checked. | EVIDENCE: (1) Comprehensive General Development Control Regulations 2017 (CGDCR), Table 1.1, a binding state notification of the Urban Development and Urban Housing Department (ULG-14, p.1-2, and the same in ULG-05). It groups bodies as category D1 'Urban Development Authority (Constituted under Section 22 of The Gujarat Town Planning and Urban Development Act, 1976)', which includes Surat Urban Development Authority (SUDA), and category D2 'Urban/ Area Development Authority (Constituted under Section 22 or 5...)'. Category D3 covers Area Development Authorities 'Constituted under Section 5' (e.g. Bhuj, Bhachau, Rapar, Anjar). (2) GTPUD Rules 1979 (ULG-04): r.3 has an 'authorized Officer' appointed under s.9(2) prepare the draft development plan 'withi | N5: Comprehensive General Development Control Regulations (CGDCR) 2017, Part I: Procedure Regulations (UD&UHD, Government of Gujarat). This copy is hosted on the Rajkot Municipal Corporation website [ULG-14] | O5: https://rmc.gov.in/rmcwebsite/docs/All_TPS/TP_34/CGDCR_2017_PART_1_PROCEDURE_REGULATIONS.pdf | P5: D5(4) Area Development Authority (Constituted under Section 5 of The Gujarat Town Planning and Urban Development Act, 1976 (Special Project Areas) viz.:Alang Area Development Authority (AlADA) | Q5: Why YES: Under the methodology, the question is whether the state town planning law (here the Gujarat Town Planning and Urban Development Act, 1976, the GTPUD Act) provides for setting up a planning authority for notified new areas or special developments. I checked the Step 2 answer against the sources and it holds up. The evidence is the CGDCR 2017 (ULG-14, the same text as ULG-05). This is a binding Gujarat UD&UHD notification made under GTPUD Act s.116A/122. Its Table 1.1 records the state government's statement of the legal basis for bodies that already exist. Category D5 is Area Development Authorities 'Constituted under Section 5' of the GTPUD Act for 'Special Project Areas' (Alang, Ambaji, Shamlaji, Khambhaliya). This fits 'special developments' directly. Other categories are D1, D2 and D4 (Urban Development Authorities under s.22, including SUDA), D3 (Section 5 Area Development Authorities in Seismic Zone V) and D7A/D7B (authorities designated under s.6). Other sources point the same way. (1) The GTPUD (Amendment) Act 2017, appended in ULG-01 (p.90), amends ss.7(2) and 23(2) so that the State 'may' delegate 'the powers and functions of the Area Development Authorities' and 'of the Urban Development Authorities' to local authorities. This shows that both kinds of authority are created by the Act. (2) GTPUD Rules 1979 (ULG-04) rr.3 and 5 refer to the 'area declared as development area' and the 'area development authority or ... the authorized officer'. So where no authority is constituted, an authorised officer prepares the plan, which also fits the methodology's alternative test. (3) SUDA's DP 2035 report (ULG-06, p.13) says the 1976 Act 'made the provision for formation of Urban / Area Development Authorities' for growth beyond municipal limits. What to check (why confidence is low): The operative text of GTPUD Act ss.3, 5 and 22 cannot be read in ULG-01 (PRS copy; the principal Act's pages are scanned or blank). So I could not quote the exact trigger ('development area' or 'urban development area' declared by notification) or the verb ('may' or 'shall'). The YES rests on a binding state regulation and on amendment and Rules text that refer to these sections, not on the sections themselves. A reviewer should get readable official text of ss.3, 5 and 22 to confirm. Also confirm that UPD2 scores YES = 10 and NO = 0; the methodology does not state bands. I did not check the Gujarat Special Investment Region Act or the GIDC Act 1962 because they are not in the Citation Sheet. They are not needed for YES, since the GTPUD Act provision is enough.
A6: UPD3a | B6: Bangalore | C6: Does the Act require three levels of spatial plans for cities: Metropolitan/Regional, Municipal and Ward(s) /Local >:< Metropolitan/ Regional Plan | D6: =IFERROR(UPD3a!K14,"") -> 3.33 | E6: 10 >:< 3.33 | H6: =IF(OR(F6="",NOT(ISNUMBER(D6))),"",IF(ABS(F6-D6)<0.001,"Yes","No")) | I6: =IF(ISNUMBER(F6),F6,D6) -> 3.33 | J6: =IF(ISNUMBER(F6),"Expert (overrides AI)",IF(ISNUMBER(D6),"AI","Not scored yet")) -> AI | K6: Scored by AI | L6: Answered — Verified Source | M6: ANSWER: Yes. Karnataka law requires a metropolitan plan for Bengaluru. Clause (2)(c) of the Greater Bengaluru Governance Act, 2024 uses 'shall' twice. The State Government must set up a Bengaluru Metropolitan Planning Committee (BMPC), with membership as laid down in Article 243ZE of the Constitution, for an area at least as large as the Greater Bengaluru Area. A named planning body must then prepare a draft development plan for the Greater Bengaluru Area as a whole. On the regional side, the official BMRDA website lists preparing a structure plan for the Bangalore Metropolitan Region as one of the functions the Authority 'shall' have. Who prepares what: the metropolitan draft development plan is assigned to the 'Bengaluru Metropolitan Planning Authority' (this is the Act's wording, inside the BMPC clause). The Chief Commissioner of the Greater Bengaluru Authority (GBA) is the BMPC's Member Secretary, and the Chief Minister chairs it. BMRDA, a state body, prepares the regional structure plan. Separately, the GBA is the KTCP 'Planning Authority' for the Greater Bengaluru Area and must make its master plan. | EVIDENCE: (1) ULG-01, Greater Bengaluru Governance Act, 2024, chapter on GBA functions, sub-section (2) 'Planning Functions', clause (c) (the section number is probably 14; this is only a location note): 'The State Government shall constitute the Bengaluru Metropolitan Planning Committee (BMPC)... The Bengaluru Metropolitan Planning Authority shall prepare a draft developm | N6: The Greater Bengaluru Governance Act, 2024 (Karnataka Act No. 36 of 2025), as enacted, PRS copy of the Gazette text (DPAL notification dated 24.04.2025) [ULG-01] | O6: https://prsindia.org/files/bills_acts/acts_states/karnataka/2025/Act36of2025KA.pdf | P6: The Chief Commissioner of the Greater Bengaluru Authority shall be its Member Secretary. The Bengaluru Metropolitan Planning Authority shall prepare a draft development plan for the Greater Bengaluru Area as a whole | Q6: Scored YES. Bengaluru is a metropolitan city. In the Greater Bengaluru Governance Act, 2024 (Karnataka Act 36 of 2025), the 'Planning Functions' sub-section, clause (2)(c), says the State Government 'shall constitute' the Bengaluru Metropolitan Planning Committee (BMPC). The BMPC covers an area 'including but not limited to the Greater Bengaluru Area', and its membership follows Article 243ZE. The same clause says a draft development plan for the Greater Bengaluru Area as a whole 'shall' be prepared. Both duties use 'shall', so this is a binding requirement for a metropolitan plan, not a 'may'. The methodology lets us count a metropolitan authority Act as evidence. Section 103(1)(b) of the same Act backs this up: Ward Development Plans must be drawn up 'in accordance with the plans prepared by the Bengaluru Metropolitan Planning Committee'. On the regional side, the official BMRDA Functions page (ULG-10) says the Authority's functions 'shall be' to 'prepare a structure plan' for the Bangalore Metropolitan Region. This is only the website's restatement of the BMRDA Act, 1985. The Act's own text is not in the Citation Sheet, so it is supporting evidence only. I checked the source against the Step 2 answer and it supports it. The YES rests on the GBA Act provision. Caveats for the reviewer: (1) Drafting mismatch: the clause sets up the 'BMPC' but gives the plan-preparing duty to the 'Bengaluru Metropolitan Planning Authority', a body the excerpt never creates. The duty is mandatory either way. A reviewer should check the official Gazette text, because ULG-01 is a PRS copy. (2) The mandated plan covers the Greater Bengaluru Area 'as a whole', not the wider BMRDA region. (3) I could not confirm the commencement date or the GBA era from the Sheet. (4) ULG-02 (KTCP Act) was not fully searched for a regional-plan chapter. This does not affect a YES that already rests on a binding provision. I scored only the Metropolitan/Regional sub-question (SQ, max 3.33).
A7: UPD3a | B7: Surat | C7: Does the Act require three levels of spatial plans for cities: Metropolitan/Regional, Municipal and Ward(s) /Local >:< Metropolitan/ Regional Plan | D7: =IFERROR(UPD3a!K33,"") | E7: 10 >:< 3.33 | H7: =IF(OR(F7="",NOT(ISNUMBER(D7))),"",IF(ABS(F7-D7)<0.001,"Yes","No")) | I7: =IF(ISNUMBER(F7),F7,D7) | J7: =IF(ISNUMBER(F7),"Expert (overrides AI)",IF(ISNUMBER(D7),"AI","Not scored yet")) -> Not scored yet | K7: Left for a person | L7: Partially Answered | M7: ANSWER: The sources show that Gujarat law provides for a metropolitan-level development plan covering Surat. The Gujarat Metropolitan Planning Committees Act, 2008 (MPC Act) plans for a draft development plan that the Metropolitan Planning Committee submits to the State Government. Once the State sanctions it, that plan binds every authority in the metropolitan area. However, the section of the MPC Act that actually requires ("shall") the Committee to prepare the plan is not in the Citation Sheet. The sheet only has the 2019 amending Act, which assumes such a plan will exist. So I cannot confirm that a metropolitan or regional plan is mandatory. | EVIDENCE: (1) Gujarat Act No. 14 of 2019 (Gujarat Local Authorities and Town Planning Laws (Amendment) Act, 2019), printed in the PRS copy of the Town Planning and Urban Development Act, 1976 (TPUD Act). Clause 9 adds new s.10A to the MPC Act: "The State Government may, on receipt of the draft development plan submitted by the Metropolitan Planning Committee... either (a) sanction or refuse to sanction... or (b) return the draft development plan to the metropolitan planning committee". s.10A(3): the final development plan "shall be binding on the concerned all authorities functioning in the metropolitan area". s.10C(3)(a): an officer appointed by the State shall "assist the metropolitan planning committee in the preparation of the development plan under the Act". These sections deal with sanctioning and assisting the plan. They do n | N7: The Gujarat Town Planning and Urban Development Act, 1976 (Act 27 of 1976), with amendments appended (PRS Legislative Research copy) [ULG-01] | O7: https://prsindia.org/files/bills_acts/acts_states/gujarat/1976/1976Gujarat27.pdf | P7: (a) assist the metropolitan planning committee in the preparation of the development plan under the Act; | Q7: The Answer is left blank because the Citation Sheet does not show whether a metropolitan plan is mandatory. A 'NO' would need affirmative absence, and that is not possible here. What the sources show: Gujarat law does provide for a metropolitan-level development plan. The 2019 amending Act (Guj. 14 of 2019) is appended to the PRS copy of the Gujarat Town Planning and Urban Development Act, 1976 (TPUD Act) in ULG-01. It inserts the following into the Gujarat Metropolitan Planning Committees Act, 2008 (MPC Act): - s.10A(1): the State Government 'may', on receipt of the draft development plan submitted by the Metropolitan Planning Committee, sanction it, refuse it, or return it. - s.10A(3): the final plan 'shall be binding on the concerned all authorities functioning in the metropolitan area'. - s.10C(3)(a): a State-appointed officer shall assist the Committee 'in the preparation of the development plan under the Act'. The same Act also amends the TPUD Act. It adds a proviso to s.9(1) and a new s.19A, which say the local development plan 'shall include' the spatial proposals of the sanctioned MPC plan. These provisions only cover sanctioning (and s.10A(1) uses 'may'), the plan's binding effect, and help with preparing it. They assume a metropolitan plan will exist. None of them is itself a 'shall prepare' duty. The provision that would decide this question is not in the Citation Sheet: the MPC Act, 2008's own section requiring the Committee to prepare a draft development plan for the metropolitan area. What I checked: - ULG-01: appended amendments only. The main TPUD Act text could not be found in what I could read, and searches turned up no regional plan provision. - ULG-02: the 2019 Bill, with the same wording. - ULG-03: the GPMC Act, 1949. It covers re-development plans only. - ULG-04: the TPUD Rules, 1979. They cover the authority's development plan, not a metropolitan or regional plan. - ULG-05/14/15/16: the CGDCR 2017. - ULG-06: SUDA DP 2035. This is context only. It says the Surat Metropolitan area was declared under the MPC Act on 11/03/2016, and that as of 2017 the MPC development plan was 'not in place'. - ULG-09: the NITI Aayog plan, which is non-statutory. - Searches for 'regional plan' and 'Metropolitan Planning Committee shall prepare draft development plan' found no mandate. Other caveats: - The 2019 Act comes into force on a date the State notifies, and no commencement notification is in the sheet. - ULG-01 is a secondary PRS republication. ACTION: The research team should add the official text of the Gujarat MPC Act, 2008 (Guj. 18 of 2008) and check whether it says the MPC 'shall' prepare a draft development plan for the metropolitan area. If it does, and Surat's declared metropolitan area falls under it, 'YES' would likely be right. Otherwise this needs checking against the full TPUD Act text for any regional plan mandate. | R7: The citation didn't settle every input. "Answer" left blank: the Citation Sheet doesn't decide it.
A8: UPD3b | B8: Bangalore | C8: Does the Act require three levels of spatial plans for cities: Metropolitan/Regional, Municipal and Ward(s) /Local >:< Municipal/city plan | D8: =IFERROR(UPD3b!K14,"") -> 3.33 | E8: 10 >:< 3.33 | H8: =IF(OR(F8="",NOT(ISNUMBER(D8))),"",IF(ABS(F8-D8)<0.001,"Yes","No")) | I8: =IF(ISNUMBER(F8),F8,D8) -> 3.33 | J8: =IF(ISNUMBER(F8),"Expert (overrides AI)",IF(ISNUMBER(D8),"AI","Not scored yet")) -> AI | K8: Scored by AI | L8: Answered — Verified Source | M8: ANSWER: Yes. Section 9(1) of the Karnataka Town and Country Planning Act, 1961 says every planning authority 'shall' prepare and publish a master plan for its area. This is the city-level spatial plan. The deadline is two years from the date the local planning area is declared, and the plan goes to the State Government, through the Director, for provisional approval. If the authority misses the deadline, s.9(2) lets the State authorise the Director to prepare the plan and recover the cost from the authority. So the plan is required whoever the planning authority is. For Bengaluru, the Greater Bengaluru Governance Act, 2024 names the Greater Bengaluru Authority (GBA) as that planning authority for the Greater Bengaluru Area. Before that, KTCP s.81-B and BDA Act s.67 named the Bangalore Development Authority (BDA). The State approves the plan; the city body prepares it. | EVIDENCE: (1) KTCP Act (PRS compilation, amended up to Act 38 of 2015). s.2(3-b), inserted by Act 1 of 2005, defines a master plan as 'a plan for the development or re-development of the area within the jurisdiction of a planning authority'. s.9(1), substituted w.e.f. 14.2.2005: 'Every planning authority shall, as soon as may be, carry out a survey ... and shall, not later than two years from the date of declaration of the local planning area, prepare and publish ... a master plan'. s.9(2) is the Director fallback. s.10(1): the planning authority 'shall' declare its intention to prepare the plan and invite pub | N8: The Karnataka Town and Country Planning Act, 1961 (Karnataka Act 11 of 1963), PRS compilation with amendments up to Act 38 of 2015 [ULG-02] | O8: https://prsindia.org/files/bills_acts/acts_states/karnataka/1963/1963KR11.pdf | P8: Every planning authority shall, as soon as may be, carry out a survey of the area within its jurisdiction and shall, not later than two years from the date of declaration of the local planning area, prepare and publish in the prescribed manner a master plan for such area and submit it to the State Government, through the Director, for provisional approval. | Q8: UPD3b asks whether the state planning law requires a municipal/city plan. The answer is YES. Section 9(1) of the Karnataka Town and Country Planning Act, 1961 (PRS compilation, amended up to Act 38 of 2015; s.9 is in its 2005 substituted form) says every planning authority 'shall' prepare and publish a master plan for its area within two years of the local planning area being declared. Section 2(3-b), inserted by Act 1 of 2005, defines a master plan as 'a plan for the development or re-development of the area within the jurisdiction of a planning authority'. That is the city-level spatial plan. Other provisions back this up: - s.9(2): if the planning authority misses the deadline, the State may authorise the Director to prepare the plan and recover the cost from the authority. - s.10(1): the authority 'shall' declare its intention to prepare the plan. - s.12: 'The Master Plan shall consist of' set contents, such as land-use zoning and the street pattern. - s.13-B: a master plan is also required for any area added to the authority's jurisdiction. So the plan is mandatory ('shall'), not discretionary ('may'). Revision under s.13-D is discretionary unless the State directs it, but that does not affect whether a city plan must exist. Applying this to Bengaluru: KTCP s.81-B (inserted by BDA Act s.67) names the Bangalore Development Authority (BDA) as the planning authority. The Greater Bengaluru Governance Act, 2024 (ULG-01, 'Planning Functions' provision) makes the Greater Bengaluru Authority (GBA) the 'Planning Authority' under KTCP for the Greater Bengaluru Area. I checked this against the Step 2 answer and the source text; I did not re-read ULG-01 here. The State approves the plan, but the planning authority must prepare it. What a person should check: - When the GBA designation took effect, and whether the KTCP Amendment Bill 2025 (ULG-03) was enacted. Neither changes the answer, because s.9 binds whichever body is the planning authority. - The text relied on is a PRS compilation, not the Gazette copy. - The planning authority (BDA, now GBA) is a development or metropolitan authority, not the municipal council itself. The methodology lets a development authority Act count as evidence, so this should not matter. One point for scoring: the sheet gives a max of 3.33 but no rubric bands, so YES is treated as full marks for this sub-question (3 x 3.33 for UPD3). The metropolitan and ward levels belong to UPD3a and UPD3c and are not assessed here.
A9: UPD3b | B9: Surat | C9: Does the Act require three levels of spatial plans for cities: Metropolitan/Regional, Municipal and Ward(s) /Local >:< Municipal/city plan | D9: =IFERROR(UPD3b!K33,"") -> 3.33 | E9: 10 >:< 3.33 | H9: =IF(OR(F9="",NOT(ISNUMBER(D9))),"",IF(ABS(F9-D9)<0.001,"Yes","No")) | I9: =IF(ISNUMBER(F9),F9,D9) -> 3.33 | J9: =IF(ISNUMBER(F9),"Expert (overrides AI)",IF(ISNUMBER(D9),"AI","Not scored yet")) -> AI | K9: Scored by AI | L9: Partially Answered | M9: ANSWER: Very likely yes, but this is not confirmed from the operative text of the Act. The Gujarat Town Planning and Urban Development Act, 1976 (GTPUD Act) and its 1979 Rules set up a mandatory development plan, which works as the city's master plan for Surat. Surat Urban Development Authority (SUDA) prepares it for an area that includes Surat Municipal Corporation (SMC), and the State Government sanctions it. SMC itself does not prepare or approve the city-wide plan. Several 'shall' provisions require this plan, but the wording of the mandate in Act s.9(1) (whether it says 'shall', and any deadline) and in s.21 (revision) is not in the Citation Sheet text I could read. | EVIDENCE: (1) GTPUD Rules, 1979 (ULG-04): r.3 says 'The authorized Officer shall prepare and submit the draft development plan after carrying out the survey of the area within the jurisdiction of the area development authority'. Under its heading, r.3 applies to the officer appointed under s.9(2). r.5(1) says the area development authority or authorized officer 'shall' publish the draft 'after a draft development plan is prepared and submitted to the State Government under section 9'. Form A refers to the authority having 'prepared and submitted a draft development plan... under section 9'. (2) GTPUD Act amendments appended to the PRS copy (ULG-01): Gujarat Act 14 of 2019 adds a proviso to s.9(1): 'the development plan shall include the proposals, with regard to spatial planning, of the development plan san | N9: Gujarat Bill No. 21 of 2019: The Gujarat Local Authorities and Town Planning Laws (Amendment) Bill, 2019 (Gujarat Government Gazette Extra No.21, Part V) [ULG-02] | O9: https://prsindia.org/files/bills_acts/bills_states/gujarat/2019/BillNo21of2019Gujarat.pdf | P9: Although all three Tp Act, Mpc Act & Dpc Aet mandates toprepare the development plans | Q9: I answered YES. This is the city/municipal-plan sub-question (SQ, max 3.33), which asks whether the T&CP Act requires a city plan; the methodology lets the development authority Act count as evidence. In Gujarat the GTPUD Act, 1976 is both the T&CP Act and the Urban Development Authority Act. Several instruments in the Citation Sheet, read together, support a mandatory development plan, which works as the city's master plan: (1) ULG-02 is the State Government's official Gazette text of the 2019 Bill. Its Statement of Objects and Reasons says the appropriate authorities under the TP Act 'are required to prepare the draft development plan'. It also says 'all three Tp Act, Mpc Act & Dpc Act mandates to prepare the development plans' (the quote above copies the source's OCR spelling exactly, e.g. 'Aet', 'toprepare'). (2) ULG-01 (PRS copy) shows the 2019 amendment Act adding a proviso to s.9(1): 'the development plan shall include the proposals, with regard to spatial planning...'. It also adds s.19A: 'the appropriate authority shall include in the development plan...'. Both treat the s.9 development plan as a required instrument. (3) ULG-04, the GTPUD Rules 1979, r.3: 'The authorized Officer shall prepare and submit the draft development plan after carrying out the survey of the area within the jurisdiction of the area development authority'. r.5(1) refers to the draft 'prepared and submitted to the State Government under section 9'. (4) ULG-06, SUDA's DP-2035 report, is a description of the law, not the law. It says the plan was submitted under s.9 and 'as per section 21 of the Act, the development plan is to be revised once in 10 years'. Plans came into force in 1986 and 2004, and the draft DP-2035 was submitted on 9-5-2016. I checked the Step 2 answer against these sources. It is right that the operative text of s.9(1) and s.21 is not readable in ULG-01: only the appended amendment Acts came back again when I re-read it. Things a person should check: (a) The 'shall' and any deadline in s.9(1), and the 10-year revision duty in s.21, are confirmed only indirectly. The evidence is the Government's own Statement of Objects and Reasons, the 2019 proviso and the Rules, not the operative section text. A reviewer may want the consolidated Act text. (b) The plan is prepared by the appropriate authority for its development area. For Surat that is SUDA, whose area includes the SMC area, and the State Government sanctions it. SMC (the ULG) does not itself prepare a city-wide plan. ULG-03, the GPMC Act s.284F, covers only re-development plans for declared areas. I scored YES because the methodology expressly allows evidence from the development authority Act; confirm the rubric accepts a SUDA plan covering the city as the 'municipal/city plan'. Confidence is medium because the answer rests on 2+ instruments read together and on the PRS copy.
A10: UPD3c | B10: Bangalore | C10: Does the Act require three levels of spatial plans for cities: Metropolitan/Regional, Municipal and Ward(s) /Local >:< Ward(s)/local plan | D10: =IFERROR(UPD3c!L14,"") | E10: 10 >:< 3.33 | H10: =IF(OR(F10="",NOT(ISNUMBER(D10))),"",IF(ABS(F10-D10)<0.001,"Yes","No")) | I10: =IF(ISNUMBER(F10),F10,D10) | J10: =IF(ISNUMBER(F10),"Expert (overrides AI)",IF(ISNUMBER(D10),"AI","Not scored yet")) -> Not scored yet | K10: Left for a person | L10: Partially Answered | M10: ANSWER: The Karnataka Town and Country Planning Act text in the Citation Sheet does not appear to require a third tier of plan at zone, ward or local-area level. Under the Act as amended, the statutory plan is the Master Plan for the whole local planning area (ss.9-13D). The Act's only plan below that level is the Town Planning Scheme (s.26), which is optional ('may') and implements the Master Plan, so the methodology excludes it. The city government's own law, the Greater Bengaluru Governance Act 2024 (s.103(1)(b)), requires an annual Ward Development Plan. That plan is a ward budget and priority list of projects, not a spatial plan, and it sits in the municipal law, not the T&CP Act. So it does not count as a zonal/ward/local area plan mandate. Because some layers of the law are missing from the sheet, this is recorded as 'not found', not as a confirmed absence. | EVIDENCE: (1) KTCP Act 1961, PRS compilation, 2005 amending Act s.4 (new s.9(1)): 'Every planning authority shall ... prepare and publish in the prescribed manner a master plan for such area'. s.2(3-b): Master Plan 'means a plan for the development or re-development of the area within the jurisdiction of a planning authority'. s.12(1): the Master Plan covers 'the entire planning area' and includes 'zoning of land use ... together with Zoning Regulations'. These are zoning regulations inside the Master Plan, not separate zonal plans. The Outline Development Plan and Comprehensive Development Plan tiers (ss.19-23, 2 | N10: The Karnataka Town and Country Planning Act, 1961 (Karnataka Act 11 of 1963), PRS compilation with amendments up to Act 38 of 2015 [ULG-02] | O10: https://prsindia.org/files/bills_acts/acts_states/karnataka/1963/1963KR11.pdf | P10: Every planning authority shall, as soon as may be, carry out a survey of the area within its jurisdiction and shall, not later than two years from the date of declaration of the local planning area, prepare and publish in the prescribed manner a master plan for such area and submit it to the State Government, through the Director, for provisional approval. | Q10: I have left 'Answer' blank because the evidence shows no ward or local plan in the Act text, but it does not prove one is absent from every layer of the law. A NO would score 0, and that needs every relevant instrument to have been read. The KTCP Rules, the official gazette copy and any amendments made between 2020 and 2025 are not in the Citation Sheet. My provisional finding is NO. If a reviewer confirms those missing layers add nothing, the Answer should be NO. What I checked in ULG-02 (the KTCP Act 1961, a PRS secondary copy with amending Acts up to 2015 and the 2020 amendment appended): (1) The list of sections and Chapter III. Act 1 of 2005 replaced the Outline Development Plan and the Comprehensive Development Plan with a single Master Plan for 'such area', meaning the whole local planning area (s.9(1), which says 'shall'). That Act also deleted ss.19-23 and 25. (2) s.12(1). The Master Plan covers 'the entire planning area' and includes 'zoning of land use ... together with Zoning Regulations'. These are land-use zones inside the one plan, not a separate zonal plan level. (3) s.13-A. The Interim Master Plan is a stop-gap Master Plan, not a lower level of plan. (4) s.26(1). A Planning Authority 'may' make town planning schemes to carry out the Master Plan. This is optional, and the methodology excludes TPSs anyway. (5) The Act provides for no zonal, ward or local area plan. Nothing in the metropolitan, municipal and ward set of three levels appears as a requirement. I also read ULG-03, the KTCP and certain other laws (Amendment) Bill 2025. It only makes the GBA the planning authority for the Greater Bengaluru Area, sets up a Commissionerate and adds s.81-G. It adds no plan level. The Ward Development Plans in the city government's own laws (GBA Act 2024 s.103(1)(b), ULG-01; BBMP Act 2020 s.2(65), ULG-19) are in municipal law, not the T&CP Act. Under the GBA Act it is an annual priority list for allocating funds, so it does not count as a T&CP ward plan. Still missing: the KTCP plan-preparation Rules, an official or current consolidated text of the Act (only the PRS copy is in the sheet), and any amendments between 2020 and 2025. Scorers' note: no zonal, ward or local-area plan requirement was found in the KTCP Act. The only plan below the Master Plan is the optional Town Planning Scheme, which is excluded. | R10: The citation didn't settle every input. "Answer" left blank: the Citation Sheet doesn't decide it.
A11: UPD3c | B11: Surat | C11: Does the Act require three levels of spatial plans for cities: Metropolitan/Regional, Municipal and Ward(s) /Local >:< Ward(s)/local plan | D11: =IFERROR(UPD3c!L33,"") | E11: 10 >:< 3.33 | H11: =IF(OR(F11="",NOT(ISNUMBER(D11))),"",IF(ABS(F11-D11)<0.001,"Yes","No")) | I11: =IF(ISNUMBER(F11),F11,D11) | J11: =IF(ISNUMBER(F11),"Expert (overrides AI)",IF(ISNUMBER(D11),"AI","Not scored yet")) -> Not scored yet | K11: Left for a person | L11: Partially Answered | M11: ANSWER: I can't tell from the Citation Sheet whether Gujarat's planning law requires a zone- or ward-level plan. The Gujarat Town Planning and Urban Development (GTPUD) Act, 1976, as amended in 2017, does create a 'Local Area Plan' (LAP). It adds LAPs to the functions of area and urban development authorities, and the State Government sanctions them under section 76A. But the operative text of s.76A(1)-(6) is not in the Sheet. That is the part that would say who must prepare an LAP, for which areas, and whether it is 'shall' or 'may'. Nothing seen ties LAPs to zones or wards. The mandate type found is a 'Local Area Plan' (an area/zone-specific plan), not a ward plan. | EVIDENCE: (1) GTPUD Act, 2017 amendment (Gazette Ex. 13-04-2017, in ULG-01 p.90): in s.7(1)(ii) for area development authorities and s.23(1)(ii) for urban development authorities (SUDA is constituted under this Act), the words "or Local Area Plan" are inserted after "town planning schemes". The original wording of those clauses was not seen, so I can't tell whether this is a duty or a power. The same amendment adds s.76A(7)-(8), p.90-91: "Where the State Government sanctions the Local Area Plan under clause (a) of sub-section (6), it shall state in the notification" where the plan can be inspected and when its liabilities come into force; (8) covers eviction and enforcement. These show state sanction, but not a duty to prepare. (2) Gujarat Local Authorities and Town Planning Laws (Amendment) Act, 2019 (ULG-01 p | N11: The Gujarat Town Planning and Urban Development Act, 1976 (Act 27 of 1976), with amendments appended (PRS Legislative Research copy) [ULG-01] | O11: https://prsindia.org/files/bills_acts/acts_states/gujarat/1976/1976Gujarat27.pdf | P11: in sub-section (1), in clause (ii), after the words "town planning schemes", the words "or Local Area Plan" shall be inserted; | Q11: I left the Answer blank because the Citation Sheet does not contain the provision that would decide it. 1) What the evidence shows. The 2017 amendment to the GTPUD Act (ULG-01, pp. 90-91) adds the words 'or Local Area Plan' after 'town planning schemes' in s.7(1)(ii) and s.23(1)(ii). Those clauses list the functions of area and urban development authorities. The amendment also adds s.76A(7)-(8). Under these, when the State Government sanctions a Local Area Plan (LAP) under s.76A(6)(a), it must say where the plan can be inspected and when its liabilities take effect; (8) covers eviction and enforcement. So the T&CP Act does recognise a sub-development-plan instrument, the LAP. 2) What is missing. The text of s.76A(1)-(6) is not in the Sheet. That is the part that would say who prepares an LAP, for which areas, and whether preparation is mandatory ('shall') or optional ('may'). I searched ULG-01 three times for it, and also searched the whole Sheet, and could not find it. The original wording of s.7(1)(ii) and s.23(1)(ii) is not available either, so I cannot tell whether the authority must do these things or only may. 3) Why not YES. Being listed as a function, plus State sanction under s.76A(6)-(7), shows that LAPs exist. It does not show a mandate for a third tier of plan at zone or ward level. Nothing I saw ties LAPs to zones or wards, or requires them across the whole city. 4) Why not NO. A NO needs affirmative absence, and the decisive section is unread. 5) Other sources checked: - 2019 Amendment Act (ULG-01, pp. 93-98; ULG-02 is its Bill): links the development plan to the Metropolitan and District Planning Committee plans (s.19A; s.10A-10C of those Acts). These are upper tiers only. - GTPUD Rules, 1979 (ULG-04): written before LAPs existed. No LAP or zonal-plan rule seen. - CGDCR 2017 (ULG-05/14), reg. 2.66: defines an LAP as 'a plan prepared for a specific area or a zone by the competent authority'. The LAP mandates for the CBD and transit-oriented zones apply to AUDA only. In any case these are regulations, not the Act. - Gujarat Provincial Municipal Corporations Act s.284E-F (ULG-03): re-development plans, which the Corporation may make at its discretion. Not a third tier. - SUDA Development Plan 2035 (ULG-06): implemented through town planning (TP) schemes, which the methodology excludes. Plan type to note in comments: Local Area Plan (an area- or zone-specific plan prepared by the appropriate authority and sanctioned by the State under GTPUD s.76A). It is not a ward plan. For the reviewer: (a) Get GTPUD s.76A(1)-(6), inserted by a pre-2017 amendment, from the Gujarat Legislative and Parliamentary Affairs Department or the Urban Development and Urban Housing Department (UD&UHD), to confirm 'shall' versus 'may' and the area coverage. (b) Decide whether an LAP sanctioned by the State for a specific area counts as a 'zone/ward level' third tier under UPD3c. Version relied on: GTPUD Act as amended up to Gujarat Act 14 of 2019 (PRS copy). The Step 2 answer's description of the evidence matches the source. | R11: The citation didn't settle every input. "Answer" left blank: the Citation Sheet doesn't decide it.
A12: UPD4 | B12: Bangalore | C12: Is the planning boundary of the municipal/city plan aligned with political and administrative boundaries? | D12: =IFERROR('UPD4'!K14,"") -> 10 | E12: 10 | H12: =IF(OR(F12="",NOT(ISNUMBER(D12))),"",IF(ABS(F12-D12)<0.001,"Yes","No")) | I12: =IF(ISNUMBER(F12),F12,D12) -> 10 | J12: =IF(ISNUMBER(F12),"Expert (overrides AI)",IF(ISNUMBER(D12),"AI","Not scored yet")) -> AI | K12: Left for a person | L12: Partially Answered | M12: ANSWER: The Citation Sheet does not settle this. By law, the planning area should match the city government's area. Section 14(2)(a) of the Greater Bengaluru Governance Act makes the Greater Bengaluru Authority (GBA) the Planning Authority under the Karnataka Town and Country Planning (KTCP) Act for 'the areas comprising of the Greater Bengaluru Area'. Section 15(1) makes GBA responsible for the master plan of that same area. That area is also the GBA's own area and contains its City Corporations (s.4, s.5). Read together, these point to a planning area coterminous with the city government. But none of the documents the question says decide it are in the Sheet: no master plan in force for the GBA area, no notification declaring its planning area, no plan map, and no s.3 notification fixing the Greater Bengaluru Area. The only plan described is the Bangalore Development Authority's (BDA) Revised Master Plan 2015 (RMP 2015), and only in a secondary source. That plan covers the Bengaluru Metropolitan Area (BMA): BBMP plus 251 villages, about 1,294 sq km, which is larger than the BBMP area. Nothing in the Sheet shows whether those 251 villages are included whole or split. | EVIDENCE: (1) GBA Act 2024 (Karnataka Act 36 of 2025), city government's law: s.14(2)(a), GBA 'shall be the Planning Authority ... for the areas comprising of the Greater Bengaluru Area'. s.14(2)(d): development regulations 'shall be applied uniformly across the Greater Bengaluru Area'. s.15(1): GBA 'shall be | N12: The Greater Bengaluru Governance Act, 2024 (Karnataka Act No. 36 of 2025), as enacted, PRS copy of the Gazette text (DPAL notification dated 24.04.2025) [ULG-01] | O12: https://prsindia.org/files/bills_acts/acts_states/karnataka/2025/Act36of2025KA.pdf | P12: (a) the Greater Bengaluru Authority shall be the “Planning Authority” as defined under the Karnataka Town and Country Planning Act, 1961, for the areas comprising of the Greater Bengaluru Area; | Q12: I left the answer blank because the documents that decide this question are not in the Citation Sheet. The method says the primary source is the notification or text defining the planning area, plus the plan map. The Sheet has no master plan in force for Bengaluru, no notification declaring a planning area and no plan map. It also lacks the s.3 notification declaring the Greater Bengaluru Area and the s.7(3) final notification setting City Corporation boundaries. I checked the Step 2 answer against the sources and agree that it is only partly answered. What the law says: GBA Act 2024 s.14(2)(a) makes GBA the Planning Authority under the KTCP Act 'for the areas comprising of the Greater Bengaluru Area'. It applies 'notwithstanding anything contained in any other law'. s.15(1) makes GBA responsible for the master plan for that area, and that same area holds the City Corporations (s.4, s.5). Read together, the law points to a planning area that matches the city government's area. That would score YES (10). But this is the legal design only. It does not show where the boundary of the plan in force actually runs. Competing arrangement: - KTCP Act (ULG-02, PRS compilation to 2015) s.2(7)(a)(i) and s.81-B still make BDA the Planning Authority for the City of Bangalore. The same wording appears in BDA Act s.67 (ULG-04), whose 2026 amendment (Act 42 of 2026) changes only s.10 and s.38D, not planning jurisdiction. - The KTCP amendment Bill 2025 (ULG-03) would split planning between GBA (the Greater Bengaluru Area) and BDA (the BMA excluding the Greater Bengaluru Area). The Sheet does not show it was enacted or brought into force. - BCAP 2023 (ULG-16) is a secondary, BBMP-era source. It describes the BDA plan area (the BMA) as BBMP plus 251 villages, about 1,294 sq km. If BDA's RMP 2015 is still 'the city plan', the test is whether those 251 villages are included whole. The Sheet does not show the village list or a map. - GBA Act s.7(1) and the s.7(4) proviso allow parts of local bodies to be included. That concerns the outer boundary of the Greater Bengaluru Area, not proof that the plan boundary splits a unit. Why not NO: a NO (score 0) needs affirmative evidence that the boundary splits a unit, and there is none. Absence cannot be confirmed either, because the plan and notification are not in the Sheet. What I checked: ULG-01 (s.3, s.4, s.5, s.7, s.14(2), s.15, s.26), ULG-02, ULG-03, ULG-04 (s.67 and Act 42 of 2026), ULG-16 and ULG-20, plus a search of the whole Sheet for the local planning area, master plan and villages. A person needs to: (a) decide which plan is the operative municipal/city plan: BDA's RMP 2015 or a GBA master plan; (b) get the planning-area notification and map, or the RMP 2015 approval notification with its village list, and check the 251 villages are whole; (c) get the s.3 Greater Bengaluru Area notification; (d) confirm whether the KTCP amendment of 2025 has been enacted. | R12: The citation didn't settle every input. "Answer" left blank: the Citation Sheet doesn't decide it.
A13: UPD4 | B13: Surat | C13: Is the planning boundary of the municipal/city plan aligned with political and administrative boundaries? | D13: =IFERROR('UPD4'!K33,"") -> 0 | E13: 10 | H13: =IF(OR(F13="",NOT(ISNUMBER(D13))),"",IF(ABS(F13-D13)<0.001,"Yes","No")) | I13: =IF(ISNUMBER(F13),F13,D13) -> 0 | J13: =IF(ISNUMBER(F13),"Expert (overrides AI)",IF(ISNUMBER(D13),"AI","Not scored yet")) -> AI | K13: Left for a person | L13: Human Verification Required | M13: ANSWER: Probably not aligned, but this can't be scored on current evidence. The city plan for Surat is the Development Plan 2035 of the Surat Urban Development Authority (SUDA), a state development authority. SMC is the Surat Municipal Corporation. SUDA's February 2017 plan report defines the planning area in two ways that split existing units. First, it covers 'Surat Municipal Corporation (except Moje: Khajod)': Khajod village was moved to a separate Khajod Urban Development Authority, so part of the city government's own area sits outside the plan. Second, it includes 3 villages only in part (Velanja in Kamrej taluka; Sandhiyer and Paria in Olpad taluka). Both match the methodology's Score 0 condition ('planning boundary bisects the ULG or other administrative/local-government units'). However, the final plan was only sanctioned on 08.10.2020. The planning-area definition in that sanctioned plan, and the current SMC boundary, are not in the Citation Sheet. So the 2017 position can't be confirmed as the current one. | EVIDENCE: (1) ULG-06, SUDA DP 2035 report, 22.02.2017, ch.21.1 'Exclusion of villages' (p.216-217 of the report). The state used GTPUD Act s.22(2A) to split off SUDA's area and form Khajod UDA (notification GH/V/144 of 2016, 19.07.2016): 'Thus, Khajod village of Chorayasi Taluks was deleted from the jurisdiction of SUDA.' Notification GH/V/199 of 2016 (24.10.2016) took out 54 villages, '50 wholly and 4 partly'. Asnabad was corrected back in, leaving '53 village | R13: Step 2 found no evidence: a source needs to be found and added. Step 2 found no evidence (Human Verification Required). Source needed: The Gujarat UD&UHD notification sanctioning SUDA's Final Development Plan (GH/V/157 of 2020, dated 08.10.2020), with its schedule and plan map of the development area. The current s.22 notifications defining SUDA's development area, including whether Khajod is still outside SUDA and whether Velanja, Sandhiyer and Paria are still only partly included. The current SMC boundary notification.
A14: UPD5a | B14: Bangalore | C14: Is there a clear decentralised procedure for approvals of each level of plans? >:< Does the law mandate that the metropolitan/regional plan be approved by the state government? | D14: =IFERROR(UPD5a!K14,"") | E14: 10 >:< 3.33 | H14: =IF(OR(F14="",NOT(ISNUMBER(D14))),"",IF(ABS(F14-D14)<0.001,"Yes","No")) | I14: =IF(ISNUMBER(F14),F14,D14) | J14: =IF(ISNUMBER(F14),"Expert (overrides AI)",IF(ISNUMBER(D14),"AI","Not scored yet")) -> Not scored yet | K14: Left for a person | L14: Partially Answered | M14: ANSWER: Not determined from the Citation Sheet. The two metropolitan-planning provisions in the sheet do not say the state must approve the metropolitan plan. Under both, the Metropolitan Planning Committee prepares a draft development plan, and the older law says it is forwarded to the State Government. Approval is not mentioned. The Bengaluru Metropolitan Region Development Authority (BMRDA) Act, 1985 is the regional-planning law for the Revised Structure Plan 2031 (RSP 2031), but its text is not in the sheet. So whether state approval of the regional plan is mandatory cannot be confirmed or ruled out. | EVIDENCE: (1) Greater Bengaluru Governance (GBA) Act 2024 (Kar. Act 36 of 2025), the planning-functions sub-section (2)(c), within the section just before s.15: 'The State Government shall constitute the Bengaluru Metropolitan Planning Committee (BMPC)... The Bengaluru Metropolitan Planning Authority shall prepare a draft development plan for the Greater Bengaluru Area as a whole and discharge responsibilities as enshrined in Article 243ZE'. There is no state approval step. (2) BBMP Act 2020 s.367(6)-(8): the Metropolitan Planning Committee (MPC) 'shall prepare a draft development plan for the Bengaluru metropolitan area as a whole'; s.367(8) 'The Chairman of the Metropolitan Planning Committee shall forward the development plan, as recommended by such Committee, to the State Government'. The verb is 'forward', not 'approve'. The BBMP Act may have been superseded by the GBA | N14: The Bruhat Bengaluru Mahanagara Palike Act, 2020 (Karnataka Act No. 53 of 2020), PRS republished text with Amendments 1, 2 and 29 of 2022 [ULG-19] | O14: https://prsindia.org/files/bills_acts/acts_states/karnataka/2020/Act%2053%20of%202020%20Karnataka.pdf | P14: (8) The Chairman of the Metropolitan Planning Committee shall forward the development plan, as recommended by such Committee, to the State Government. | Q14: I left the Answer blank: the evidence is not found, not absent. The law that would decide this, the Bangalore Metropolitan Region Development Authority (BMRDA) Act 1985 and any rules made under it, is not in the Citation Sheet. That is the regional-planning law for the Structure Plan (Revised Structure Plan 2031). Without it I cannot answer YES, and I cannot show affirmative absence for a NO. What I checked: (1) ULG-19, BBMP Act 2020 s.367. Under s.367(6) the Metropolitan Planning Committee 'shall prepare a draft development plan'. Under s.367(8) the Chairman 'shall forward' the plan to the State Government. The verb is 'forward'. No approval by the state is stated, and this section may have been superseded by the GBA Act. (2) ULG-01, GBA Act 2024 (Kar. Act 36 of 2025), planning-functions clause (2)(c). It sets up the Bengaluru Metropolitan Planning Committee (BMPC), chaired by the Chief Minister, under Article 243ZE. The Committee prepares a draft development plan for the Greater Bengaluru Area. The text I read has no state-approval step. (3) ULG-02, KTCP Act 1961 (PRS text, amended to 2015). Sections 13 and 13-B require state approval of a Master Plan prepared by a local Planning Authority. That is a local plan, not a metropolitan or regional plan. My searches found no regional-plan approval provision in this Act. The Act was not read in full. (4) ULG-03, KTCP Amendment Bill 2025. This is a bill, not shown to be enacted. It changes which body is the planning authority (GBA or BDA) but has no regional-plan approval provision. (5) ULG-10, BMRDA Functions page. It lists the function 'to prepare a structure plan' and says nothing about approval. (6) ULG-18, BMLTA Act. Its state approval in s.21(4) covers only the Comprehensive Mobility Plan, which is not the metropolitan/regional plan. The Step 2 'Partially Answered / not determined' result holds up against the sources. For the reviewer: (a) Add the BMRDA Act 1985 sections on preparing and approving the Structure Plan, from an official Karnataka source, and any BMRDA rules. (b) Confirm which instrument counts as Bengaluru's 'metropolitan/regional plan'. (c) Check whether rules prescribe a BMPC procedure that includes state approval. | R14: The citation didn't settle every input. "Answer" left blank: the Citation Sheet doesn't decide it.
