Workbook

Sheet UPD Questions_290926 
A1: S_No | B1: ASICS_2017_Report_Q_No | C1: ASICS 2023 Question number | D1: New City-Systems | E1: ASICS 2027_Report_Q No | F1: Group | G1: Thematic questions | H1: Sub-themes | I1: Question | J1: MQ_SQ | K1: Max Score | L1: Assessment level | M1: Detailed Methodology | N1: Notes for scorers
A2: 1 | B2: UPD1 | C2: UPD1 | D2: UPD | E2: UPD1 | F2: Planning | G2: Legal and institutional planning architecture | H2: State-level planning framework | I2: Is there a provision for a State Spatial Planning Board which is mandated with planning policies and reforms for the state? | J2: MQ | K2: 10 | L2: Law or Policy | M2: Part A - Check if the state Town and Country Planning (T&CP) act provides for a state-level town and country planning board/ spatial planning board or equivalent body with a 'Shall' provision. If yes, score 5. Where the law only enables the constitution of such a body (e.g., “the State Government may constitute”), additionally verify whether the body has actually been constituted through a government notification or order, or by checking the official website of the relevant State Government department or planning body. If yes, score 5. Part B - If Part A is scored as 'Yes', check whether the body has an explicit mandate to advise on or formulate state-level spatial planning policies and reforms. if yes, score 5. | N2: Please note that the name of the body need not be identical, provided its statutory functions correspond to the intent of the question.
A3: 2 | B3: UPD9 | C3: UPD6 | D3: UPD | E3: UPD2 | F3: Planning | G3: Legal and institutional planning architecture | H3: State-level planning framework | I3: Is there a provision for the establishment of Planning Authorities for notified new towns or special developments? | J3: MQ | K3: 10 | L3: Law or Policy | M3: Check if the T&CP Act has provisions for establishing a planning authority for new areas/towns notified. The state can also be considered, if the provision mandates the existing planning authority to develop a plan for the notified new area.
A4: 3 | B4: UPD2 | C4: UPD2 | D4: UPD | E4: UPD3 | F4: Planning | G4: Legal and institutional planning architecture | H4: Spatial planning hierarchy | I4: Does the Act require three levels of spatial plans for cities: Metropolitan/Regional, Municipal and Ward(s) /Local | J4: MQ | K4: 10 | L4: Law or Policy | M4: The T&CP Act should mandate three levels of spatial plans.
A5: 3a | B5: UPD2a | C5: UPD2a | D5: UPD | E5: UPD3a | F5: Planning | G5: Legal and institutional planning architecture | H5: Spatial planning hierarchy | I5: Metropolitan/ Regional Plan | J5: SQ | K5: 3.33 | L5: Law or Policy | M5: Check the T&CP/Metropolitan Planning Act for provisions that mandate the creation of a metropolitan/regional plan. Relevant metropolitan authority act/urban areas development authority act can also be considered for evidence. If the city is not a metropolitan, the act should mandate the creation of a regional plan.
A6: 3b | B6: UPD2b | C6: UPD2b | D6: UPD | E6: UPD3b | F6: Planning | G6: Legal and institutional planning architecture | H6: Spatial planning hierarchy | I6: Municipal/city plan | J6: SQ | K6: 3.33 | L6: Law or Policy | M6: Check the T&CP Act for provisions that mandate the creation of a municipal/city plan. Relevant urban areas development authority act can also be considered for evidence.
A7: 3c | B7: UPD2c | C7: UPD2c | D7: UPD | E7: UPD3c | F7: Planning | G7: Legal and institutional planning architecture | H7: Spatial planning hierarchy | I7: Ward(s)/local plan | J7: SQ | K7: 3.33 | L7: Law or Policy | M7: Check the T&CP Act for provisions that mandate the creation of a third tier of plan at the zone/ward level. Town planning schemes that are developed within the framework of the municipal/city plan shall not be considered. | N7: Note: Please capture in the comments if the mandate is for a zonal/ward/local area plan, mention the type.
A8: 4 | B8: UPD6 | C8: NA | D8: UPD | E8: UPD4 | F8: Planning | G8: Legal and institutional planning architecture | H8: Spatial planning hierarchy | I8: Is the planning boundary of the municipal/city plan aligned with political and administrative boundaries? | J8: MQ | K8: 10 | L8: Law or Policy | M8: Review the applicable municipal/city plan, its maps and/or the notification defining the planning area. Identify the ULG and administrative units used to define the planning area. First, compare the planning boundary with the ULG boundary. If the planning boundary is coterminous with the ULG boundary, score 10. Where the planning area extends beyond the ULG boundary, identify how the additional area has been defined in the plan or notification. The extension need not follow district boundaries. It may comprise whole gram panchayats, revenue villages, taluks/tehsils or other notified administrative/local-government units. The key test is whether existing units are included in their entirety rather than split by the planning boundary. For example: Entire ULG only = Score 10 Entire ULG + 10 complete Gram Panchayats = Score 10 Entire ULG + 15 complete revenue villages = Score 10 Entire ULG + 2 complete taluks = Score 10 ULG + only part of a Gram Panchayat/revenue village = Score 0 Planning boundary itself divides the ULG, leaving part of the ULG outside the plan = Score 0 Use the notification/text defining the planning area as the primary source. Refer to the plan map where necessary to verify the boundary. Do not assess whether the planning boundary is appropriate or whether it represents the functional urban region; assess only whether it aligns with identifiable political/local-government and administrative units. Score 10: The municipal/city plan boundary corresponds to the ULG boundary, or any area extending beyond the ULG is defined using whole administrative/local-government units. Score 0: The planning boundary bisects the ULG or other administrative/local-government units used to constitute the planning area.
A9: 5 | B9: UPD | C9: NA | D9: UPD | E9: UPD5 | F9: Planning | G9: Legal and institutional planning architecture | H9: Spatial planning hierarchy | I9: Is there a clear decentralised procedure for approvals of each level of plans? | J9: MQ | K9: 10 | L9: Law or Policy | M9: Check the state T&CP Act for provisions that delineate a decentralised plan approval process.
A10: 5a | B10: UPD | C10: NA | D10: UPD | E10: UPD5a | F10: Planning | G10: Legal and institutional planning architecture | H10: Spatial planning hierarchy | I10: Does the law mandate that the metropolitan/regional plan be approved by the state government? | J10: SQ | K10: 3.33 | L10: Law or Policy | M10: Check if the T&CP Act/metropolitan planning act mandates the metropolitan/regional plan to be approved by the state government.
A11: 5b | B11: UPD | C11: NA | D11: UPD | E11: UPD5b | F11: Planning | G11: Legal and institutional planning architecture | H11: Spatial planning hierarchy | I11: Does the law mandate that the municipal/city plan be approved by the MPC (Metropolitan Planning Committee) for metropolitan cities or by DPC (District Planning Committee) for non-metropolitan cities? | J11: SQ | K11: 3.33 | L11: Law or Policy | M11: Check if the T&CP Act mandates the municipal/city plans to be approved by the metropolitan planning committee in case of million plus cities and District Planning Committees in the case of non-metropolitan cities. In the case of states with no metropolitan cities, check if the municipal/city plan is to be approved by the state.
A12: 5c | B12: UPD | C12: NA | D12: UPD | E12: UPD5c | F12: Planning | G12: Legal and institutional planning architecture | H12: Spatial planning hierarchy | I12: Does the law mandate that the ward(s)/local plan be approved by the ULG? | J12: SQ | K12: 3.33 | L12: Law or Policy | M12: Check if the T&CP Act mandates the zonal/ward plans to be approved by the ULG.
A13: 6 | B13: UPD5 | C13: UPD4 | D13: UPD | E13: UPD6 | F13: Planning | G13: Legal and institutional planning architecture | H13: Objectives of each level of Municipal/City Plans | I13: Does the Act clearly define the objectives/contents of each level of spatial plan? | J13: MQ | K13: 10 | L13: Law or Policy | M13: Check the T&CP Act for provisions that detail the objectives and contents of each level of spatial plan. The Act should broadly mention what each level of spatial plan should cover. Score 3.33 each for the objectives and contents of - 1. Metropolitan/regional plan 2. Municipal/city plan 3. Ward(s)/local plan If the T&CP Act provides for all three, score 10.
A14: 7 | B14: UPD16 | C14: UPD9 | D14: UPD | E14: UPD7 | F14: Planning | G14: Legal and institutional planning architecture | H14: Metropolitan and district planning institutions | I14: Does the city have a functional MPC/DPC? | J14: MQ | K14: 10 | L14: Law/Policy & Implementation | M14: Sum of the sub-questions
A15: 7a | B15: UPD16a | C15: UPD9a | D15: UPD | E15: UPD7a | F15: Planning | G15: Legal and institutional planning architecture | H15: Metropolitan and district planning institutions | I15: Does the law provide for the constitution of an MPC/DPC? | J15: SQ | K15: 5 | L15: Law/Policy | M15: Part A: Check whether there is a mandate in the Municipal or T&CP Act for the constitution of MPC/DPC. If yes, score 2.5 Part B: Check whether the State has notified the rules for the MPC/DPC applicable to the city. If yes, score 2.5. MPC applies to metropolitan cities (46 cities); DPC applies for non-metropolitan cities
A16: 7b | B16: UPD16b | C16: UPD9b | D16: UPD | E16: UPD7b | F16: Planning | G16: Legal and institutional planning architecture | H16: Metropolitan and district planning institutions | I16: Have they met at least once in the past two years? | J16: SQ | K16: 5 | L16: Implementation | M16: Check whether the MPC/DPC has met at least once in the past two years. Score 5 where there is evidence of meeting in the last two years. Evidence: State UD/Municipal Administration department notifications/constitution orders/website; MPC/DPC meeting minutes, agendas or resolutions; MPC/DPC and metropolitan planning authority/development authority websites and RTIs.
A17: 8 | B17: NA | C17: NA | D17: UPD | E17: UPD8 | F17: Planning | G17: Legal and institutional planning architecture | H17: Metropolitan and district planning institutions | I17: Does the city (million-plus) have a Metropolitan Authority? | J17: MQ | K17: 10 | L17: Law or Policy | M17: Check if the state municipal and T&CP Act mandates a statutory metropolitan-level authority. For example the Greater Bengaluru Authority (GBA) under the Greater Bengaluru Governance Act, 2024. Score 10 where such a metropolitan authority has been established by law and constituted for the city. Note: The question is NA for non-metropolitan cities
A18: 9 | B18: UPD4 | C18: UPD3 | D18: UPD | E18: UPD9 | F18: Planning | G18: Municipal/City Plan preparation, participation and review | H18: Inter-agency participation | I18: Does the law mandate participation of all parastatals/ agencies /ULGs in creation of Spatial plans (metro/municipal/ward)? | J18: MQ | K18: 10 | L18: Law or Policy | M18: Check the T&CP Act for provisions that mandate the participation of all parastatals/agencies/ULGs in creation of spatial plans at all three levels with respect to its jurisdiction. The clause may either state verbatim "all parastatals/agencies/ULGs" or allude to their presence using other terminologies such as local bodies/relevant authorities. Check if the act mandates the constitution of an advisory council to advise the planning authorities on drawing up the plan. The advisory council should have representation from various civic agencies. Score 10 if there are such provisions, else, score 0.
A19: 10 | B19: UPD33 | C19: UPD18 | D19: UPD | E19: UPD10 | F19: Planning | G19: Municipal/City Plan preparation, participation and review | H19: Public participation and scrutiny | I19: Does the law mandate public participation in preparation of the municipal plan through Area Sabhas / Ward Sabhas and other means? | J19: MQ | K19: 10 | L19: Law or Policy | M19: Check if the T&CP Act mandates public participation in preparation of municipal/city plan through: Part A: Formal platforms such as ward committees and area sabhas. If yes, score 5. Part B: Other means* for municipal/city plan. If yes, score 5. *Even if the provision alludes to 'public participation/consultation or consolidation of suggestions and objections without specifying the mode for the same
... A31: 14 | B31: UPD3 | C31: NA | D31: UPD | E31: UPD14 | F31: Implementation | G31: Municipal/City Plan status, hierarchy and coordination | H31: Existence of Municipal/City Plans at each level | I31: Are the spatial plans at the Metropolitan/Regional, Municipal and Ward(s) /Local level notified? | J31: MQ | K31: 10 | L31: Implementation | M31: The existence of such a document or map should be notified in respective state gazettes
A32: 14a | B32: UPD3a | C32: NA | D32: UPD | E32: UPD14a | F32: Implementation | G32: Municipal/City Plan status, hierarchy and coordination | H32: Existence of Municipal/City Plans at each level | I32: Is there a Metropolitan/Regional Plan? | J32: SQ | K32: 3.33 | L32: Implementation | M32: Document should mention the words metropolitan/regional plan or any word that can be safely assumed to be a synonym for a metropolitan region. Check the website of the metro region development authority or urban development authority or ULB website. Score 3.33 if any of these apply, else, 0. | N32: Note: Please ensure an existence of a notified document of the plan. Maps alone will not make the cut
A33: 14b | B33: UPD3b | C33: NA | D33: UPD | E33: UPD14b | F33: Implementation | G33: Municipal/City Plan status, hierarchy and coordination | H33: Existence of Municipal/City Plans at each level | I33: Is there Municipal/City Plan? | J33: SQ | K33: 3.33 | L33: Implementation | M33: Document should mention the word municipal/development/city plan or municipal/city plan. Check the website of the urban development authority or ULG website or T&CP Dept. Score 3.33 if any of these apply, else, 0. | N33: Note: Please ensure an existence of a notified document of the plan. Maps alone will not make the cut
A34: 14c | B34: UPD3c | C34: NA | D34: UPD | E34: UPD14c | F34: Implementation | G34: Municipal/City Plan status, hierarchy and coordination | H34: Existence of Municipal/City Plans at each level | I34: Is there a Ward(s) /Local area/ neighbourhood Plan? | J34: SQ | K34: 3.33 | L34: Implementation | M34: Document should mention the word ward development plan/zonal plan/local area plan. This can exist as a standalone document or spatial plans or map. Score 3.33 if any of these apply, else, 0.
A35: 15 | B35: NA | C35: NA | D35: UPD | E35: UPD15 | F35: Implementation | G35: Municipal/City Plan status, hierarchy and coordination | H35: Validity of Municipal/City Plans | I35: Does the city have a municipal/city plan that is currently in force and within its prescribed validity period? | J35: MQ | K35: 10 | L35: Implementation | M35: Review the applicable municipal/ city plan to identify the valid period, and the gazette notification date of the current and immediately preceding municipal/city plan Score 10 — notified within the statutory period Score 0 — municipal/city plans that have lapsed and have not been replaced by a new municipal/city plan should be treated as ‘no municipal/city plans/inactive municipal/city plans. The scorer to capture in the scoring sheet the amount of time (in months) that has been passed since the end of the validity period
A36: 16 | B36: UPD7 | C36: NA | D36: UPD | E36: UPD16 | F36: Implementation | G36: Municipal/City Plan status, hierarchy and coordination | H36: Alignment across planning levels | I36: Are the spatial plans at the Metropolitan/Regional, Municipal and Ward(s) /Local level in a concurrent or nested timeline of validity? | J36: MQ | K36: 10 | L36: Implementation | M36: Check whether the validity periods of the metropolitan/regional, municipal/city, and ward/zonal/local area/neighbourhood-level spatial plans align, ensuring that lower-level plans do not extend beyond the metropolitan/regional plan's validity.
A37: 16a | B37: UPD7a | C37: NA | D37: UPD | E37: UPD16a | F37: Implementation | G37: Municipal/City Plan status, hierarchy and coordination | H37: Alignment across planning levels | I37: Is the Metropolitan/Regional plan in a concurrent or nested timeline of validity with municipal plan? | J37: SQ | K37: 5 | L37: Implementation | M37: Check whether the validity periods of the metropolitan/regional and municipal/city-level plans overlap and align, so that the municipal/city plan does not extend beyond the metropolitan/regional plan's validity. For example, if the metropolitan/regional plan is valid from 2001–2021, the municipal/city plan should not extend beyond 2021.
A38: 16b | B38: UPD7b | C38: NA | D38: UPD | E38: UPD16b | F38: Implementation | G38: Municipal/City Plan status, hierarchy and coordination | H38: Alignment across planning levels | I38: Is the Municipal municipal/city plan in a concurrent or nested timeline of validity with Ward municipal/city plan? | J38: SQ | K38: 5 | L38: Implementation | M38: Check whether the validity periods of the municipal/city municipal/city plan and ward/local-level plans overlap and are aligned, such that the validity of the ward/local-level plan does not extend beyond that of the municipal/city municipal/city plan. For example: if the municipal/city plan is valid from 2021–2041, the applicable ward/zonal/local-level plan should fall within and not extend beyond 2041.
A39: 17 | B39: UPD12 | C39: NA | D39: UPD | E39: UPD17 | F39: Implementation | G39: Municipal/City Plan status, hierarchy and coordination | H39: Inter-agency coordination and integration | I39: Do the municipal/city plans at each level, integrate the plans and priorities of various sectoral public departments and agencies? | J39: MQ | K39: 10 | L39: Implementation | M39: Check if creation of the municipal/city plan at each level involved creation of a committee/process for deliberation and decision making where all sectoral public departments and agencies were invited (at least water and sewerage, traffic, electricity, transport, health and education). Details of such delibrations can be available in the municipal/city plan, or as MoM / notes on the planning authority's website.
A40: 18 | B40: UPD27 | C40: NA | D40: UPD | E40: UPD18 | F40: Implementation | G40: Municipal/City Plan status, hierarchy and coordination | H40: Objectives of the Municipal/City Plan | I40: Does the municipal/city plan include objectives on jobs and economy? | J40: MQ | K40: 10 | L40: Implementation | M40: Check whether the municipal/city plan identifies key economic development priorities and provides measurable targets/outcomes for them. These may include: Increase in workforce participation. Number of jobs to be generated across economic sectors. Land identified/allocated for economic activities. Number/area of enterprises, industries or commercial activities to be facilitated. Provision of designated spaces/facilities for street vendors and other informal livelihoods. Score based on whether the municipal/city plan contains both: 1. A clearly stated objective or priority in the municipal/city plan relating to the city’s economy, employment or livelihoods. This could include job creation, workforce participation, industrial/commercial development, informal livelihoods, economic clusters, markets, tourism, or allocating land/infrastructure to support economic activity. 2. Quantifiable targets or outcome indicators to measure progress. Score 10: The municipal/city plan identifies clear economic development priorities and includes measurable/quantifiable targets or outcome indicators against which progress can be assessed. Score 5: The municipal/city plan identifies clear economic development priorities and proposed interventions/actions, but does not provide measurable targets/outcome indicators. Score 0: The municipal/city plan does not identify clear economic development priorities and associated interventions. General or aspirational references to economic development, employment, jobs or livelihoods without clearly identified priorities and interventions shall not be considered for scoring.
A41: 19 | B41: UPD28 | C41: NA | D41: UPD | E41: UPD19 | F41: Implementation | G41: Municipal/City Plan status, hierarchy and coordination | H41: Objectives of the Municipal/City Plan | I41: Does the municipal/city plan include objectives on environment and heritage conservation? | J41: MQ | K41: 10 | L41: Implementation | M41: Sum of the sub-questions below -
A42: 19a | B42: NA | C42: NA | D42: UPD | E42: UPD19a | F42: Implementation | G42: Municipal/City Plan status, hierarchy and coordination | H42: Objectives of the Municipal/City Plan | I42: a) Environmental Conservation | J42: SQ | K42: 5 | L42: Implementation | M42: Check whether the municipal/city plan identifies clear priorities, interventions and measurable targets/outcomes across the following two components: Natural Environment and Climate Resilience These may include: Protection, enhancement or increase of recreational and non-recreational green spaces, urban forests and natural habitats. Conservation, restoration or revival of lakes, wetlands and other water bodies. Protection of environmentally sensitive areas and natural assets through appropriate zoning, buffers or other development controls. Increase in green cover, afforestation or reforestation. Protection/restoration of biodiversity and ecologically significant areas. Reduction in air, water and soil pollution. Climate-change mitigation and adaptation, including reduction in greenhouse gas emissions. Promotion of renewable energy and clean technologies. Disaster-risk reduction and resilience of natural systems. For each component, score as follows: Score 5: The municipal/city plan identifies atleast 2 or more clear priorities and associated interventions/actions and provides measurable/quantifiable targets or outcome indicators. Score 2.5: The municipal/city plan identifies atleast 2 or more clear priorities and associated interventions/actions, but does not provide measurable targets/outcome indicators. Score 0: The component is absent, or is referred to only in general/aspirational terms without clearly identified priorities and associated interventions
A43: 19b | B43: NA | C43: NA | D43: UPD | E43: UPD19b | F43: Implementation | G43: Municipal/City Plan status, hierarchy and coordination | H43: Objectives of the Municipal/City Plan | I43: b) Heritage Conservation | J43: SQ | K43: 5 | L43: Implementation | M43: Check whether the municipal/city plan identifies clear priorities, interventions and measurable targets/outcomes across the following two components: Heritage Conservation These may include: Identification and protection of heritage buildings, precincts, sites and other heritage assets. Identification and protection of natural heritage and culturally significant landscapes. Conservation, restoration or adaptive reuse of heritage buildings/sites. Designation of heritage zones/precincts and appropriate development controls or buffer areas. Protection of the character and built form of heritage areas. Integration of heritage conservation with redevelopment and other development proposals. Measurable targets for conservation, restoration or protection of identified heritage assets/precincts. For each component, score as follows: Score 5: The municipal/city plan identifies atleast 2 or more clear priorities and associated interventions/actions and provides measurable/quantifiable targets or outcome indicators. Score 2.5: The municipal/city plan identifies atleast 2 or more clear priorities and associated interventions/actions, but does not provide measurable targets/outcme indicators. Score 0: The component is absent, or is referred to only in general/aspirational terms without clearly identified priorities and associated interventions.
A44: 20 | B44: UPD29 | C44: UPD 11f | D44: UPD | E44: UPD20 | F44: Implementation | G44: Municipal/City Plan status, hierarchy and coordination | H44: Objectives of the Municipal/City Plan | I44: Does the municipal/city plan include objectives on social development (health care, education)? | J44: MQ | K44: 10 | L44: Implementation | M44: Check whether the municipal/city plan identifies clear priorities, interventions and measurable targets/outcomes across the following three components:
A45: 20a | B45: NA | C45: NA | D45: UPD | E45: UPD20a | F45: Implementation | G45: Municipal/City Plan status, hierarchy and coordination | H45: Objectives of the Municipal/City Plan | I45: a) Education | J45: SQ | K45: 3.33 | L45: Implementation | M45: Education These may include: Coverage/accessibility of anganwadis and pre-primary facilities. Availability of schools relative to population/service standards. Accessibility of educational facilities, including for persons with disabilities. Other measurable education-related service or accessibility outcomes. For each component, score as follows: Score: 3.33 - The municipal/city plan identifies atleast two or more clear priorities and associated interventions/actions and provides measurable/quantifiable targets or outcome indicators. Score: 1.67 - If the municipal/city plan identifies atleast two or more clear priorities and associated interventions/actions, but does not provide measurable targets/outcome indicators. Score 0 if the component is absent, or is referred to only in general/aspirational terms without clearly identified priorities and associated interventions.
... A63: 24 | B63: UPD19 | C63: NA | D63: UPD | E63: UPD24 | F63: Implementation | G63: Sectoral planning | H63: Sustainability, resilience and climate action | I63: Does your city have a Sustainability/ Resilience Strategy/Climate Action Plan that clearly articulates development priorities, measurable objectives, and the roles and responsibilities of the ULG? | J63: MQ | K63: 10 | L63: Implementation | M63: NA
A64: 24a | B64: UPD19a | C64: NA | D64: UPD | E64: UPD24a | F64: Implementation | G64: Sectoral planning | H64: Sustainability, resilience and climate action | I64: Does the city have a notified and active Sustainability/Resilience Strategy? | J64: SQ | K64: 3.33 | L64: Implementation | M64: Check the municipal/city plan/ULB website/parastatal website/city website for the existence of a Climate Action Plan, City Resilience Strategy or Sustainability Strategy. The document must be formally adopted or approved by the competent authority (a ULG/Council resolution, a Government Order, or integration into the statutory municipal/city plan/DP) to be scored. A Disaster Management Plan may also be considered as evidence. If the plan/ strategy does exist score 3.33, or score 0 otherwise. Note: A draft document. Independent consultant's report/academic /NGO reports will not be considered. | N64: Note: Independent consultant's report/academic reports will not be considered.
A65: 24b | B65: UPD19b | C65: NA | D65: UPD | E65: UPD24b | F65: Implementation | G65: Sectoral planning | H65: Sustainability, resilience and climate action | I65: Does the plan have development priorities and measurable objectives? | J65: SQ | K65: 3.33 | L65: Implementation | M65: Check whether the climate action plan, city resilience strategy, sustainability strategy or disaster management plan identifies clear priorities and specifies measurable objectives or targets against those priorities, including quantitative or qualitative indicators, as appropriate. Examples may include greenhouse-gas emission reduction or net-zero targets; reduction in exposure to heat, flooding or other climate hazards; increase in green cover; flood-risk mitigation; water security; or other climate adaptation and resilience outcomes. A general statement of intent, such as becoming climate-resilient, sustainable or reducing emissions, without identifiable priorities and measurable objectives or targets, shall not qualify. Score 3.33 if the plan identifies atleast two or more clear priorities and includes measurable objectives or targets against those priorities; score 0 otherwise.
A66: 24c | B66: NA | C66: NA | D66: UPD | E66: UPD24c | F66: Implementation | G66: Sectoral planning | H66: Sustainability, resilience and climate action | I66: Does the plan clearly articulate the role of the ULG? | J66: SQ | K66: 3.33 | L66: Implementation | M66: Score 3.33 where the plan clearly articulates the role/responsibilities of the ULG in its preparation/implementation; score 0 otherwise.
A67: 25 | B67: UPD20 | C67: NA | D67: UPD | E67: UPD25 | F67: Implementation | G67: Sectoral planning | H67: Comprehensive mobility planning | I67: Does your city have a Comprehensive Mobility Plan that clearly articulates development priorities, measurable objectives, and the roles and responsibilities of the ULG? | J67: MQ | K67: 10 | L67: Implementation | M67: NA
A68: 25a | B68: NA | C68: NA | D68: UPD | E68: UPD25a | F68: Implementation | G68: Sectoral planning | H68: Comprehensive mobility planning | I68: Does the city have a notified and active Comprehensive Mobility Plan? | J68: SQ | K68: 3.33 | L68: Implementation | M68: Check the municipal/city plan/ULB website/parastatal website/UMTA or State transport department website for the existence of a Comprehensive Mobility Plan (CMP). The plan must be formally adopted or approved by the competent authority (approval by the UMTA where one exists, the State Government, or a Municipal Corporation/Council resolution) to be scored - a draft, a consultant's report or an unadopted study will not be considered. Check whether the city has a Comprehensive Mobility Plan (CMP) that has been formally adopted or approved by the competent authority, such as the UMTA, the Urban Development Department, Transport Department or the ULG/Council through a resolution. Sources may include the municipal/city plan, the ULB website, parastatal websites, and the UMTA or State Transport Department website. A draft CMP, a consultant's report, or an unadopted study, without evidence of formal adoption or approval, shall not qualify. Score 3.33 if the city has a CMP formally adopted or approved by the competent authority; score 0 otherwise.
...

Sheet UPD_SUMMARY_RAW
A1: ASICS 2027_Report_Q No | B1: Group | C1: Thematic questions | D1: Sub-themes | E1: MQ_SQ | F1: Question | G1: Assessment level | H1: Max Score | I1: Ahmedabad | J1: Bangalore | K1: Bhopal | L1: Bhubaneswar | M1: Chandigarh | N1: Chennai | O1: Dehradun | P1: Delhi | Q1: Guwahati | R1: Hyderabad | S1: Jaipur | T1: Kanpur | U1: Kolkata | V1: Lucknow | W1: Ludhiana | X1: Mumbai | Y1: Patna | Z1: Pune | AA1: Raipur | AB1: Ranchi | AC1: Surat | AD1: Thiruvananthapuram | AE1: Visakhapatnam | AF1: Solan | AG1: Panaji | AH1: Agartala | AI1: New York | AJ1: London | AK1: Johannesburg
A2: ENTER | B2: Derived | C2: Derived | D2: Derived | E2: Derived | F2: Derived | G2: Derived | H2: Derived | I2: Derived
A3: UPD1 | B3: =IF(ISBLANK($A3),"NO_CODE",VLOOKUP($A3,'UPD Questions_290926 '!$E$1:$N$300,MATCH(B$1,'UPD Questions_290926 '!$E$1:$N$1,0),0)&"") -> Planning | C3: =IF(ISBLANK($A3),"NO_CODE",VLOOKUP($A3,'UPD Questions_290926 '!$E$1:$N$300,MATCH(C$1,'UPD Questions_290926 '!$E$1:$N$1,0),0)&"") -> Legal and institutional planning architecture | D3: =IF(ISBLANK($A3),"NO_CODE",VLOOKUP($A3,'UPD Questions_290926 '!$E$1:$N$300,MATCH(D$1,'UPD Questions_290926 '!$E$1:$N$1,0),0)&"") -> State-level planning framework | E3: =IF(ISBLANK($A3),"NO_CODE",VLOOKUP($A3,'UPD Questions_290926 '!$E$1:$N$300,MATCH(E$1,'UPD Questions_290926 '!$E$1:$N$1,0),0)&"") -> MQ | F3: =IF(ISBLANK($A3),"NO_CODE",VLOOKUP($A3,'UPD Questions_290926 '!$E$1:$N$300,MATCH(F$1,'UPD Questions_290926 '!$E$1:$N$1,0),0)&"") -> Is there a provision for a State Spatial Planning Board which is mandated with planning policies and reforms for the state? | G3: =IF(ISBLANK($A3),"NO_CODE",VLOOKUP($A3,'UPD Questions_290926 '!$E$1:$N$300,MATCH(G$1,'UPD Questions_290926 '!$E$1:$N$1,0),0)&"") -> Law or Policy | H3: =IF(ISBLANK($A3),"NO_CODE",VLOOKUP($A3,'UPD Questions_290926 '!$E$1:$N$300,MATCH(H$1,'UPD Questions_290926 '!$E$1:$N$1,0),0)) -> 10 | I3: =IF($H3=0,"NA",IF($A3=INDIRECT("'"&$A3&"'!$B$1"),IF(VLOOKUP(I$1,INDIRECT("'"&$A3&"'!$A$12:$Z$41"),MATCH("Points (Auto-generate)",INDIRECT("'"&$A3&"'!$A$12:$Z$12"),0),0)="","?",VLOOKUP(I$1,INDIRECT("'"&$A3&"'!$A$12:$Z$41"),MATCH("Points (Auto-generate)",INDIRECT("'"&$A3&"'!$A$12:$Z$12"),0),0)),"ER")) -> ? | J3: =IF($H3=0,"NA",IF($A3=INDIRECT("'"&$A3&"'!$B$1"),IF(VLOOKUP(J$1,INDIRECT("'"&$A3&"'!$A$12:$Z$41"),MATCH("Points (Auto-generate)",INDIRECT("'"&$A3&"'!$A$12:$Z$12"),0),0)="","?",VLOOKUP(J$1,INDIRECT("'"&$A3&"'!$A$12:$Z$41"),MATCH("Points (Auto-generate)",INDIRECT("'"&$A3&"'!$A$12:$Z$12"),0),0)),"ER")) -> ? | K3: =IF($H3=0,"NA",IF($A3=INDIRECT("'"&$A3&"'!$B$1"),IF(VLOOKUP(K$1,INDIRECT("'"&$A3&"'!$A$12:$Z$41"),MATCH("Points (Auto-generate)",INDIRECT("'"&$A3&"'!$A$12:$Z$12"),0),0)="","?",VLOOKUP(K$1,INDIRECT("'"&$A3&"'!$A$12:$Z$41"),MATCH("Points (Auto-generate)",INDIRECT("'"&$A3&"'!$A$12:$Z$12"),0),0)),"ER")) -> ? | L3: =IF($H3=0,"NA",IF($A3=INDIRECT("'"&$A3&"'!$B$1"),IF(VLOOKUP(L$1,INDIRECT("'"&$A3&"'!$A$12:$Z$41"),MATCH("Points (Auto-generate)",INDIRECT("'"&$A3&"'!$A$12:$Z$12"),0),0)="","?",VLOOKUP(L$1,INDIRECT("'"&$A3&"'!$A$12:$Z$41"),MATCH("Points (Auto-generate)",INDIRECT("'"&$A3&"'!$A$12:$Z$12"),0),0)),"ER")) -> ? | M3: =IF($H3=0,"NA",IF($A3=INDIRECT("'"&$A3&"'!$B$1"),IF(VLOOKUP(M$1,INDIRECT("'"&$A3&"'!$A$12:$Z$41"),MATCH("Points (Auto-generate)",INDIRECT("'"&$A3&"'!$A$12:$Z$12"),0),0)="","?",VLOOKUP(M$1,INDIRECT("'"&$A3&"'!$A$12:$Z$41"),MATCH("Points (Auto-generate)",INDIRECT("'"&$A3&"'!$A$12:$Z$12"),0),0)),"ER")) -> ? | N3: =IF($H3=0,"NA",IF($A3=INDIRECT("'"&$A3&"'!$B$1"),IF(VLOOKUP(N$1,INDIRECT("'"&$A3&"'!$A$12:$Z$41"),MATCH("Points (Auto-generate)",INDIRECT("'"&$A3&"'!$A$12:$Z$12"),0),0)="","?",VLOOKUP(N$1,INDIRECT("'"&$A3&"'!$A$12:$Z$41"),MATCH("Points (Auto-generate)",INDIRECT("'"&$A3&"'!$A$12:$Z$12"),0),0)),"ER")) -> ? | O3: =IF($H3=0,"NA",IF($A3=INDIRECT("'"&$A3&"'!$B$1"),IF(VLOOKUP(O$1,INDIRECT("'"&$A3&"'!$A$12:$Z$41"),MATCH("Points (Auto-generate)",INDIRECT("'"&$A3&"'!$A$12:$Z$12"),0),0)="","?",VLOOKUP(O$1,INDIRECT("'"&$A3&"'!$A$12:$Z$41"),MATCH("Points (Auto-generate)",INDIRECT("'"&$A3&"'!$A$12:$Z$12"),0),0)),"ER")) -> ? | P3: =IF($H3=0,"NA",IF($A3=INDIRECT("'"&$A3&"'!$B$1"),IF(VLOOKUP(P$1,INDIRECT("'"&$A3&"'!$A$12:$Z$41"),MATCH("Points (Auto-generate)",INDIRECT("'"&$A3&"'!$A$12:$Z$12"),0),0)="","?",VLOOKUP(P$1,INDIRECT("'"&$A3&"'!$A$12:$Z$41"),MATCH("Points (Auto-generate)",INDIRECT("'"&$A3&"'!$A$12:$Z$12"),0),0)),"ER")) -> ? | ... AK3: =IF($H3=0,"NA",IF($A3=INDIRECT("'"&$A3&"'!$B$1"),IF(VLOOKUP(AK$1,INDIRECT("'"&$A3&"'!$A$12:$Z$41"),MATCH("Points (Auto-generate)",INDIRECT("'"&$A3&"'!$A$12:$Z$12"),0),0)="","?",VLOOKUP(AK$1,INDIRECT("'"&$A3&"'!$A$12:$Z$41"),MATCH("Points (Auto-generate)",INDIRECT("'"&$A3&"'!$A$12:$Z$12"),0),0)),"ER")) -> ?
A4: UPD2 | B4: =IF(ISBLANK($A4),"NO_CODE",VLOOKUP($A4,'UPD Questions_290926 '!$E$1:$N$300,MATCH(B$1,'UPD Questions_290926 '!$E$1:$N$1,0),0)&"") -> Planning | C4: =IF(ISBLANK($A4),"NO_CODE",VLOOKUP($A4,'UPD Questions_290926 '!$E$1:$N$300,MATCH(C$1,'UPD Questions_290926 '!$E$1:$N$1,0),0)&"") -> Legal and institutional planning architecture | D4: =IF(ISBLANK($A4),"NO_CODE",VLOOKUP($A4,'UPD Questions_290926 '!$E$1:$N$300,MATCH(D$1,'UPD Questions_290926 '!$E$1:$N$1,0),0)&"") -> State-level planning framework | E4: =IF(ISBLANK($A4),"NO_CODE",VLOOKUP($A4,'UPD Questions_290926 '!$E$1:$N$300,MATCH(E$1,'UPD Questions_290926 '!$E$1:$N$1,0),0)&"") -> MQ | F4: =IF(ISBLANK($A4),"NO_CODE",VLOOKUP($A4,'UPD Questions_290926 '!$E$1:$N$300,MATCH(F$1,'UPD Questions_290926 '!$E$1:$N$1,0),0)&"") -> Is there a provision for the establishment of Planning Authorities for notified new towns or special developments? | G4: =IF(ISBLANK($A4),"NO_CODE",VLOOKUP($A4,'UPD Questions_290926 '!$E$1:$N$300,MATCH(G$1,'UPD Questions_290926 '!$E$1:$N$1,0),0)&"") -> Law or Policy | H4: =IF(ISBLANK($A4),"NO_CODE",VLOOKUP($A4,'UPD Questions_290926 '!$E$1:$N$300,MATCH(H$1,'UPD Questions_290926 '!$E$1:$N$1,0),0)) -> 10 | I4: =IF($H4=0,"NA",IF($A4=INDIRECT("'"&$A4&"'!$B$1"),IF(VLOOKUP(I$1,INDIRECT("'"&$A4&"'!$A$12:$Z$41"),MATCH("Points (Auto-generate)",INDIRECT("'"&$A4&"'!$A$12:$Z$12"),0),0)="","?",VLOOKUP(I$1,INDIRECT("'"&$A4&"'!$A$12:$Z$41"),MATCH("Points (Auto-generate)",INDIRECT("'"&$A4&"'!$A$12:$Z$12"),0),0)),"ER")) -> ? | J4: =IF($H4=0,"NA",IF($A4=INDIRECT("'"&$A4&"'!$B$1"),IF(VLOOKUP(J$1,INDIRECT("'"&$A4&"'!$A$12:$Z$41"),MATCH("Points (Auto-generate)",INDIRECT("'"&$A4&"'!$A$12:$Z$12"),0),0)="","?",VLOOKUP(J$1,INDIRECT("'"&$A4&"'!$A$12:$Z$41"),MATCH("Points (Auto-generate)",INDIRECT("'"&$A4&"'!$A$12:$Z$12"),0),0)),"ER")) -> ? | K4: =IF($H4=0,"NA",IF($A4=INDIRECT("'"&$A4&"'!$B$1"),IF(VLOOKUP(K$1,INDIRECT("'"&$A4&"'!$A$12:$Z$41"),MATCH("Points (Auto-generate)",INDIRECT("'"&$A4&"'!$A$12:$Z$12"),0),0)="","?",VLOOKUP(K$1,INDIRECT("'"&$A4&"'!$A$12:$Z$41"),MATCH("Points (Auto-generate)",INDIRECT("'"&$A4&"'!$A$12:$Z$12"),0),0)),"ER")) -> ? | L4: =IF($H4=0,"NA",IF($A4=INDIRECT("'"&$A4&"'!$B$1"),IF(VLOOKUP(L$1,INDIRECT("'"&$A4&"'!$A$12:$Z$41"),MATCH("Points (Auto-generate)",INDIRECT("'"&$A4&"'!$A$12:$Z$12"),0),0)="","?",VLOOKUP(L$1,INDIRECT("'"&$A4&"'!$A$12:$Z$41"),MATCH("Points (Auto-generate)",INDIRECT("'"&$A4&"'!$A$12:$Z$12"),0),0)),"ER")) -> ? | M4: =IF($H4=0,"NA",IF($A4=INDIRECT("'"&$A4&"'!$B$1"),IF(VLOOKUP(M$1,INDIRECT("'"&$A4&"'!$A$12:$Z$41"),MATCH("Points (Auto-generate)",INDIRECT("'"&$A4&"'!$A$12:$Z$12"),0),0)="","?",VLOOKUP(M$1,INDIRECT("'"&$A4&"'!$A$12:$Z$41"),MATCH("Points (Auto-generate)",INDIRECT("'"&$A4&"'!$A$12:$Z$12"),0),0)),"ER")) -> ? | N4: =IF($H4=0,"NA",IF($A4=INDIRECT("'"&$A4&"'!$B$1"),IF(VLOOKUP(N$1,INDIRECT("'"&$A4&"'!$A$12:$Z$41"),MATCH("Points (Auto-generate)",INDIRECT("'"&$A4&"'!$A$12:$Z$12"),0),0)="","?",VLOOKUP(N$1,INDIRECT("'"&$A4&"'!$A$12:$Z$41"),MATCH("Points (Auto-generate)",INDIRECT("'"&$A4&"'!$A$12:$Z$12"),0),0)),"ER")) -> ? | O4: =IF($H4=0,"NA",IF($A4=INDIRECT("'"&$A4&"'!$B$1"),IF(VLOOKUP(O$1,INDIRECT("'"&$A4&"'!$A$12:$Z$41"),MATCH("Points (Auto-generate)",INDIRECT("'"&$A4&"'!$A$12:$Z$12"),0),0)="","?",VLOOKUP(O$1,INDIRECT("'"&$A4&"'!$A$12:$Z$41"),MATCH("Points (Auto-generate)",INDIRECT("'"&$A4&"'!$A$12:$Z$12"),0),0)),"ER")) -> ? | P4: =IF($H4=0,"NA",IF($A4=INDIRECT("'"&$A4&"'!$B$1"),IF(VLOOKUP(P$1,INDIRECT("'"&$A4&"'!$A$12:$Z$41"),MATCH("Points (Auto-generate)",INDIRECT("'"&$A4&"'!$A$12:$Z$12"),0),0)="","?",VLOOKUP(P$1,INDIRECT("'"&$A4&"'!$A$12:$Z$41"),MATCH("Points (Auto-generate)",INDIRECT("'"&$A4&"'!$A$12:$Z$12"),0),0)),"ER")) -> ? | ... AK4: =IF($H4=0,"NA",IF($A4=INDIRECT("'"&$A4&"'!$B$1"),IF(VLOOKUP(AK$1,INDIRECT("'"&$A4&"'!$A$12:$Z$41"),MATCH("Points (Auto-generate)",INDIRECT("'"&$A4&"'!$A$12:$Z$12"),0),0)="","?",VLOOKUP(AK$1,INDIRECT("'"&$A4&"'!$A$12:$Z$41"),MATCH("Points (Auto-generate)",INDIRECT("'"&$A4&"'!$A$12:$Z$12"),0),0)),"ER")) -> ?
A5: UPD3 | B5: =IF(ISBLANK($A5),"NO_CODE",VLOOKUP($A5,'UPD Questions_290926 '!$E$1:$N$300,MATCH(B$1,'UPD Questions_290926 '!$E$1:$N$1,0),0)&"") -> Planning | C5: =IF(ISBLANK($A5),"NO_CODE",VLOOKUP($A5,'UPD Questions_290926 '!$E$1:$N$300,MATCH(C$1,'UPD Questions_290926 '!$E$1:$N$1,0),0)&"") -> Legal and institutional planning architecture | D5: =IF(ISBLANK($A5),"NO_CODE",VLOOKUP($A5,'UPD Questions_290926 '!$E$1:$N$300,MATCH(D$1,'UPD Questions_290926 '!$E$1:$N$1,0),0)&"") -> Spatial planning hierarchy | E5: =IF(ISBLANK($A5),"NO_CODE",VLOOKUP($A5,'UPD Questions_290926 '!$E$1:$N$300,MATCH(E$1,'UPD Questions_290926 '!$E$1:$N$1,0),0)&"") -> MQ | F5: =IF(ISBLANK($A5),"NO_CODE",VLOOKUP($A5,'UPD Questions_290926 '!$E$1:$N$300,MATCH(F$1,'UPD Questions_290926 '!$E$1:$N$1,0),0)&"") -> Does the Act require three levels of spatial plans for cities: Metropolitan/Regional, Municipal and Ward(s) /Local | G5: =IF(ISBLANK($A5),"NO_CODE",VLOOKUP($A5,'UPD Questions_290926 '!$E$1:$N$300,MATCH(G$1,'UPD Questions_290926 '!$E$1:$N$1,0),0)&"") -> Law or Policy | H5: =IF(ISBLANK($A5),"NO_CODE",VLOOKUP($A5,'UPD Questions_290926 '!$E$1:$N$300,MATCH(H$1,'UPD Questions_290926 '!$E$1:$N$1,0),0)) -> 10 | I5: =IF(OR(I6="ER",I7="ER",I8="ER"),"ER",IF(OR(I6="?",I7="?",I8="?"),"?",IF(AND(I6="NA",I7="NA",I8="NA"),"NA",SUM(I6,I7,I8)/((I6<>"NA")*$H$6+(I7<>"NA")*$H$7+(I8<>"NA")*$H$8)*$H5))) -> ? | J5: =IF(OR(J6="ER",J7="ER",J8="ER"),"ER",IF(OR(J6="?",J7="?",J8="?"),"?",IF(AND(J6="NA",J7="NA",J8="NA"),"NA",SUM(J6,J7,J8)/((J6<>"NA")*$H$6+(J7<>"NA")*$H$7+(J8<>"NA")*$H$8)*$H5))) -> ? | K5: =IF(OR(K6="ER",K7="ER",K8="ER"),"ER",IF(OR(K6="?",K7="?",K8="?"),"?",IF(AND(K6="NA",K7="NA",K8="NA"),"NA",SUM(K6,K7,K8)/((K6<>"NA")*$H$6+(K7<>"NA")*$H$7+(K8<>"NA")*$H$8)*$H5))) -> ? | L5: =IF(OR(L6="ER",L7="ER",L8="ER"),"ER",IF(OR(L6="?",L7="?",L8="?"),"?",IF(AND(L6="NA",L7="NA",L8="NA"),"NA",SUM(L6,L7,L8)/((L6<>"NA")*$H$6+(L7<>"NA")*$H$7+(L8<>"NA")*$H$8)*$H5))) -> ? | M5: =IF(OR(M6="ER",M7="ER",M8="ER"),"ER",IF(OR(M6="?",M7="?",M8="?"),"?",IF(AND(M6="NA",M7="NA",M8="NA"),"NA",SUM(M6,M7,M8)/((M6<>"NA")*$H$6+(M7<>"NA")*$H$7+(M8<>"NA")*$H$8)*$H5))) -> ? | N5: =IF(OR(N6="ER",N7="ER",N8="ER"),"ER",IF(OR(N6="?",N7="?",N8="?"),"?",IF(AND(N6="NA",N7="NA",N8="NA"),"NA",SUM(N6,N7,N8)/((N6<>"NA")*$H$6+(N7<>"NA")*$H$7+(N8<>"NA")*$H$8)*$H5))) -> ? | O5: =IF(OR(O6="ER",O7="ER",O8="ER"),"ER",IF(OR(O6="?",O7="?",O8="?"),"?",IF(AND(O6="NA",O7="NA",O8="NA"),"NA",SUM(O6,O7,O8)/((O6<>"NA")*$H$6+(O7<>"NA")*$H$7+(O8<>"NA")*$H$8)*$H5))) -> ? | P5: =IF(OR(P6="ER",P7="ER",P8="ER"),"ER",IF(OR(P6="?",P7="?",P8="?"),"?",IF(AND(P6="NA",P7="NA",P8="NA"),"NA",SUM(P6,P7,P8)/((P6<>"NA")*$H$6+(P7<>"NA")*$H$7+(P8<>"NA")*$H$8)*$H5))) -> ? | ... AK5: =IF(OR(AK6="ER",AK7="ER",AK8="ER"),"ER",IF(OR(AK6="?",AK7="?",AK8="?"),"?",IF(AND(AK6="NA",AK7="NA",AK8="NA"),"NA",SUM(AK6,AK7,AK8)/((AK6<>"NA")*$H$6+(AK7<>"NA")*$H$7+(AK8<>"NA")*$H$8)*$H5))) -> ?
A6: UPD3a | B6: =IF(ISBLANK($A6),"NO_CODE",VLOOKUP($A6,'UPD Questions_290926 '!$E$1:$N$300,MATCH(B$1,'UPD Questions_290926 '!$E$1:$N$1,0),0)&"") -> Planning | C6: =IF(ISBLANK($A6),"NO_CODE",VLOOKUP($A6,'UPD Questions_290926 '!$E$1:$N$300,MATCH(C$1,'UPD Questions_290926 '!$E$1:$N$1,0),0)&"") -> Legal and institutional planning architecture | D6: =IF(ISBLANK($A6),"NO_CODE",VLOOKUP($A6,'UPD Questions_290926 '!$E$1:$N$300,MATCH(D$1,'UPD Questions_290926 '!$E$1:$N$1,0),0)&"") -> Spatial planning hierarchy | E6: =IF(ISBLANK($A6),"NO_CODE",VLOOKUP($A6,'UPD Questions_290926 '!$E$1:$N$300,MATCH(E$1,'UPD Questions_290926 '!$E$1:$N$1,0),0)&"") -> SQ | F6: =IF(ISBLANK($A6),"NO_CODE",VLOOKUP($A6,'UPD Questions_290926 '!$E$1:$N$300,MATCH(F$1,'UPD Questions_290926 '!$E$1:$N$1,0),0)&"") -> Metropolitan/ Regional Plan | G6: =IF(ISBLANK($A6),"NO_CODE",VLOOKUP($A6,'UPD Questions_290926 '!$E$1:$N$300,MATCH(G$1,'UPD Questions_290926 '!$E$1:$N$1,0),0)&"") -> Law or Policy | H6: =IF(ISBLANK($A6),"NO_CODE",VLOOKUP($A6,'UPD Questions_290926 '!$E$1:$N$300,MATCH(H$1,'UPD Questions_290926 '!$E$1:$N$1,0),0)) -> 3.33 | I6: =IF($H6=0,"NA",IF($A6=INDIRECT("'"&$A6&"'!$B$1"),IF(VLOOKUP(I$1,INDIRECT("'"&$A6&"'!$A$12:$Z$41"),MATCH("Points (Auto-generate)",INDIRECT("'"&$A6&"'!$A$12:$Z$12"),0),0)="","?",VLOOKUP(I$1,INDIRECT("'"&$A6&"'!$A$12:$Z$41"),MATCH("Points (Auto-generate)",INDIRECT("'"&$A6&"'!$A$12:$Z$12"),0),0)),"ER")) -> ? | J6: =IF($H6=0,"NA",IF($A6=INDIRECT("'"&$A6&"'!$B$1"),IF(VLOOKUP(J$1,INDIRECT("'"&$A6&"'!$A$12:$Z$41"),MATCH("Points (Auto-generate)",INDIRECT("'"&$A6&"'!$A$12:$Z$12"),0),0)="","?",VLOOKUP(J$1,INDIRECT("'"&$A6&"'!$A$12:$Z$41"),MATCH("Points (Auto-generate)",INDIRECT("'"&$A6&"'!$A$12:$Z$12"),0),0)),"ER")) -> ? | K6: =IF($H6=0,"NA",IF($A6=INDIRECT("'"&$A6&"'!$B$1"),IF(VLOOKUP(K$1,INDIRECT("'"&$A6&"'!$A$12:$Z$41"),MATCH("Points (Auto-generate)",INDIRECT("'"&$A6&"'!$A$12:$Z$12"),0),0)="","?",VLOOKUP(K$1,INDIRECT("'"&$A6&"'!$A$12:$Z$41"),MATCH("Points (Auto-generate)",INDIRECT("'"&$A6&"'!$A$12:$Z$12"),0),0)),"ER")) -> ? | L6: =IF($H6=0,"NA",IF($A6=INDIRECT("'"&$A6&"'!$B$1"),IF(VLOOKUP(L$1,INDIRECT("'"&$A6&"'!$A$12:$Z$41"),MATCH("Points (Auto-generate)",INDIRECT("'"&$A6&"'!$A$12:$Z$12"),0),0)="","?",VLOOKUP(L$1,INDIRECT("'"&$A6&"'!$A$12:$Z$41"),MATCH("Points (Auto-generate)",INDIRECT("'"&$A6&"'!$A$12:$Z$12"),0),0)),"ER")) -> ? | M6: =IF($H6=0,"NA",IF($A6=INDIRECT("'"&$A6&"'!$B$1"),IF(VLOOKUP(M$1,INDIRECT("'"&$A6&"'!$A$12:$Z$41"),MATCH("Points (Auto-generate)",INDIRECT("'"&$A6&"'!$A$12:$Z$12"),0),0)="","?",VLOOKUP(M$1,INDIRECT("'"&$A6&"'!$A$12:$Z$41"),MATCH("Points (Auto-generate)",INDIRECT("'"&$A6&"'!$A$12:$Z$12"),0),0)),"ER")) -> ? | N6: =IF($H6=0,"NA",IF($A6=INDIRECT("'"&$A6&"'!$B$1"),IF(VLOOKUP(N$1,INDIRECT("'"&$A6&"'!$A$12:$Z$41"),MATCH("Points (Auto-generate)",INDIRECT("'"&$A6&"'!$A$12:$Z$12"),0),0)="","?",VLOOKUP(N$1,INDIRECT("'"&$A6&"'!$A$12:$Z$41"),MATCH("Points (Auto-generate)",INDIRECT("'"&$A6&"'!$A$12:$Z$12"),0),0)),"ER")) -> ? | O6: =IF($H6=0,"NA",IF($A6=INDIRECT("'"&$A6&"'!$B$1"),IF(VLOOKUP(O$1,INDIRECT("'"&$A6&"'!$A$12:$Z$41"),MATCH("Points (Auto-generate)",INDIRECT("'"&$A6&"'!$A$12:$Z$12"),0),0)="","?",VLOOKUP(O$1,INDIRECT("'"&$A6&"'!$A$12:$Z$41"),MATCH("Points (Auto-generate)",INDIRECT("'"&$A6&"'!$A$12:$Z$12"),0),0)),"ER")) -> ? | P6: =IF($H6=0,"NA",IF($A6=INDIRECT("'"&$A6&"'!$B$1"),IF(VLOOKUP(P$1,INDIRECT("'"&$A6&"'!$A$12:$Z$41"),MATCH("Points (Auto-generate)",INDIRECT("'"&$A6&"'!$A$12:$Z$12"),0),0)="","?",VLOOKUP(P$1,INDIRECT("'"&$A6&"'!$A$12:$Z$41"),MATCH("Points (Auto-generate)",INDIRECT("'"&$A6&"'!$A$12:$Z$12"),0),0)),"ER")) -> ? | ... AK6: =IF($H6=0,"NA",IF($A6=INDIRECT("'"&$A6&"'!$B$1"),IF(VLOOKUP(AK$1,INDIRECT("'"&$A6&"'!$A$12:$Z$41"),MATCH("Points (Auto-generate)",INDIRECT("'"&$A6&"'!$A$12:$Z$12"),0),0)="","?",VLOOKUP(AK$1,INDIRECT("'"&$A6&"'!$A$12:$Z$41"),MATCH("Points (Auto-generate)",INDIRECT("'"&$A6&"'!$A$12:$Z$12"),0),0)),"ER")) -> ?
A7: UPD3b | B7: =IF(ISBLANK($A7),"NO_CODE",VLOOKUP($A7,'UPD Questions_290926 '!$E$1:$N$300,MATCH(B$1,'UPD Questions_290926 '!$E$1:$N$1,0),0)&"") -> Planning | C7: =IF(ISBLANK($A7),"NO_CODE",VLOOKUP($A7,'UPD Questions_290926 '!$E$1:$N$300,MATCH(C$1,'UPD Questions_290926 '!$E$1:$N$1,0),0)&"") -> Legal and institutional planning architecture | D7: =IF(ISBLANK($A7),"NO_CODE",VLOOKUP($A7,'UPD Questions_290926 '!$E$1:$N$300,MATCH(D$1,'UPD Questions_290926 '!$E$1:$N$1,0),0)&"") -> Spatial planning hierarchy | E7: =IF(ISBLANK($A7),"NO_CODE",VLOOKUP($A7,'UPD Questions_290926 '!$E$1:$N$300,MATCH(E$1,'UPD Questions_290926 '!$E$1:$N$1,0),0)&"") -> SQ | F7: =IF(ISBLANK($A7),"NO_CODE",VLOOKUP($A7,'UPD Questions_290926 '!$E$1:$N$300,MATCH(F$1,'UPD Questions_290926 '!$E$1:$N$1,0),0)&"") -> Municipal/city plan | G7: =IF(ISBLANK($A7),"NO_CODE",VLOOKUP($A7,'UPD Questions_290926 '!$E$1:$N$300,MATCH(G$1,'UPD Questions_290926 '!$E$1:$N$1,0),0)&"") -> Law or Policy | H7: =IF(ISBLANK($A7),"NO_CODE",VLOOKUP($A7,'UPD Questions_290926 '!$E$1:$N$300,MATCH(H$1,'UPD Questions_290926 '!$E$1:$N$1,0),0)) -> 3.33 | I7: =IF($H7=0,"NA",IF($A7=INDIRECT("'"&$A7&"'!$B$1"),IF(VLOOKUP(I$1,INDIRECT("'"&$A7&"'!$A$12:$Z$41"),MATCH("Points (Auto-generate)",INDIRECT("'"&$A7&"'!$A$12:$Z$12"),0),0)="","?",VLOOKUP(I$1,INDIRECT("'"&$A7&"'!$A$12:$Z$41"),MATCH("Points (Auto-generate)",INDIRECT("'"&$A7&"'!$A$12:$Z$12"),0),0)),"ER")) -> ? | J7: =IF($H7=0,"NA",IF($A7=INDIRECT("'"&$A7&"'!$B$1"),IF(VLOOKUP(J$1,INDIRECT("'"&$A7&"'!$A$12:$Z$41"),MATCH("Points (Auto-generate)",INDIRECT("'"&$A7&"'!$A$12:$Z$12"),0),0)="","?",VLOOKUP(J$1,INDIRECT("'"&$A7&"'!$A$12:$Z$41"),MATCH("Points (Auto-generate)",INDIRECT("'"&$A7&"'!$A$12:$Z$12"),0),0)),"ER")) -> ? | K7: =IF($H7=0,"NA",IF($A7=INDIRECT("'"&$A7&"'!$B$1"),IF(VLOOKUP(K$1,INDIRECT("'"&$A7&"'!$A$12:$Z$41"),MATCH("Points (Auto-generate)",INDIRECT("'"&$A7&"'!$A$12:$Z$12"),0),0)="","?",VLOOKUP(K$1,INDIRECT("'"&$A7&"'!$A$12:$Z$41"),MATCH("Points (Auto-generate)",INDIRECT("'"&$A7&"'!$A$12:$Z$12"),0),0)),"ER")) -> ? | L7: =IF($H7=0,"NA",IF($A7=INDIRECT("'"&$A7&"'!$B$1"),IF(VLOOKUP(L$1,INDIRECT("'"&$A7&"'!$A$12:$Z$41"),MATCH("Points (Auto-generate)",INDIRECT("'"&$A7&"'!$A$12:$Z$12"),0),0)="","?",VLOOKUP(L$1,INDIRECT("'"&$A7&"'!$A$12:$Z$41"),MATCH("Points (Auto-generate)",INDIRECT("'"&$A7&"'!$A$12:$Z$12"),0),0)),"ER")) -> ? | M7: =IF($H7=0,"NA",IF($A7=INDIRECT("'"&$A7&"'!$B$1"),IF(VLOOKUP(M$1,INDIRECT("'"&$A7&"'!$A$12:$Z$41"),MATCH("Points (Auto-generate)",INDIRECT("'"&$A7&"'!$A$12:$Z$12"),0),0)="","?",VLOOKUP(M$1,INDIRECT("'"&$A7&"'!$A$12:$Z$41"),MATCH("Points (Auto-generate)",INDIRECT("'"&$A7&"'!$A$12:$Z$12"),0),0)),"ER")) -> ? | N7: =IF($H7=0,"NA",IF($A7=INDIRECT("'"&$A7&"'!$B$1"),IF(VLOOKUP(N$1,INDIRECT("'"&$A7&"'!$A$12:$Z$41"),MATCH("Points (Auto-generate)",INDIRECT("'"&$A7&"'!$A$12:$Z$12"),0),0)="","?",VLOOKUP(N$1,INDIRECT("'"&$A7&"'!$A$12:$Z$41"),MATCH("Points (Auto-generate)",INDIRECT("'"&$A7&"'!$A$12:$Z$12"),0),0)),"ER")) -> ? | O7: =IF($H7=0,"NA",IF($A7=INDIRECT("'"&$A7&"'!$B$1"),IF(VLOOKUP(O$1,INDIRECT("'"&$A7&"'!$A$12:$Z$41"),MATCH("Points (Auto-generate)",INDIRECT("'"&$A7&"'!$A$12:$Z$12"),0),0)="","?",VLOOKUP(O$1,INDIRECT("'"&$A7&"'!$A$12:$Z$41"),MATCH("Points (Auto-generate)",INDIRECT("'"&$A7&"'!$A$12:$Z$12"),0),0)),"ER")) -> ? | P7: =IF($H7=0,"NA",IF($A7=INDIRECT("'"&$A7&"'!$B$1"),IF(VLOOKUP(P$1,INDIRECT("'"&$A7&"'!$A$12:$Z$41"),MATCH("Points (Auto-generate)",INDIRECT("'"&$A7&"'!$A$12:$Z$12"),0),0)="","?",VLOOKUP(P$1,INDIRECT("'"&$A7&"'!$A$12:$Z$41"),MATCH("Points (Auto-generate)",INDIRECT("'"&$A7&"'!$A$12:$Z$12"),0),0)),"ER")) -> ? | ... AK7: =IF($H7=0,"NA",IF($A7=INDIRECT("'"&$A7&"'!$B$1"),IF(VLOOKUP(AK$1,INDIRECT("'"&$A7&"'!$A$12:$Z$41"),MATCH("Points (Auto-generate)",INDIRECT("'"&$A7&"'!$A$12:$Z$12"),0),0)="","?",VLOOKUP(AK$1,INDIRECT("'"&$A7&"'!$A$12:$Z$41"),MATCH("Points (Auto-generate)",INDIRECT("'"&$A7&"'!$A$12:$Z$12"),0),0)),"ER")) -> ?
A8: UPD3c | B8: =IF(ISBLANK($A8),"NO_CODE",VLOOKUP($A8,'UPD Questions_290926 '!$E$1:$N$300,MATCH(B$1,'UPD Questions_290926 '!$E$1:$N$1,0),0)&"") -> Planning | C8: =IF(ISBLANK($A8),"NO_CODE",VLOOKUP($A8,'UPD Questions_290926 '!$E$1:$N$300,MATCH(C$1,'UPD Questions_290926 '!$E$1:$N$1,0),0)&"") -> Legal and institutional planning architecture | D8: =IF(ISBLANK($A8),"NO_CODE",VLOOKUP($A8,'UPD Questions_290926 '!$E$1:$N$300,MATCH(D$1,'UPD Questions_290926 '!$E$1:$N$1,0),0)&"") -> Spatial planning hierarchy | E8: =IF(ISBLANK($A8),"NO_CODE",VLOOKUP($A8,'UPD Questions_290926 '!$E$1:$N$300,MATCH(E$1,'UPD Questions_290926 '!$E$1:$N$1,0),0)&"") -> SQ | F8: =IF(ISBLANK($A8),"NO_CODE",VLOOKUP($A8,'UPD Questions_290926 '!$E$1:$N$300,MATCH(F$1,'UPD Questions_290926 '!$E$1:$N$1,0),0)&"") -> Ward(s)/local plan | G8: =IF(ISBLANK($A8),"NO_CODE",VLOOKUP($A8,'UPD Questions_290926 '!$E$1:$N$300,MATCH(G$1,'UPD Questions_290926 '!$E$1:$N$1,0),0)&"") -> Law or Policy | H8: =IF(ISBLANK($A8),"NO_CODE",VLOOKUP($A8,'UPD Questions_290926 '!$E$1:$N$300,MATCH(H$1,'UPD Questions_290926 '!$E$1:$N$1,0),0)) -> 3.33 | I8: =IF($H8=0,"NA",IF($A8=INDIRECT("'"&$A8&"'!$B$1"),IF(VLOOKUP(I$1,INDIRECT("'"&$A8&"'!$A$12:$Z$41"),MATCH("Points (Auto-generate)",INDIRECT("'"&$A8&"'!$A$12:$Z$12"),0),0)="","?",VLOOKUP(I$1,INDIRECT("'"&$A8&"'!$A$12:$Z$41"),MATCH("Points (Auto-generate)",INDIRECT("'"&$A8&"'!$A$12:$Z$12"),0),0)),"ER")) -> ? | J8: =IF($H8=0,"NA",IF($A8=INDIRECT("'"&$A8&"'!$B$1"),IF(VLOOKUP(J$1,INDIRECT("'"&$A8&"'!$A$12:$Z$41"),MATCH("Points (Auto-generate)",INDIRECT("'"&$A8&"'!$A$12:$Z$12"),0),0)="","?",VLOOKUP(J$1,INDIRECT("'"&$A8&"'!$A$12:$Z$41"),MATCH("Points (Auto-generate)",INDIRECT("'"&$A8&"'!$A$12:$Z$12"),0),0)),"ER")) -> ? | K8: =IF($H8=0,"NA",IF($A8=INDIRECT("'"&$A8&"'!$B$1"),IF(VLOOKUP(K$1,INDIRECT("'"&$A8&"'!$A$12:$Z$41"),MATCH("Points (Auto-generate)",INDIRECT("'"&$A8&"'!$A$12:$Z$12"),0),0)="","?",VLOOKUP(K$1,INDIRECT("'"&$A8&"'!$A$12:$Z$41"),MATCH("Points (Auto-generate)",INDIRECT("'"&$A8&"'!$A$12:$Z$12"),0),0)),"ER")) -> ? | L8: =IF($H8=0,"NA",IF($A8=INDIRECT("'"&$A8&"'!$B$1"),IF(VLOOKUP(L$1,INDIRECT("'"&$A8&"'!$A$12:$Z$41"),MATCH("Points (Auto-generate)",INDIRECT("'"&$A8&"'!$A$12:$Z$12"),0),0)="","?",VLOOKUP(L$1,INDIRECT("'"&$A8&"'!$A$12:$Z$41"),MATCH("Points (Auto-generate)",INDIRECT("'"&$A8&"'!$A$12:$Z$12"),0),0)),"ER")) -> ? | M8: =IF($H8=0,"NA",IF($A8=INDIRECT("'"&$A8&"'!$B$1"),IF(VLOOKUP(M$1,INDIRECT("'"&$A8&"'!$A$12:$Z$41"),MATCH("Points (Auto-generate)",INDIRECT("'"&$A8&"'!$A$12:$Z$12"),0),0)="","?",VLOOKUP(M$1,INDIRECT("'"&$A8&"'!$A$12:$Z$41"),MATCH("Points (Auto-generate)",INDIRECT("'"&$A8&"'!$A$12:$Z$12"),0),0)),"ER")) -> ? | N8: =IF($H8=0,"NA",IF($A8=INDIRECT("'"&$A8&"'!$B$1"),IF(VLOOKUP(N$1,INDIRECT("'"&$A8&"'!$A$12:$Z$41"),MATCH("Points (Auto-generate)",INDIRECT("'"&$A8&"'!$A$12:$Z$12"),0),0)="","?",VLOOKUP(N$1,INDIRECT("'"&$A8&"'!$A$12:$Z$41"),MATCH("Points (Auto-generate)",INDIRECT("'"&$A8&"'!$A$12:$Z$12"),0),0)),"ER")) -> ? | O8: =IF($H8=0,"NA",IF($A8=INDIRECT("'"&$A8&"'!$B$1"),IF(VLOOKUP(O$1,INDIRECT("'"&$A8&"'!$A$12:$Z$41"),MATCH("Points (Auto-generate)",INDIRECT("'"&$A8&"'!$A$12:$Z$12"),0),0)="","?",VLOOKUP(O$1,INDIRECT("'"&$A8&"'!$A$12:$Z$41"),MATCH("Points (Auto-generate)",INDIRECT("'"&$A8&"'!$A$12:$Z$12"),0),0)),"ER")) -> ? | P8: =IF($H8=0,"NA",IF($A8=INDIRECT("'"&$A8&"'!$B$1"),IF(VLOOKUP(P$1,INDIRECT("'"&$A8&"'!$A$12:$Z$41"),MATCH("Points (Auto-generate)",INDIRECT("'"&$A8&"'!$A$12:$Z$12"),0),0)="","?",VLOOKUP(P$1,INDIRECT("'"&$A8&"'!$A$12:$Z$41"),MATCH("Points (Auto-generate)",INDIRECT("'"&$A8&"'!$A$12:$Z$12"),0),0)),"ER")) -> ? | ... AK8: =IF($H8=0,"NA",IF($A8=INDIRECT("'"&$A8&"'!$B$1"),IF(VLOOKUP(AK$1,INDIRECT("'"&$A8&"'!$A$12:$Z$41"),MATCH("Points (Auto-generate)",INDIRECT("'"&$A8&"'!$A$12:$Z$12"),0),0)="","?",VLOOKUP(AK$1,INDIRECT("'"&$A8&"'!$A$12:$Z$41"),MATCH("Points (Auto-generate)",INDIRECT("'"&$A8&"'!$A$12:$Z$12"),0),0)),"ER")) -> ?
A9: UPD4 | B9: =IF(ISBLANK($A9),"NO_CODE",VLOOKUP($A9,'UPD Questions_290926 '!$E$1:$N$300,MATCH(B$1,'UPD Questions_290926 '!$E$1:$N$1,0),0)&"") -> Planning | C9: =IF(ISBLANK($A9),"NO_CODE",VLOOKUP($A9,'UPD Questions_290926 '!$E$1:$N$300,MATCH(C$1,'UPD Questions_290926 '!$E$1:$N$1,0),0)&"") -> Legal and institutional planning architecture | D9: =IF(ISBLANK($A9),"NO_CODE",VLOOKUP($A9,'UPD Questions_290926 '!$E$1:$N$300,MATCH(D$1,'UPD Questions_290926 '!$E$1:$N$1,0),0)&"") -> Spatial planning hierarchy | E9: =IF(ISBLANK($A9),"NO_CODE",VLOOKUP($A9,'UPD Questions_290926 '!$E$1:$N$300,MATCH(E$1,'UPD Questions_290926 '!$E$1:$N$1,0),0)&"") -> MQ | F9: =IF(ISBLANK($A9),"NO_CODE",VLOOKUP($A9,'UPD Questions_290926 '!$E$1:$N$300,MATCH(F$1,'UPD Questions_290926 '!$E$1:$N$1,0),0)&"") -> Is the planning boundary of the municipal/city plan aligned with political and administrative boundaries? | G9: =IF(ISBLANK($A9),"NO_CODE",VLOOKUP($A9,'UPD Questions_290926 '!$E$1:$N$300,MATCH(G$1,'UPD Questions_290926 '!$E$1:$N$1,0),0)&"") -> Law or Policy | H9: =IF(ISBLANK($A9),"NO_CODE",VLOOKUP($A9,'UPD Questions_290926 '!$E$1:$N$300,MATCH(H$1,'UPD Questions_290926 '!$E$1:$N$1,0),0)) -> 10 | I9: =IF($H9=0,"NA",IF($A9=INDIRECT("'"&$A9&"'!$B$1"),IF(VLOOKUP(I$1,INDIRECT("'"&$A9&"'!$A$12:$Z$41"),MATCH("Points (Auto-generate)",INDIRECT("'"&$A9&"'!$A$12:$Z$12"),0),0)="","?",VLOOKUP(I$1,INDIRECT("'"&$A9&"'!$A$12:$Z$41"),MATCH("Points (Auto-generate)",INDIRECT("'"&$A9&"'!$A$12:$Z$12"),0),0)),"ER")) -> ? | J9: =IF($H9=0,"NA",IF($A9=INDIRECT("'"&$A9&"'!$B$1"),IF(VLOOKUP(J$1,INDIRECT("'"&$A9&"'!$A$12:$Z$41"),MATCH("Points (Auto-generate)",INDIRECT("'"&$A9&"'!$A$12:$Z$12"),0),0)="","?",VLOOKUP(J$1,INDIRECT("'"&$A9&"'!$A$12:$Z$41"),MATCH("Points (Auto-generate)",INDIRECT("'"&$A9&"'!$A$12:$Z$12"),0),0)),"ER")) -> 10 | K9: =IF($H9=0,"NA",IF($A9=INDIRECT("'"&$A9&"'!$B$1"),IF(VLOOKUP(K$1,INDIRECT("'"&$A9&"'!$A$12:$Z$41"),MATCH("Points (Auto-generate)",INDIRECT("'"&$A9&"'!$A$12:$Z$12"),0),0)="","?",VLOOKUP(K$1,INDIRECT("'"&$A9&"'!$A$12:$Z$41"),MATCH("Points (Auto-generate)",INDIRECT("'"&$A9&"'!$A$12:$Z$12"),0),0)),"ER")) -> ? | L9: =IF($H9=0,"NA",IF($A9=INDIRECT("'"&$A9&"'!$B$1"),IF(VLOOKUP(L$1,INDIRECT("'"&$A9&"'!$A$12:$Z$41"),MATCH("Points (Auto-generate)",INDIRECT("'"&$A9&"'!$A$12:$Z$12"),0),0)="","?",VLOOKUP(L$1,INDIRECT("'"&$A9&"'!$A$12:$Z$41"),MATCH("Points (Auto-generate)",INDIRECT("'"&$A9&"'!$A$12:$Z$12"),0),0)),"ER")) -> ? | M9: =IF($H9=0,"NA",IF($A9=INDIRECT("'"&$A9&"'!$B$1"),IF(VLOOKUP(M$1,INDIRECT("'"&$A9&"'!$A$12:$Z$41"),MATCH("Points (Auto-generate)",INDIRECT("'"&$A9&"'!$A$12:$Z$12"),0),0)="","?",VLOOKUP(M$1,INDIRECT("'"&$A9&"'!$A$12:$Z$41"),MATCH("Points (Auto-generate)",INDIRECT("'"&$A9&"'!$A$12:$Z$12"),0),0)),"ER")) -> ? | N9: =IF($H9=0,"NA",IF($A9=INDIRECT("'"&$A9&"'!$B$1"),IF(VLOOKUP(N$1,INDIRECT("'"&$A9&"'!$A$12:$Z$41"),MATCH("Points (Auto-generate)",INDIRECT("'"&$A9&"'!$A$12:$Z$12"),0),0)="","?",VLOOKUP(N$1,INDIRECT("'"&$A9&"'!$A$12:$Z$41"),MATCH("Points (Auto-generate)",INDIRECT("'"&$A9&"'!$A$12:$Z$12"),0),0)),"ER")) -> ? | O9: =IF($H9=0,"NA",IF($A9=INDIRECT("'"&$A9&"'!$B$1"),IF(VLOOKUP(O$1,INDIRECT("'"&$A9&"'!$A$12:$Z$41"),MATCH("Points (Auto-generate)",INDIRECT("'"&$A9&"'!$A$12:$Z$12"),0),0)="","?",VLOOKUP(O$1,INDIRECT("'"&$A9&"'!$A$12:$Z$41"),MATCH("Points (Auto-generate)",INDIRECT("'"&$A9&"'!$A$12:$Z$12"),0),0)),"ER")) -> ? | P9: =IF($H9=0,"NA",IF($A9=INDIRECT("'"&$A9&"'!$B$1"),IF(VLOOKUP(P$1,INDIRECT("'"&$A9&"'!$A$12:$Z$41"),MATCH("Points (Auto-generate)",INDIRECT("'"&$A9&"'!$A$12:$Z$12"),0),0)="","?",VLOOKUP(P$1,INDIRECT("'"&$A9&"'!$A$12:$Z$41"),MATCH("Points (Auto-generate)",INDIRECT("'"&$A9&"'!$A$12:$Z$12"),0),0)),"ER")) -> ? | ... AK9: =IF($H9=0,"NA",IF($A9=INDIRECT("'"&$A9&"'!$B$1"),IF(VLOOKUP(AK$1,INDIRECT("'"&$A9&"'!$A$12:$Z$41"),MATCH("Points (Auto-generate)",INDIRECT("'"&$A9&"'!$A$12:$Z$12"),0),0)="","?",VLOOKUP(AK$1,INDIRECT("'"&$A9&"'!$A$12:$Z$41"),MATCH("Points (Auto-generate)",INDIRECT("'"&$A9&"'!$A$12:$Z$12"),0),0)),"ER")) -> ?
