Workbook

Sheet Check before use
A1: DRAFT PARASTATAL scoring workbook - generated from the methodology sheet
A3: This draft follows the same layout as the UPD scoring workbook, so the app can fill, merge and read it. The scoring experts should:
A4: 1. Replace each question sheet's simple inputs (yellow) and Points formula with the real ones, keeping the row-11 instructions (e.g. SELECT YES / NO) and the column names 'Points (Auto-generate)' and 'SCORER COMMENTS'.
A5: 2. Check 'Applies?' (filled in from each agency's type and the question's Applicability). To change it, fix the agency in the city register or Sources workbook and generate again.
A6: 3. Fix the points below in the methodology sheet and generate again.
A8: Points to check:
A9: • Section 'Decentralised Participatory Governance' has no (CODE); using DPG
A10: • Section 'State Capacities' has no (CODE); using SC
A11: • Question Bank row 57: the ID "SC-5" is used twice. Each question needs its own ID; the second one was skipped.
A12: • UPD 1a: the methodology gives scores up to 10, but the Max Score is 5. Say how the score should be scaled.
A13: • DPG 4 has no Tag or Max Score, so it is left out of the scores. Add them if it should be scored.

Sheet PARASTATAL_SUMMARY_RAW
A1: ASICS 2027_Report_Q No | B1: Group | C1: MQ_SQ | D1: Question | E1: Assessment level | F1: Max Score | G1: Bengaluru – BWSSB | H1: Bengaluru – BMTC | I1: Bengaluru – BDA | J1: Bengaluru – BMRCL | K1: Bengaluru – BMRDA | L1: Surat – SUDA | M1: Surat – GMRC
A2: ENTER | B2: Derived | C2: Derived | D2: Derived | E2: Derived | F2: Derived | G2: Derived | H2: Derived | I2: Derived | J2: Derived | K2: Derived | L2: Derived | M2: Derived
A3: UPD1 | B3: =VLOOKUP($A3,'PARASTATAL Questions'!$A:$J,3,0)&"" -> Urban Planning & Design (UPD) | C3: =VLOOKUP($A3,'PARASTATAL Questions'!$A:$J,4,0)&"" -> MQ | D3: =VLOOKUP($A3,'PARASTATAL Questions'!$A:$J,5,0)&"" -> Does the parastatal coordinate with the ULG(s) in preparing its sectoral plans? | E3: =VLOOKUP($A3,'PARASTATAL Questions'!$A:$J,7,0)&"" -> Law/Policy + Implementation | F3: =VLOOKUP($A3,'PARASTATAL Questions'!$A:$J,6,0) -> 10 | G3: =IF(OR(G4="ER",G5="ER"),"ER",IF(OR(G4="?",G5="?"),"?",IF(AND(G4="NA",G5="NA"),"NA",SUM(G4,G5)/((G4<>"NA")*$F$4+(G5<>"NA")*$F$5)*$F3))) -> 5 | H3: =IF(OR(H4="ER",H5="ER"),"ER",IF(OR(H4="?",H5="?"),"?",IF(AND(H4="NA",H5="NA"),"NA",SUM(H4,H5)/((H4<>"NA")*$F$4+(H5<>"NA")*$F$5)*$F3))) -> ? | I3: =IF(OR(I4="ER",I5="ER"),"ER",IF(OR(I4="?",I5="?"),"?",IF(AND(I4="NA",I5="NA"),"NA",SUM(I4,I5)/((I4<>"NA")*$F$4+(I5<>"NA")*$F$5)*$F3))) -> NA | J3: =IF(OR(J4="ER",J5="ER"),"ER",IF(OR(J4="?",J5="?"),"?",IF(AND(J4="NA",J5="NA"),"NA",SUM(J4,J5)/((J4<>"NA")*$F$4+(J5<>"NA")*$F$5)*$F3))) -> ? | K3: =IF(OR(K4="ER",K5="ER"),"ER",IF(OR(K4="?",K5="?"),"?",IF(AND(K4="NA",K5="NA"),"NA",SUM(K4,K5)/((K4<>"NA")*$F$4+(K5<>"NA")*$F$5)*$F3))) -> NA | L3: =IF(OR(L4="ER",L5="ER"),"ER",IF(OR(L4="?",L5="?"),"?",IF(AND(L4="NA",L5="NA"),"NA",SUM(L4,L5)/((L4<>"NA")*$F$4+(L5<>"NA")*$F$5)*$F3))) -> NA | M3: =IF(OR(M4="ER",M5="ER"),"ER",IF(OR(M4="?",M5="?"),"?",IF(AND(M4="NA",M5="NA"),"NA",SUM(M4,M5)/((M4<>"NA")*$F$4+(M5<>"NA")*$F$5)*$F3))) -> ?
A4: UPD1a | B4: =VLOOKUP($A4,'PARASTATAL Questions'!$A:$J,3,0)&"" -> Urban Planning & Design (UPD) | C4: =VLOOKUP($A4,'PARASTATAL Questions'!$A:$J,4,0)&"" -> SQ | D4: =VLOOKUP($A4,'PARASTATAL Questions'!$A:$J,5,0)&"" -> Is the parastatal mandated to prepare its sectoral plans in coordination with the ULG(s) within its jurisdiction? | E4: =VLOOKUP($A4,'PARASTATAL Questions'!$A:$J,7,0)&"" -> Law/Policy | F4: =VLOOKUP($A4,'PARASTATAL Questions'!$A:$J,6,0) -> 5 | G4: =IF($F4=0,"NA",IF($A4=INDIRECT("'"&$A4&"'!$B$1"),IF(VLOOKUP(G$1,INDIRECT("'"&$A4&"'!$A$12:$Z$19"),MATCH("Points (Auto-generate)",INDIRECT("'"&$A4&"'!$A$12:$Z$12"),0),0)="","?",VLOOKUP(G$1,INDIRECT("'"&$A4&"'!$A$12:$Z$19"),MATCH("Points (Auto-generate)",INDIRECT("'"&$A4&"'!$A$12:$Z$12"),0),0)),"ER")) -> 0 | H4: =IF($F4=0,"NA",IF($A4=INDIRECT("'"&$A4&"'!$B$1"),IF(VLOOKUP(H$1,INDIRECT("'"&$A4&"'!$A$12:$Z$19"),MATCH("Points (Auto-generate)",INDIRECT("'"&$A4&"'!$A$12:$Z$12"),0),0)="","?",VLOOKUP(H$1,INDIRECT("'"&$A4&"'!$A$12:$Z$19"),MATCH("Points (Auto-generate)",INDIRECT("'"&$A4&"'!$A$12:$Z$12"),0),0)),"ER")) -> ? | I4: =IF($F4=0,"NA",IF($A4=INDIRECT("'"&$A4&"'!$B$1"),IF(VLOOKUP(I$1,INDIRECT("'"&$A4&"'!$A$12:$Z$19"),MATCH("Points (Auto-generate)",INDIRECT("'"&$A4&"'!$A$12:$Z$12"),0),0)="","?",VLOOKUP(I$1,INDIRECT("'"&$A4&"'!$A$12:$Z$19"),MATCH("Points (Auto-generate)",INDIRECT("'"&$A4&"'!$A$12:$Z$12"),0),0)),"ER")) -> NA | J4: =IF($F4=0,"NA",IF($A4=INDIRECT("'"&$A4&"'!$B$1"),IF(VLOOKUP(J$1,INDIRECT("'"&$A4&"'!$A$12:$Z$19"),MATCH("Points (Auto-generate)",INDIRECT("'"&$A4&"'!$A$12:$Z$12"),0),0)="","?",VLOOKUP(J$1,INDIRECT("'"&$A4&"'!$A$12:$Z$19"),MATCH("Points (Auto-generate)",INDIRECT("'"&$A4&"'!$A$12:$Z$12"),0),0)),"ER")) -> 0 | K4: =IF($F4=0,"NA",IF($A4=INDIRECT("'"&$A4&"'!$B$1"),IF(VLOOKUP(K$1,INDIRECT("'"&$A4&"'!$A$12:$Z$19"),MATCH("Points (Auto-generate)",INDIRECT("'"&$A4&"'!$A$12:$Z$12"),0),0)="","?",VLOOKUP(K$1,INDIRECT("'"&$A4&"'!$A$12:$Z$19"),MATCH("Points (Auto-generate)",INDIRECT("'"&$A4&"'!$A$12:$Z$12"),0),0)),"ER")) -> NA | L4: =IF($F4=0,"NA",IF($A4=INDIRECT("'"&$A4&"'!$B$1"),IF(VLOOKUP(L$1,INDIRECT("'"&$A4&"'!$A$12:$Z$19"),MATCH("Points (Auto-generate)",INDIRECT("'"&$A4&"'!$A$12:$Z$12"),0),0)="","?",VLOOKUP(L$1,INDIRECT("'"&$A4&"'!$A$12:$Z$19"),MATCH("Points (Auto-generate)",INDIRECT("'"&$A4&"'!$A$12:$Z$12"),0),0)),"ER")) -> NA | M4: =IF($F4=0,"NA",IF($A4=INDIRECT("'"&$A4&"'!$B$1"),IF(VLOOKUP(M$1,INDIRECT("'"&$A4&"'!$A$12:$Z$19"),MATCH("Points (Auto-generate)",INDIRECT("'"&$A4&"'!$A$12:$Z$12"),0),0)="","?",VLOOKUP(M$1,INDIRECT("'"&$A4&"'!$A$12:$Z$19"),MATCH("Points (Auto-generate)",INDIRECT("'"&$A4&"'!$A$12:$Z$12"),0),0)),"ER")) -> ?
A5: UPD1b | B5: =VLOOKUP($A5,'PARASTATAL Questions'!$A:$J,3,0)&"" -> Urban Planning & Design (UPD) | C5: =VLOOKUP($A5,'PARASTATAL Questions'!$A:$J,4,0)&"" -> SQ | D5: =VLOOKUP($A5,'PARASTATAL Questions'!$A:$J,5,0)&"" -> Has the ULG participated in the parastatal’s plan-making process? | E5: =VLOOKUP($A5,'PARASTATAL Questions'!$A:$J,7,0)&"" -> Implementation | F5: =VLOOKUP($A5,'PARASTATAL Questions'!$A:$J,6,0) -> 5 | G5: =IF($F5=0,"NA",IF($A5=INDIRECT("'"&$A5&"'!$B$1"),IF(VLOOKUP(G$1,INDIRECT("'"&$A5&"'!$A$12:$Z$19"),MATCH("Points (Auto-generate)",INDIRECT("'"&$A5&"'!$A$12:$Z$12"),0),0)="","?",VLOOKUP(G$1,INDIRECT("'"&$A5&"'!$A$12:$Z$19"),MATCH("Points (Auto-generate)",INDIRECT("'"&$A5&"'!$A$12:$Z$12"),0),0)),"ER")) -> 5 | H5: =IF($F5=0,"NA",IF($A5=INDIRECT("'"&$A5&"'!$B$1"),IF(VLOOKUP(H$1,INDIRECT("'"&$A5&"'!$A$12:$Z$19"),MATCH("Points (Auto-generate)",INDIRECT("'"&$A5&"'!$A$12:$Z$12"),0),0)="","?",VLOOKUP(H$1,INDIRECT("'"&$A5&"'!$A$12:$Z$19"),MATCH("Points (Auto-generate)",INDIRECT("'"&$A5&"'!$A$12:$Z$12"),0),0)),"ER")) -> ? | I5: =IF($F5=0,"NA",IF($A5=INDIRECT("'"&$A5&"'!$B$1"),IF(VLOOKUP(I$1,INDIRECT("'"&$A5&"'!$A$12:$Z$19"),MATCH("Points (Auto-generate)",INDIRECT("'"&$A5&"'!$A$12:$Z$12"),0),0)="","?",VLOOKUP(I$1,INDIRECT("'"&$A5&"'!$A$12:$Z$19"),MATCH("Points (Auto-generate)",INDIRECT("'"&$A5&"'!$A$12:$Z$12"),0),0)),"ER")) -> NA | J5: =IF($F5=0,"NA",IF($A5=INDIRECT("'"&$A5&"'!$B$1"),IF(VLOOKUP(J$1,INDIRECT("'"&$A5&"'!$A$12:$Z$19"),MATCH("Points (Auto-generate)",INDIRECT("'"&$A5&"'!$A$12:$Z$12"),0),0)="","?",VLOOKUP(J$1,INDIRECT("'"&$A5&"'!$A$12:$Z$19"),MATCH("Points (Auto-generate)",INDIRECT("'"&$A5&"'!$A$12:$Z$12"),0),0)),"ER")) -> ? | K5: =IF($F5=0,"NA",IF($A5=INDIRECT("'"&$A5&"'!$B$1"),IF(VLOOKUP(K$1,INDIRECT("'"&$A5&"'!$A$12:$Z$19"),MATCH("Points (Auto-generate)",INDIRECT("'"&$A5&"'!$A$12:$Z$12"),0),0)="","?",VLOOKUP(K$1,INDIRECT("'"&$A5&"'!$A$12:$Z$19"),MATCH("Points (Auto-generate)",INDIRECT("'"&$A5&"'!$A$12:$Z$12"),0),0)),"ER")) -> NA | L5: =IF($F5=0,"NA",IF($A5=INDIRECT("'"&$A5&"'!$B$1"),IF(VLOOKUP(L$1,INDIRECT("'"&$A5&"'!$A$12:$Z$19"),MATCH("Points (Auto-generate)",INDIRECT("'"&$A5&"'!$A$12:$Z$12"),0),0)="","?",VLOOKUP(L$1,INDIRECT("'"&$A5&"'!$A$12:$Z$19"),MATCH("Points (Auto-generate)",INDIRECT("'"&$A5&"'!$A$12:$Z$12"),0),0)),"ER")) -> NA | M5: =IF($F5=0,"NA",IF($A5=INDIRECT("'"&$A5&"'!$B$1"),IF(VLOOKUP(M$1,INDIRECT("'"&$A5&"'!$A$12:$Z$19"),MATCH("Points (Auto-generate)",INDIRECT("'"&$A5&"'!$A$12:$Z$12"),0),0)="","?",VLOOKUP(M$1,INDIRECT("'"&$A5&"'!$A$12:$Z$19"),MATCH("Points (Auto-generate)",INDIRECT("'"&$A5&"'!$A$12:$Z$12"),0),0)),"ER")) -> ?
A6: UPD2 | B6: =VLOOKUP($A6,'PARASTATAL Questions'!$A:$J,3,0)&"" -> Urban Planning & Design (UPD) | C6: =VLOOKUP($A6,'PARASTATAL Questions'!$A:$J,4,0)&"" -> MQ | D6: =VLOOKUP($A6,'PARASTATAL Questions'!$A:$J,5,0)&"" -> Where multiple statutory or sectoral plans apply to the same territory, does the water supply board and transport corporation ensure consistency with the municipal/city plan for the city? | E6: =VLOOKUP($A6,'PARASTATAL Questions'!$A:$J,7,0)&"" -> Law/Policy + Implementation | F6: =VLOOKUP($A6,'PARASTATAL Questions'!$A:$J,6,0) -> 10 | G6: =IF(OR(G7="ER",G8="ER",G9="ER",G10="ER"),"ER",IF(OR(G7="?",G8="?",G9="?",G10="?"),"?",IF(AND(G7="NA",G8="NA",G9="NA",G10="NA"),"NA",SUM(G7,G8,G9,G10)/((G7<>"NA")*$F$7+(G8<>"NA")*$F$8+(G9<>"NA")*$F$9+(G10<>"NA")*$F$10)*$F6))) -> ? | H6: =IF(OR(H7="ER",H8="ER",H9="ER",H10="ER"),"ER",IF(OR(H7="?",H8="?",H9="?",H10="?"),"?",IF(AND(H7="NA",H8="NA",H9="NA",H10="NA"),"NA",SUM(H7,H8,H9,H10)/((H7<>"NA")*$F$7+(H8<>"NA")*$F$8+(H9<>"NA")*$F$9+(H10<>"NA")*$F$10)*$F6))) -> ? | I6: =IF(OR(I7="ER",I8="ER",I9="ER",I10="ER"),"ER",IF(OR(I7="?",I8="?",I9="?",I10="?"),"?",IF(AND(I7="NA",I8="NA",I9="NA",I10="NA"),"NA",SUM(I7,I8,I9,I10)/((I7<>"NA")*$F$7+(I8<>"NA")*$F$8+(I9<>"NA")*$F$9+(I10<>"NA")*$F$10)*$F6))) -> NA | J6: =IF(OR(J7="ER",J8="ER",J9="ER",J10="ER"),"ER",IF(OR(J7="?",J8="?",J9="?",J10="?"),"?",IF(AND(J7="NA",J8="NA",J9="NA",J10="NA"),"NA",SUM(J7,J8,J9,J10)/((J7<>"NA")*$F$7+(J8<>"NA")*$F$8+(J9<>"NA")*$F$9+(J10<>"NA")*$F$10)*$F6))) -> NA | K6: =IF(OR(K7="ER",K8="ER",K9="ER",K10="ER"),"ER",IF(OR(K7="?",K8="?",K9="?",K10="?"),"?",IF(AND(K7="NA",K8="NA",K9="NA",K10="NA"),"NA",SUM(K7,K8,K9,K10)/((K7<>"NA")*$F$7+(K8<>"NA")*$F$8+(K9<>"NA")*$F$9+(K10<>"NA")*$F$10)*$F6))) -> NA | L6: =IF(OR(L7="ER",L8="ER",L9="ER",L10="ER"),"ER",IF(OR(L7="?",L8="?",L9="?",L10="?"),"?",IF(AND(L7="NA",L8="NA",L9="NA",L10="NA"),"NA",SUM(L7,L8,L9,L10)/((L7<>"NA")*$F$7+(L8<>"NA")*$F$8+(L9<>"NA")*$F$9+(L10<>"NA")*$F$10)*$F6))) -> NA | M6: =IF(OR(M7="ER",M8="ER",M9="ER",M10="ER"),"ER",IF(OR(M7="?",M8="?",M9="?",M10="?"),"?",IF(AND(M7="NA",M8="NA",M9="NA",M10="NA"),"NA",SUM(M7,M8,M9,M10)/((M7<>"NA")*$F$7+(M8<>"NA")*$F$8+(M9<>"NA")*$F$9+(M10<>"NA")*$F$10)*$F6))) -> NA
A7: UPD2a | B7: =VLOOKUP($A7,'PARASTATAL Questions'!$A:$J,3,0)&"" -> Urban Planning & Design (UPD) | C7: =VLOOKUP($A7,'PARASTATAL Questions'!$A:$J,4,0)&"" -> SQ | D7: =VLOOKUP($A7,'PARASTATAL Questions'!$A:$J,5,0)&"" -> Where multiple statutory or sectoral plans apply to the same territory, is the water board mandated to ensure consistency with the applicable city /municipal plan for the city? | E7: =VLOOKUP($A7,'PARASTATAL Questions'!$A:$J,7,0)&"" -> Law/Policy | F7: =VLOOKUP($A7,'PARASTATAL Questions'!$A:$J,6,0) -> 2.5 | G7: =IF($F7=0,"NA",IF($A7=INDIRECT("'"&$A7&"'!$B$1"),IF(VLOOKUP(G$1,INDIRECT("'"&$A7&"'!$A$12:$Z$19"),MATCH("Points (Auto-generate)",INDIRECT("'"&$A7&"'!$A$12:$Z$12"),0),0)="","?",VLOOKUP(G$1,INDIRECT("'"&$A7&"'!$A$12:$Z$19"),MATCH("Points (Auto-generate)",INDIRECT("'"&$A7&"'!$A$12:$Z$12"),0),0)),"ER")) -> ? | H7: =IF($F7=0,"NA",IF($A7=INDIRECT("'"&$A7&"'!$B$1"),IF(VLOOKUP(H$1,INDIRECT("'"&$A7&"'!$A$12:$Z$19"),MATCH("Points (Auto-generate)",INDIRECT("'"&$A7&"'!$A$12:$Z$12"),0),0)="","?",VLOOKUP(H$1,INDIRECT("'"&$A7&"'!$A$12:$Z$19"),MATCH("Points (Auto-generate)",INDIRECT("'"&$A7&"'!$A$12:$Z$12"),0),0)),"ER")) -> NA | I7: =IF($F7=0,"NA",IF($A7=INDIRECT("'"&$A7&"'!$B$1"),IF(VLOOKUP(I$1,INDIRECT("'"&$A7&"'!$A$12:$Z$19"),MATCH("Points (Auto-generate)",INDIRECT("'"&$A7&"'!$A$12:$Z$12"),0),0)="","?",VLOOKUP(I$1,INDIRECT("'"&$A7&"'!$A$12:$Z$19"),MATCH("Points (Auto-generate)",INDIRECT("'"&$A7&"'!$A$12:$Z$12"),0),0)),"ER")) -> NA | J7: =IF($F7=0,"NA",IF($A7=INDIRECT("'"&$A7&"'!$B$1"),IF(VLOOKUP(J$1,INDIRECT("'"&$A7&"'!$A$12:$Z$19"),MATCH("Points (Auto-generate)",INDIRECT("'"&$A7&"'!$A$12:$Z$12"),0),0)="","?",VLOOKUP(J$1,INDIRECT("'"&$A7&"'!$A$12:$Z$19"),MATCH("Points (Auto-generate)",INDIRECT("'"&$A7&"'!$A$12:$Z$12"),0),0)),"ER")) -> NA | K7: =IF($F7=0,"NA",IF($A7=INDIRECT("'"&$A7&"'!$B$1"),IF(VLOOKUP(K$1,INDIRECT("'"&$A7&"'!$A$12:$Z$19"),MATCH("Points (Auto-generate)",INDIRECT("'"&$A7&"'!$A$12:$Z$12"),0),0)="","?",VLOOKUP(K$1,INDIRECT("'"&$A7&"'!$A$12:$Z$19"),MATCH("Points (Auto-generate)",INDIRECT("'"&$A7&"'!$A$12:$Z$12"),0),0)),"ER")) -> NA | L7: =IF($F7=0,"NA",IF($A7=INDIRECT("'"&$A7&"'!$B$1"),IF(VLOOKUP(L$1,INDIRECT("'"&$A7&"'!$A$12:$Z$19"),MATCH("Points (Auto-generate)",INDIRECT("'"&$A7&"'!$A$12:$Z$12"),0),0)="","?",VLOOKUP(L$1,INDIRECT("'"&$A7&"'!$A$12:$Z$19"),MATCH("Points (Auto-generate)",INDIRECT("'"&$A7&"'!$A$12:$Z$12"),0),0)),"ER")) -> NA | M7: =IF($F7=0,"NA",IF($A7=INDIRECT("'"&$A7&"'!$B$1"),IF(VLOOKUP(M$1,INDIRECT("'"&$A7&"'!$A$12:$Z$19"),MATCH("Points (Auto-generate)",INDIRECT("'"&$A7&"'!$A$12:$Z$12"),0),0)="","?",VLOOKUP(M$1,INDIRECT("'"&$A7&"'!$A$12:$Z$19"),MATCH("Points (Auto-generate)",INDIRECT("'"&$A7&"'!$A$12:$Z$12"),0),0)),"ER")) -> NA
A8: UPD2b | B8: =VLOOKUP($A8,'PARASTATAL Questions'!$A:$J,3,0)&"" -> Urban Planning & Design (UPD) | C8: =VLOOKUP($A8,'PARASTATAL Questions'!$A:$J,4,0)&"" -> SQ | D8: =VLOOKUP($A8,'PARASTATAL Questions'!$A:$J,5,0)&"" -> Where multiple statutory or sectoral plans apply to the same territory, does the water supply board ensure consistency with the applicable municipal/city plan for the city? | E8: =VLOOKUP($A8,'PARASTATAL Questions'!$A:$J,7,0)&"" -> Implementation | F8: =VLOOKUP($A8,'PARASTATAL Questions'!$A:$J,6,0) -> 2.5 | G8: =IF($F8=0,"NA",IF($A8=INDIRECT("'"&$A8&"'!$B$1"),IF(VLOOKUP(G$1,INDIRECT("'"&$A8&"'!$A$12:$Z$19"),MATCH("Points (Auto-generate)",INDIRECT("'"&$A8&"'!$A$12:$Z$12"),0),0)="","?",VLOOKUP(G$1,INDIRECT("'"&$A8&"'!$A$12:$Z$19"),MATCH("Points (Auto-generate)",INDIRECT("'"&$A8&"'!$A$12:$Z$12"),0),0)),"ER")) -> ? | H8: =IF($F8=0,"NA",IF($A8=INDIRECT("'"&$A8&"'!$B$1"),IF(VLOOKUP(H$1,INDIRECT("'"&$A8&"'!$A$12:$Z$19"),MATCH("Points (Auto-generate)",INDIRECT("'"&$A8&"'!$A$12:$Z$12"),0),0)="","?",VLOOKUP(H$1,INDIRECT("'"&$A8&"'!$A$12:$Z$19"),MATCH("Points (Auto-generate)",INDIRECT("'"&$A8&"'!$A$12:$Z$12"),0),0)),"ER")) -> NA | I8: =IF($F8=0,"NA",IF($A8=INDIRECT("'"&$A8&"'!$B$1"),IF(VLOOKUP(I$1,INDIRECT("'"&$A8&"'!$A$12:$Z$19"),MATCH("Points (Auto-generate)",INDIRECT("'"&$A8&"'!$A$12:$Z$12"),0),0)="","?",VLOOKUP(I$1,INDIRECT("'"&$A8&"'!$A$12:$Z$19"),MATCH("Points (Auto-generate)",INDIRECT("'"&$A8&"'!$A$12:$Z$12"),0),0)),"ER")) -> NA | J8: =IF($F8=0,"NA",IF($A8=INDIRECT("'"&$A8&"'!$B$1"),IF(VLOOKUP(J$1,INDIRECT("'"&$A8&"'!$A$12:$Z$19"),MATCH("Points (Auto-generate)",INDIRECT("'"&$A8&"'!$A$12:$Z$12"),0),0)="","?",VLOOKUP(J$1,INDIRECT("'"&$A8&"'!$A$12:$Z$19"),MATCH("Points (Auto-generate)",INDIRECT("'"&$A8&"'!$A$12:$Z$12"),0),0)),"ER")) -> NA | K8: =IF($F8=0,"NA",IF($A8=INDIRECT("'"&$A8&"'!$B$1"),IF(VLOOKUP(K$1,INDIRECT("'"&$A8&"'!$A$12:$Z$19"),MATCH("Points (Auto-generate)",INDIRECT("'"&$A8&"'!$A$12:$Z$12"),0),0)="","?",VLOOKUP(K$1,INDIRECT("'"&$A8&"'!$A$12:$Z$19"),MATCH("Points (Auto-generate)",INDIRECT("'"&$A8&"'!$A$12:$Z$12"),0),0)),"ER")) -> NA | L8: =IF($F8=0,"NA",IF($A8=INDIRECT("'"&$A8&"'!$B$1"),IF(VLOOKUP(L$1,INDIRECT("'"&$A8&"'!$A$12:$Z$19"),MATCH("Points (Auto-generate)",INDIRECT("'"&$A8&"'!$A$12:$Z$12"),0),0)="","?",VLOOKUP(L$1,INDIRECT("'"&$A8&"'!$A$12:$Z$19"),MATCH("Points (Auto-generate)",INDIRECT("'"&$A8&"'!$A$12:$Z$12"),0),0)),"ER")) -> NA | M8: =IF($F8=0,"NA",IF($A8=INDIRECT("'"&$A8&"'!$B$1"),IF(VLOOKUP(M$1,INDIRECT("'"&$A8&"'!$A$12:$Z$19"),MATCH("Points (Auto-generate)",INDIRECT("'"&$A8&"'!$A$12:$Z$12"),0),0)="","?",VLOOKUP(M$1,INDIRECT("'"&$A8&"'!$A$12:$Z$19"),MATCH("Points (Auto-generate)",INDIRECT("'"&$A8&"'!$A$12:$Z$12"),0),0)),"ER")) -> NA
A9: UPD2c | B9: =VLOOKUP($A9,'PARASTATAL Questions'!$A:$J,3,0)&"" -> Urban Planning & Design (UPD) | C9: =VLOOKUP($A9,'PARASTATAL Questions'!$A:$J,4,0)&"" -> SQ | D9: =VLOOKUP($A9,'PARASTATAL Questions'!$A:$J,5,0)&"" -> Where multiple statutory or sectoral plans apply to the same territory, is the transport corporation mandated to ensure consistency with the applicable municipal/city plan for the city? | E9: =VLOOKUP($A9,'PARASTATAL Questions'!$A:$J,7,0)&"" -> Law/Policy | F9: =VLOOKUP($A9,'PARASTATAL Questions'!$A:$J,6,0) -> 2.5 | G9: =IF($F9=0,"NA",IF($A9=INDIRECT("'"&$A9&"'!$B$1"),IF(VLOOKUP(G$1,INDIRECT("'"&$A9&"'!$A$12:$Z$19"),MATCH("Points (Auto-generate)",INDIRECT("'"&$A9&"'!$A$12:$Z$12"),0),0)="","?",VLOOKUP(G$1,INDIRECT("'"&$A9&"'!$A$12:$Z$19"),MATCH("Points (Auto-generate)",INDIRECT("'"&$A9&"'!$A$12:$Z$12"),0),0)),"ER")) -> NA | H9: =IF($F9=0,"NA",IF($A9=INDIRECT("'"&$A9&"'!$B$1"),IF(VLOOKUP(H$1,INDIRECT("'"&$A9&"'!$A$12:$Z$19"),MATCH("Points (Auto-generate)",INDIRECT("'"&$A9&"'!$A$12:$Z$12"),0),0)="","?",VLOOKUP(H$1,INDIRECT("'"&$A9&"'!$A$12:$Z$19"),MATCH("Points (Auto-generate)",INDIRECT("'"&$A9&"'!$A$12:$Z$12"),0),0)),"ER")) -> 0 | I9: =IF($F9=0,"NA",IF($A9=INDIRECT("'"&$A9&"'!$B$1"),IF(VLOOKUP(I$1,INDIRECT("'"&$A9&"'!$A$12:$Z$19"),MATCH("Points (Auto-generate)",INDIRECT("'"&$A9&"'!$A$12:$Z$12"),0),0)="","?",VLOOKUP(I$1,INDIRECT("'"&$A9&"'!$A$12:$Z$19"),MATCH("Points (Auto-generate)",INDIRECT("'"&$A9&"'!$A$12:$Z$12"),0),0)),"ER")) -> NA | J9: =IF($F9=0,"NA",IF($A9=INDIRECT("'"&$A9&"'!$B$1"),IF(VLOOKUP(J$1,INDIRECT("'"&$A9&"'!$A$12:$Z$19"),MATCH("Points (Auto-generate)",INDIRECT("'"&$A9&"'!$A$12:$Z$12"),0),0)="","?",VLOOKUP(J$1,INDIRECT("'"&$A9&"'!$A$12:$Z$19"),MATCH("Points (Auto-generate)",INDIRECT("'"&$A9&"'!$A$12:$Z$12"),0),0)),"ER")) -> NA | K9: =IF($F9=0,"NA",IF($A9=INDIRECT("'"&$A9&"'!$B$1"),IF(VLOOKUP(K$1,INDIRECT("'"&$A9&"'!$A$12:$Z$19"),MATCH("Points (Auto-generate)",INDIRECT("'"&$A9&"'!$A$12:$Z$12"),0),0)="","?",VLOOKUP(K$1,INDIRECT("'"&$A9&"'!$A$12:$Z$19"),MATCH("Points (Auto-generate)",INDIRECT("'"&$A9&"'!$A$12:$Z$12"),0),0)),"ER")) -> NA | L9: =IF($F9=0,"NA",IF($A9=INDIRECT("'"&$A9&"'!$B$1"),IF(VLOOKUP(L$1,INDIRECT("'"&$A9&"'!$A$12:$Z$19"),MATCH("Points (Auto-generate)",INDIRECT("'"&$A9&"'!$A$12:$Z$12"),0),0)="","?",VLOOKUP(L$1,INDIRECT("'"&$A9&"'!$A$12:$Z$19"),MATCH("Points (Auto-generate)",INDIRECT("'"&$A9&"'!$A$12:$Z$12"),0),0)),"ER")) -> NA | M9: =IF($F9=0,"NA",IF($A9=INDIRECT("'"&$A9&"'!$B$1"),IF(VLOOKUP(M$1,INDIRECT("'"&$A9&"'!$A$12:$Z$19"),MATCH("Points (Auto-generate)",INDIRECT("'"&$A9&"'!$A$12:$Z$12"),0),0)="","?",VLOOKUP(M$1,INDIRECT("'"&$A9&"'!$A$12:$Z$19"),MATCH("Points (Auto-generate)",INDIRECT("'"&$A9&"'!$A$12:$Z$12"),0),0)),"ER")) -> NA
A10: UPD2d | B10: =VLOOKUP($A10,'PARASTATAL Questions'!$A:$J,3,0)&"" -> Urban Planning & Design (UPD) | C10: =VLOOKUP($A10,'PARASTATAL Questions'!$A:$J,4,0)&"" -> SQ | D10: =VLOOKUP($A10,'PARASTATAL Questions'!$A:$J,5,0)&"" -> Where multiple statutory or sectoral plans apply to the same territory, does the transport corporation ensure consistency with the applicable municipal/city plan for the city? | E10: =VLOOKUP($A10,'PARASTATAL Questions'!$A:$J,7,0)&"" -> Implementation | F10: =VLOOKUP($A10,'PARASTATAL Questions'!$A:$J,6,0) -> 2.5 | G10: =IF($F10=0,"NA",IF($A10=INDIRECT("'"&$A10&"'!$B$1"),IF(VLOOKUP(G$1,INDIRECT("'"&$A10&"'!$A$12:$Z$19"),MATCH("Points (Auto-generate)",INDIRECT("'"&$A10&"'!$A$12:$Z$12"),0),0)="","?",VLOOKUP(G$1,INDIRECT("'"&$A10&"'!$A$12:$Z$19"),MATCH("Points (Auto-generate)",INDIRECT("'"&$A10&"'!$A$12:$Z$12"),0),0)),"ER")) -> NA | H10: =IF($F10=0,"NA",IF($A10=INDIRECT("'"&$A10&"'!$B$1"),IF(VLOOKUP(H$1,INDIRECT("'"&$A10&"'!$A$12:$Z$19"),MATCH("Points (Auto-generate)",INDIRECT("'"&$A10&"'!$A$12:$Z$12"),0),0)="","?",VLOOKUP(H$1,INDIRECT("'"&$A10&"'!$A$12:$Z$19"),MATCH("Points (Auto-generate)",INDIRECT("'"&$A10&"'!$A$12:$Z$12"),0),0)),"ER")) -> ? | I10: =IF($F10=0,"NA",IF($A10=INDIRECT("'"&$A10&"'!$B$1"),IF(VLOOKUP(I$1,INDIRECT("'"&$A10&"'!$A$12:$Z$19"),MATCH("Points (Auto-generate)",INDIRECT("'"&$A10&"'!$A$12:$Z$12"),0),0)="","?",VLOOKUP(I$1,INDIRECT("'"&$A10&"'!$A$12:$Z$19"),MATCH("Points (Auto-generate)",INDIRECT("'"&$A10&"'!$A$12:$Z$12"),0),0)),"ER")) -> NA | J10: =IF($F10=0,"NA",IF($A10=INDIRECT("'"&$A10&"'!$B$1"),IF(VLOOKUP(J$1,INDIRECT("'"&$A10&"'!$A$12:$Z$19"),MATCH("Points (Auto-generate)",INDIRECT("'"&$A10&"'!$A$12:$Z$12"),0),0)="","?",VLOOKUP(J$1,INDIRECT("'"&$A10&"'!$A$12:$Z$19"),MATCH("Points (Auto-generate)",INDIRECT("'"&$A10&"'!$A$12:$Z$12"),0),0)),"ER")) -> NA | K10: =IF($F10=0,"NA",IF($A10=INDIRECT("'"&$A10&"'!$B$1"),IF(VLOOKUP(K$1,INDIRECT("'"&$A10&"'!$A$12:$Z$19"),MATCH("Points (Auto-generate)",INDIRECT("'"&$A10&"'!$A$12:$Z$12"),0),0)="","?",VLOOKUP(K$1,INDIRECT("'"&$A10&"'!$A$12:$Z$19"),MATCH("Points (Auto-generate)",INDIRECT("'"&$A10&"'!$A$12:$Z$12"),0),0)),"ER")) -> NA | L10: =IF($F10=0,"NA",IF($A10=INDIRECT("'"&$A10&"'!$B$1"),IF(VLOOKUP(L$1,INDIRECT("'"&$A10&"'!$A$12:$Z$19"),MATCH("Points (Auto-generate)",INDIRECT("'"&$A10&"'!$A$12:$Z$12"),0),0)="","?",VLOOKUP(L$1,INDIRECT("'"&$A10&"'!$A$12:$Z$19"),MATCH("Points (Auto-generate)",INDIRECT("'"&$A10&"'!$A$12:$Z$12"),0),0)),"ER")) -> NA | M10: =IF($F10=0,"NA",IF($A10=INDIRECT("'"&$A10&"'!$B$1"),IF(VLOOKUP(M$1,INDIRECT("'"&$A10&"'!$A$12:$Z$19"),MATCH("Points (Auto-generate)",INDIRECT("'"&$A10&"'!$A$12:$Z$12"),0),0)="","?",VLOOKUP(M$1,INDIRECT("'"&$A10&"'!$A$12:$Z$19"),MATCH("Points (Auto-generate)",INDIRECT("'"&$A10&"'!$A$12:$Z$12"),0),0)),"ER")) -> NA
A11: UPD3 | B11: =VLOOKUP($A11,'PARASTATAL Questions'!$A:$J,3,0)&"" -> Urban Planning & Design (UPD) | C11: =VLOOKUP($A11,'PARASTATAL Questions'!$A:$J,4,0)&"" -> MQ | D11: =VLOOKUP($A11,'PARASTATAL Questions'!$A:$J,5,0)&"" -> Are the needs of women and the urban poor explicitly considered in the water board’s planning, service delivery or major investment decisions? | E11: =VLOOKUP($A11,'PARASTATAL Questions'!$A:$J,7,0)&"" -> Law/Policy + Implementation | F11: =VLOOKUP($A11,'PARASTATAL Questions'!$A:$J,6,0) -> 10 | G11: =IF(OR(G12="ER",G13="ER"),"ER",IF(OR(G12="?",G13="?"),"?",IF(AND(G12="NA",G13="NA"),"NA",SUM(G12,G13)/((G12<>"NA")*$F$12+(G13<>"NA")*$F$13)*$F11))) -> ? | H11: =IF(OR(H12="ER",H13="ER"),"ER",IF(OR(H12="?",H13="?"),"?",IF(AND(H12="NA",H13="NA"),"NA",SUM(H12,H13)/((H12<>"NA")*$F$12+(H13<>"NA")*$F$13)*$F11))) -> NA | I11: =IF(OR(I12="ER",I13="ER"),"ER",IF(OR(I12="?",I13="?"),"?",IF(AND(I12="NA",I13="NA"),"NA",SUM(I12,I13)/((I12<>"NA")*$F$12+(I13<>"NA")*$F$13)*$F11))) -> NA | J11: =IF(OR(J12="ER",J13="ER"),"ER",IF(OR(J12="?",J13="?"),"?",IF(AND(J12="NA",J13="NA"),"NA",SUM(J12,J13)/((J12<>"NA")*$F$12+(J13<>"NA")*$F$13)*$F11))) -> NA | K11: =IF(OR(K12="ER",K13="ER"),"ER",IF(OR(K12="?",K13="?"),"?",IF(AND(K12="NA",K13="NA"),"NA",SUM(K12,K13)/((K12<>"NA")*$F$12+(K13<>"NA")*$F$13)*$F11))) -> NA | L11: =IF(OR(L12="ER",L13="ER"),"ER",IF(OR(L12="?",L13="?"),"?",IF(AND(L12="NA",L13="NA"),"NA",SUM(L12,L13)/((L12<>"NA")*$F$12+(L13<>"NA")*$F$13)*$F11))) -> NA | M11: =IF(OR(M12="ER",M13="ER"),"ER",IF(OR(M12="?",M13="?"),"?",IF(AND(M12="NA",M13="NA"),"NA",SUM(M12,M13)/((M12<>"NA")*$F$12+(M13<>"NA")*$F$13)*$F11))) -> NA
A12: UPD3a | B12: =VLOOKUP($A12,'PARASTATAL Questions'!$A:$J,3,0)&"" -> Urban Planning & Design (UPD) | C12: =VLOOKUP($A12,'PARASTATAL Questions'!$A:$J,4,0)&"" -> SQ | D12: =VLOOKUP($A12,'PARASTATAL Questions'!$A:$J,5,0)&"" -> Is the water supply board mandated to consider the needs of women and the urban poor in decisions relating to access, affordability and delivery of water and sanitation services? | E12: =VLOOKUP($A12,'PARASTATAL Questions'!$A:$J,7,0)&"" -> Law/Policy | F12: =VLOOKUP($A12,'PARASTATAL Questions'!$A:$J,6,0) -> 5 | G12: =IF($F12=0,"NA",IF($A12=INDIRECT("'"&$A12&"'!$B$1"),IF(VLOOKUP(G$1,INDIRECT("'"&$A12&"'!$A$12:$Z$19"),MATCH("Points (Auto-generate)",INDIRECT("'"&$A12&"'!$A$12:$Z$12"),0),0)="","?",VLOOKUP(G$1,INDIRECT("'"&$A12&"'!$A$12:$Z$19"),MATCH("Points (Auto-generate)",INDIRECT("'"&$A12&"'!$A$12:$Z$12"),0),0)),"ER")) -> ? | H12: =IF($F12=0,"NA",IF($A12=INDIRECT("'"&$A12&"'!$B$1"),IF(VLOOKUP(H$1,INDIRECT("'"&$A12&"'!$A$12:$Z$19"),MATCH("Points (Auto-generate)",INDIRECT("'"&$A12&"'!$A$12:$Z$12"),0),0)="","?",VLOOKUP(H$1,INDIRECT("'"&$A12&"'!$A$12:$Z$19"),MATCH("Points (Auto-generate)",INDIRECT("'"&$A12&"'!$A$12:$Z$12"),0),0)),"ER")) -> NA | I12: =IF($F12=0,"NA",IF($A12=INDIRECT("'"&$A12&"'!$B$1"),IF(VLOOKUP(I$1,INDIRECT("'"&$A12&"'!$A$12:$Z$19"),MATCH("Points (Auto-generate)",INDIRECT("'"&$A12&"'!$A$12:$Z$12"),0),0)="","?",VLOOKUP(I$1,INDIRECT("'"&$A12&"'!$A$12:$Z$19"),MATCH("Points (Auto-generate)",INDIRECT("'"&$A12&"'!$A$12:$Z$12"),0),0)),"ER")) -> NA | J12: =IF($F12=0,"NA",IF($A12=INDIRECT("'"&$A12&"'!$B$1"),IF(VLOOKUP(J$1,INDIRECT("'"&$A12&"'!$A$12:$Z$19"),MATCH("Points (Auto-generate)",INDIRECT("'"&$A12&"'!$A$12:$Z$12"),0),0)="","?",VLOOKUP(J$1,INDIRECT("'"&$A12&"'!$A$12:$Z$19"),MATCH("Points (Auto-generate)",INDIRECT("'"&$A12&"'!$A$12:$Z$12"),0),0)),"ER")) -> NA | K12: =IF($F12=0,"NA",IF($A12=INDIRECT("'"&$A12&"'!$B$1"),IF(VLOOKUP(K$1,INDIRECT("'"&$A12&"'!$A$12:$Z$19"),MATCH("Points (Auto-generate)",INDIRECT("'"&$A12&"'!$A$12:$Z$12"),0),0)="","?",VLOOKUP(K$1,INDIRECT("'"&$A12&"'!$A$12:$Z$19"),MATCH("Points (Auto-generate)",INDIRECT("'"&$A12&"'!$A$12:$Z$12"),0),0)),"ER")) -> NA | L12: =IF($F12=0,"NA",IF($A12=INDIRECT("'"&$A12&"'!$B$1"),IF(VLOOKUP(L$1,INDIRECT("'"&$A12&"'!$A$12:$Z$19"),MATCH("Points (Auto-generate)",INDIRECT("'"&$A12&"'!$A$12:$Z$12"),0),0)="","?",VLOOKUP(L$1,INDIRECT("'"&$A12&"'!$A$12:$Z$19"),MATCH("Points (Auto-generate)",INDIRECT("'"&$A12&"'!$A$12:$Z$12"),0),0)),"ER")) -> NA | M12: =IF($F12=0,"NA",IF($A12=INDIRECT("'"&$A12&"'!$B$1"),IF(VLOOKUP(M$1,INDIRECT("'"&$A12&"'!$A$12:$Z$19"),MATCH("Points (Auto-generate)",INDIRECT("'"&$A12&"'!$A$12:$Z$12"),0),0)="","?",VLOOKUP(M$1,INDIRECT("'"&$A12&"'!$A$12:$Z$19"),MATCH("Points (Auto-generate)",INDIRECT("'"&$A12&"'!$A$12:$Z$12"),0),0)),"ER")) -> NA
A13: UPD3b | B13: =VLOOKUP($A13,'PARASTATAL Questions'!$A:$J,3,0)&"" -> Urban Planning & Design (UPD) | C13: =VLOOKUP($A13,'PARASTATAL Questions'!$A:$J,4,0)&"" -> SQ | D13: =VLOOKUP($A13,'PARASTATAL Questions'!$A:$J,5,0)&"" -> Does the water supply board actually consider the needs of women and the urban poor in decisions relating to access, affordability and delivery of water and sanitation services? | E13: =VLOOKUP($A13,'PARASTATAL Questions'!$A:$J,7,0)&"" -> Implementation | F13: =VLOOKUP($A13,'PARASTATAL Questions'!$A:$J,6,0) -> 5 | G13: =IF($F13=0,"NA",IF($A13=INDIRECT("'"&$A13&"'!$B$1"),IF(VLOOKUP(G$1,INDIRECT("'"&$A13&"'!$A$12:$Z$19"),MATCH("Points (Auto-generate)",INDIRECT("'"&$A13&"'!$A$12:$Z$12"),0),0)="","?",VLOOKUP(G$1,INDIRECT("'"&$A13&"'!$A$12:$Z$19"),MATCH("Points (Auto-generate)",INDIRECT("'"&$A13&"'!$A$12:$Z$12"),0),0)),"ER")) -> 1.25 | H13: =IF($F13=0,"NA",IF($A13=INDIRECT("'"&$A13&"'!$B$1"),IF(VLOOKUP(H$1,INDIRECT("'"&$A13&"'!$A$12:$Z$19"),MATCH("Points (Auto-generate)",INDIRECT("'"&$A13&"'!$A$12:$Z$12"),0),0)="","?",VLOOKUP(H$1,INDIRECT("'"&$A13&"'!$A$12:$Z$19"),MATCH("Points (Auto-generate)",INDIRECT("'"&$A13&"'!$A$12:$Z$12"),0),0)),"ER")) -> NA | I13: =IF($F13=0,"NA",IF($A13=INDIRECT("'"&$A13&"'!$B$1"),IF(VLOOKUP(I$1,INDIRECT("'"&$A13&"'!$A$12:$Z$19"),MATCH("Points (Auto-generate)",INDIRECT("'"&$A13&"'!$A$12:$Z$12"),0),0)="","?",VLOOKUP(I$1,INDIRECT("'"&$A13&"'!$A$12:$Z$19"),MATCH("Points (Auto-generate)",INDIRECT("'"&$A13&"'!$A$12:$Z$12"),0),0)),"ER")) -> NA | J13: =IF($F13=0,"NA",IF($A13=INDIRECT("'"&$A13&"'!$B$1"),IF(VLOOKUP(J$1,INDIRECT("'"&$A13&"'!$A$12:$Z$19"),MATCH("Points (Auto-generate)",INDIRECT("'"&$A13&"'!$A$12:$Z$12"),0),0)="","?",VLOOKUP(J$1,INDIRECT("'"&$A13&"'!$A$12:$Z$19"),MATCH("Points (Auto-generate)",INDIRECT("'"&$A13&"'!$A$12:$Z$12"),0),0)),"ER")) -> NA | K13: =IF($F13=0,"NA",IF($A13=INDIRECT("'"&$A13&"'!$B$1"),IF(VLOOKUP(K$1,INDIRECT("'"&$A13&"'!$A$12:$Z$19"),MATCH("Points (Auto-generate)",INDIRECT("'"&$A13&"'!$A$12:$Z$12"),0),0)="","?",VLOOKUP(K$1,INDIRECT("'"&$A13&"'!$A$12:$Z$19"),MATCH("Points (Auto-generate)",INDIRECT("'"&$A13&"'!$A$12:$Z$12"),0),0)),"ER")) -> NA | L13: =IF($F13=0,"NA",IF($A13=INDIRECT("'"&$A13&"'!$B$1"),IF(VLOOKUP(L$1,INDIRECT("'"&$A13&"'!$A$12:$Z$19"),MATCH("Points (Auto-generate)",INDIRECT("'"&$A13&"'!$A$12:$Z$12"),0),0)="","?",VLOOKUP(L$1,INDIRECT("'"&$A13&"'!$A$12:$Z$19"),MATCH("Points (Auto-generate)",INDIRECT("'"&$A13&"'!$A$12:$Z$12"),0),0)),"ER")) -> NA | M13: =IF($F13=0,"NA",IF($A13=INDIRECT("'"&$A13&"'!$B$1"),IF(VLOOKUP(M$1,INDIRECT("'"&$A13&"'!$A$12:$Z$19"),MATCH("Points (Auto-generate)",INDIRECT("'"&$A13&"'!$A$12:$Z$12"),0),0)="","?",VLOOKUP(M$1,INDIRECT("'"&$A13&"'!$A$12:$Z$19"),MATCH("Points (Auto-generate)",INDIRECT("'"&$A13&"'!$A$12:$Z$12"),0),0)),"ER")) -> NA
A14: UPD4 | B14: =VLOOKUP($A14,'PARASTATAL Questions'!$A:$J,3,0)&"" -> Urban Planning & Design (UPD) | C14: =VLOOKUP($A14,'PARASTATAL Questions'!$A:$J,4,0)&"" -> MQ | D14: =VLOOKUP($A14,'PARASTATAL Questions'!$A:$J,5,0)&"" -> Are the needs of women and the urban poor explicitly considered in the transport Corporation’s planning, service delivery or major investment decisions? | E14: =VLOOKUP($A14,'PARASTATAL Questions'!$A:$J,7,0)&"" -> Law/Policy + Implementation | F14: =VLOOKUP($A14,'PARASTATAL Questions'!$A:$J,6,0) -> 10 | G14: =IF(OR(G15="ER",G16="ER"),"ER",IF(OR(G15="?",G16="?"),"?",IF(AND(G15="NA",G16="NA"),"NA",SUM(G15,G16)/((G15<>"NA")*$F$15+(G16<>"NA")*$F$16)*$F14))) -> NA | H14: =IF(OR(H15="ER",H16="ER"),"ER",IF(OR(H15="?",H16="?"),"?",IF(AND(H15="NA",H16="NA"),"NA",SUM(H15,H16)/((H15<>"NA")*$F$15+(H16<>"NA")*$F$16)*$F14))) -> ? | I14: =IF(OR(I15="ER",I16="ER"),"ER",IF(OR(I15="?",I16="?"),"?",IF(AND(I15="NA",I16="NA"),"NA",SUM(I15,I16)/((I15<>"NA")*$F$15+(I16<>"NA")*$F$16)*$F14))) -> NA | J14: =IF(OR(J15="ER",J16="ER"),"ER",IF(OR(J15="?",J16="?"),"?",IF(AND(J15="NA",J16="NA"),"NA",SUM(J15,J16)/((J15<>"NA")*$F$15+(J16<>"NA")*$F$16)*$F14))) -> NA | K14: =IF(OR(K15="ER",K16="ER"),"ER",IF(OR(K15="?",K16="?"),"?",IF(AND(K15="NA",K16="NA"),"NA",SUM(K15,K16)/((K15<>"NA")*$F$15+(K16<>"NA")*$F$16)*$F14))) -> NA | L14: =IF(OR(L15="ER",L16="ER"),"ER",IF(OR(L15="?",L16="?"),"?",IF(AND(L15="NA",L16="NA"),"NA",SUM(L15,L16)/((L15<>"NA")*$F$15+(L16<>"NA")*$F$16)*$F14))) -> NA | M14: =IF(OR(M15="ER",M16="ER"),"ER",IF(OR(M15="?",M16="?"),"?",IF(AND(M15="NA",M16="NA"),"NA",SUM(M15,M16)/((M15<>"NA")*$F$15+(M16<>"NA")*$F$16)*$F14))) -> NA
A15: UPD4a | B15: =VLOOKUP($A15,'PARASTATAL Questions'!$A:$J,3,0)&"" -> Urban Planning & Design (UPD) | C15: =VLOOKUP($A15,'PARASTATAL Questions'!$A:$J,4,0)&"" -> SQ | D15: =VLOOKUP($A15,'PARASTATAL Questions'!$A:$J,5,0)&"" -> Is the transport corporation mandated to consider the mobility needs of women and the urban poor in planning and delivering public transport services? | E15: =VLOOKUP($A15,'PARASTATAL Questions'!$A:$J,7,0)&"" -> Law/Policy | F15: =VLOOKUP($A15,'PARASTATAL Questions'!$A:$J,6,0) -> 5 | G15: =IF($F15=0,"NA",IF($A15=INDIRECT("'"&$A15&"'!$B$1"),IF(VLOOKUP(G$1,INDIRECT("'"&$A15&"'!$A$12:$Z$19"),MATCH("Points (Auto-generate)",INDIRECT("'"&$A15&"'!$A$12:$Z$12"),0),0)="","?",VLOOKUP(G$1,INDIRECT("'"&$A15&"'!$A$12:$Z$19"),MATCH("Points (Auto-generate)",INDIRECT("'"&$A15&"'!$A$12:$Z$12"),0),0)),"ER")) -> NA | H15: =IF($F15=0,"NA",IF($A15=INDIRECT("'"&$A15&"'!$B$1"),IF(VLOOKUP(H$1,INDIRECT("'"&$A15&"'!$A$12:$Z$19"),MATCH("Points (Auto-generate)",INDIRECT("'"&$A15&"'!$A$12:$Z$12"),0),0)="","?",VLOOKUP(H$1,INDIRECT("'"&$A15&"'!$A$12:$Z$19"),MATCH("Points (Auto-generate)",INDIRECT("'"&$A15&"'!$A$12:$Z$12"),0),0)),"ER")) -> 0 | I15: =IF($F15=0,"NA",IF($A15=INDIRECT("'"&$A15&"'!$B$1"),IF(VLOOKUP(I$1,INDIRECT("'"&$A15&"'!$A$12:$Z$19"),MATCH("Points (Auto-generate)",INDIRECT("'"&$A15&"'!$A$12:$Z$12"),0),0)="","?",VLOOKUP(I$1,INDIRECT("'"&$A15&"'!$A$12:$Z$19"),MATCH("Points (Auto-generate)",INDIRECT("'"&$A15&"'!$A$12:$Z$12"),0),0)),"ER")) -> NA | J15: =IF($F15=0,"NA",IF($A15=INDIRECT("'"&$A15&"'!$B$1"),IF(VLOOKUP(J$1,INDIRECT("'"&$A15&"'!$A$12:$Z$19"),MATCH("Points (Auto-generate)",INDIRECT("'"&$A15&"'!$A$12:$Z$12"),0),0)="","?",VLOOKUP(J$1,INDIRECT("'"&$A15&"'!$A$12:$Z$19"),MATCH("Points (Auto-generate)",INDIRECT("'"&$A15&"'!$A$12:$Z$12"),0),0)),"ER")) -> NA | K15: =IF($F15=0,"NA",IF($A15=INDIRECT("'"&$A15&"'!$B$1"),IF(VLOOKUP(K$1,INDIRECT("'"&$A15&"'!$A$12:$Z$19"),MATCH("Points (Auto-generate)",INDIRECT("'"&$A15&"'!$A$12:$Z$12"),0),0)="","?",VLOOKUP(K$1,INDIRECT("'"&$A15&"'!$A$12:$Z$19"),MATCH("Points (Auto-generate)",INDIRECT("'"&$A15&"'!$A$12:$Z$12"),0),0)),"ER")) -> NA | L15: =IF($F15=0,"NA",IF($A15=INDIRECT("'"&$A15&"'!$B$1"),IF(VLOOKUP(L$1,INDIRECT("'"&$A15&"'!$A$12:$Z$19"),MATCH("Points (Auto-generate)",INDIRECT("'"&$A15&"'!$A$12:$Z$12"),0),0)="","?",VLOOKUP(L$1,INDIRECT("'"&$A15&"'!$A$12:$Z$19"),MATCH("Points (Auto-generate)",INDIRECT("'"&$A15&"'!$A$12:$Z$12"),0),0)),"ER")) -> NA | M15: =IF($F15=0,"NA",IF($A15=INDIRECT("'"&$A15&"'!$B$1"),IF(VLOOKUP(M$1,INDIRECT("'"&$A15&"'!$A$12:$Z$19"),MATCH("Points (Auto-generate)",INDIRECT("'"&$A15&"'!$A$12:$Z$12"),0),0)="","?",VLOOKUP(M$1,INDIRECT("'"&$A15&"'!$A$12:$Z$19"),MATCH("Points (Auto-generate)",INDIRECT("'"&$A15&"'!$A$12:$Z$12"),0),0)),"ER")) -> NA
A16: UPD4b | B16: =VLOOKUP($A16,'PARASTATAL Questions'!$A:$J,3,0)&"" -> Urban Planning & Design (UPD) | C16: =VLOOKUP($A16,'PARASTATAL Questions'!$A:$J,4,0)&"" -> SQ | D16: =VLOOKUP($A16,'PARASTATAL Questions'!$A:$J,5,0)&"" -> Does the Transport Corporation actually consider the needs of women and the urban poor in decisions relating to access, affordability and delivery of public transport services? | E16: =VLOOKUP($A16,'PARASTATAL Questions'!$A:$J,7,0)&"" -> Implementation | F16: =VLOOKUP($A16,'PARASTATAL Questions'!$A:$J,6,0) -> 5 | G16: =IF($F16=0,"NA",IF($A16=INDIRECT("'"&$A16&"'!$B$1"),IF(VLOOKUP(G$1,INDIRECT("'"&$A16&"'!$A$12:$Z$19"),MATCH("Points (Auto-generate)",INDIRECT("'"&$A16&"'!$A$12:$Z$12"),0),0)="","?",VLOOKUP(G$1,INDIRECT("'"&$A16&"'!$A$12:$Z$19"),MATCH("Points (Auto-generate)",INDIRECT("'"&$A16&"'!$A$12:$Z$12"),0),0)),"ER")) -> NA | H16: =IF($F16=0,"NA",IF($A16=INDIRECT("'"&$A16&"'!$B$1"),IF(VLOOKUP(H$1,INDIRECT("'"&$A16&"'!$A$12:$Z$19"),MATCH("Points (Auto-generate)",INDIRECT("'"&$A16&"'!$A$12:$Z$12"),0),0)="","?",VLOOKUP(H$1,INDIRECT("'"&$A16&"'!$A$12:$Z$19"),MATCH("Points (Auto-generate)",INDIRECT("'"&$A16&"'!$A$12:$Z$12"),0),0)),"ER")) -> ? | I16: =IF($F16=0,"NA",IF($A16=INDIRECT("'"&$A16&"'!$B$1"),IF(VLOOKUP(I$1,INDIRECT("'"&$A16&"'!$A$12:$Z$19"),MATCH("Points (Auto-generate)",INDIRECT("'"&$A16&"'!$A$12:$Z$12"),0),0)="","?",VLOOKUP(I$1,INDIRECT("'"&$A16&"'!$A$12:$Z$19"),MATCH("Points (Auto-generate)",INDIRECT("'"&$A16&"'!$A$12:$Z$12"),0),0)),"ER")) -> NA | J16: =IF($F16=0,"NA",IF($A16=INDIRECT("'"&$A16&"'!$B$1"),IF(VLOOKUP(J$1,INDIRECT("'"&$A16&"'!$A$12:$Z$19"),MATCH("Points (Auto-generate)",INDIRECT("'"&$A16&"'!$A$12:$Z$12"),0),0)="","?",VLOOKUP(J$1,INDIRECT("'"&$A16&"'!$A$12:$Z$19"),MATCH("Points (Auto-generate)",INDIRECT("'"&$A16&"'!$A$12:$Z$12"),0),0)),"ER")) -> NA | K16: =IF($F16=0,"NA",IF($A16=INDIRECT("'"&$A16&"'!$B$1"),IF(VLOOKUP(K$1,INDIRECT("'"&$A16&"'!$A$12:$Z$19"),MATCH("Points (Auto-generate)",INDIRECT("'"&$A16&"'!$A$12:$Z$12"),0),0)="","?",VLOOKUP(K$1,INDIRECT("'"&$A16&"'!$A$12:$Z$19"),MATCH("Points (Auto-generate)",INDIRECT("'"&$A16&"'!$A$12:$Z$12"),0),0)),"ER")) -> NA | L16: =IF($F16=0,"NA",IF($A16=INDIRECT("'"&$A16&"'!$B$1"),IF(VLOOKUP(L$1,INDIRECT("'"&$A16&"'!$A$12:$Z$19"),MATCH("Points (Auto-generate)",INDIRECT("'"&$A16&"'!$A$12:$Z$12"),0),0)="","?",VLOOKUP(L$1,INDIRECT("'"&$A16&"'!$A$12:$Z$19"),MATCH("Points (Auto-generate)",INDIRECT("'"&$A16&"'!$A$12:$Z$12"),0),0)),"ER")) -> NA | M16: =IF($F16=0,"NA",IF($A16=INDIRECT("'"&$A16&"'!$B$1"),IF(VLOOKUP(M$1,INDIRECT("'"&$A16&"'!$A$12:$Z$19"),MATCH("Points (Auto-generate)",INDIRECT("'"&$A16&"'!$A$12:$Z$12"),0),0)="","?",VLOOKUP(M$1,INDIRECT("'"&$A16&"'!$A$12:$Z$19"),MATCH("Points (Auto-generate)",INDIRECT("'"&$A16&"'!$A$12:$Z$12"),0),0)),"ER")) -> NA
A17: UPD5 | B17: =VLOOKUP($A17,'PARASTATAL Questions'!$A:$J,3,0)&"" -> Urban Planning & Design (UPD) | C17: =VLOOKUP($A17,'PARASTATAL Questions'!$A:$J,4,0)&"" -> MQ | D17: =VLOOKUP($A17,'PARASTATAL Questions'!$A:$J,5,0)&"" -> Are environmental considerations explicitly required to be integrated into the water supply board’s planning, service-delivery or major investment decisions? | E17: =VLOOKUP($A17,'PARASTATAL Questions'!$A:$J,7,0)&"" -> Law/Policy + Implementation | F17: =VLOOKUP($A17,'PARASTATAL Questions'!$A:$J,6,0) -> 10 | G17: =IF(OR(G18="ER",G19="ER"),"ER",IF(OR(G18="?",G19="?"),"?",IF(AND(G18="NA",G19="NA"),"NA",SUM(G18,G19)/((G18<>"NA")*$F$18+(G19<>"NA")*$F$19)*$F17))) -> 7.5 | H17: =IF(OR(H18="ER",H19="ER"),"ER",IF(OR(H18="?",H19="?"),"?",IF(AND(H18="NA",H19="NA"),"NA",SUM(H18,H19)/((H18<>"NA")*$F$18+(H19<>"NA")*$F$19)*$F17))) -> NA | I17: =IF(OR(I18="ER",I19="ER"),"ER",IF(OR(I18="?",I19="?"),"?",IF(AND(I18="NA",I19="NA"),"NA",SUM(I18,I19)/((I18<>"NA")*$F$18+(I19<>"NA")*$F$19)*$F17))) -> NA | J17: =IF(OR(J18="ER",J19="ER"),"ER",IF(OR(J18="?",J19="?"),"?",IF(AND(J18="NA",J19="NA"),"NA",SUM(J18,J19)/((J18<>"NA")*$F$18+(J19<>"NA")*$F$19)*$F17))) -> NA | K17: =IF(OR(K18="ER",K19="ER"),"ER",IF(OR(K18="?",K19="?"),"?",IF(AND(K18="NA",K19="NA"),"NA",SUM(K18,K19)/((K18<>"NA")*$F$18+(K19<>"NA")*$F$19)*$F17))) -> NA | L17: =IF(OR(L18="ER",L19="ER"),"ER",IF(OR(L18="?",L19="?"),"?",IF(AND(L18="NA",L19="NA"),"NA",SUM(L18,L19)/((L18<>"NA")*$F$18+(L19<>"NA")*$F$19)*$F17))) -> NA | M17: =IF(OR(M18="ER",M19="ER"),"ER",IF(OR(M18="?",M19="?"),"?",IF(AND(M18="NA",M19="NA"),"NA",SUM(M18,M19)/((M18<>"NA")*$F$18+(M19<>"NA")*$F$19)*$F17))) -> NA
A18: UPD5a | B18: =VLOOKUP($A18,'PARASTATAL Questions'!$A:$J,3,0)&"" -> Urban Planning & Design (UPD) | C18: =VLOOKUP($A18,'PARASTATAL Questions'!$A:$J,4,0)&"" -> SQ | D18: =VLOOKUP($A18,'PARASTATAL Questions'!$A:$J,5,0)&"" -> Is the water supply board mandated to consider environmental sustainability in planning and delivering water and sanitation services? | E18: =VLOOKUP($A18,'PARASTATAL Questions'!$A:$J,7,0)&"" -> Law/Policy | F18: =VLOOKUP($A18,'PARASTATAL Questions'!$A:$J,6,0) -> 5 | G18: =IF($F18=0,"NA",IF($A18=INDIRECT("'"&$A18&"'!$B$1"),IF(VLOOKUP(G$1,INDIRECT("'"&$A18&"'!$A$12:$Z$19"),MATCH("Points (Auto-generate)",INDIRECT("'"&$A18&"'!$A$12:$Z$12"),0),0)="","?",VLOOKUP(G$1,INDIRECT("'"&$A18&"'!$A$12:$Z$19"),MATCH("Points (Auto-generate)",INDIRECT("'"&$A18&"'!$A$12:$Z$12"),0),0)),"ER")) -> 2.5 | H18: =IF($F18=0,"NA",IF($A18=INDIRECT("'"&$A18&"'!$B$1"),IF(VLOOKUP(H$1,INDIRECT("'"&$A18&"'!$A$12:$Z$19"),MATCH("Points (Auto-generate)",INDIRECT("'"&$A18&"'!$A$12:$Z$12"),0),0)="","?",VLOOKUP(H$1,INDIRECT("'"&$A18&"'!$A$12:$Z$19"),MATCH("Points (Auto-generate)",INDIRECT("'"&$A18&"'!$A$12:$Z$12"),0),0)),"ER")) -> NA | I18: =IF($F18=0,"NA",IF($A18=INDIRECT("'"&$A18&"'!$B$1"),IF(VLOOKUP(I$1,INDIRECT("'"&$A18&"'!$A$12:$Z$19"),MATCH("Points (Auto-generate)",INDIRECT("'"&$A18&"'!$A$12:$Z$12"),0),0)="","?",VLOOKUP(I$1,INDIRECT("'"&$A18&"'!$A$12:$Z$19"),MATCH("Points (Auto-generate)",INDIRECT("'"&$A18&"'!$A$12:$Z$12"),0),0)),"ER")) -> NA | J18: =IF($F18=0,"NA",IF($A18=INDIRECT("'"&$A18&"'!$B$1"),IF(VLOOKUP(J$1,INDIRECT("'"&$A18&"'!$A$12:$Z$19"),MATCH("Points (Auto-generate)",INDIRECT("'"&$A18&"'!$A$12:$Z$12"),0),0)="","?",VLOOKUP(J$1,INDIRECT("'"&$A18&"'!$A$12:$Z$19"),MATCH("Points (Auto-generate)",INDIRECT("'"&$A18&"'!$A$12:$Z$12"),0),0)),"ER")) -> NA | K18: =IF($F18=0,"NA",IF($A18=INDIRECT("'"&$A18&"'!$B$1"),IF(VLOOKUP(K$1,INDIRECT("'"&$A18&"'!$A$12:$Z$19"),MATCH("Points (Auto-generate)",INDIRECT("'"&$A18&"'!$A$12:$Z$12"),0),0)="","?",VLOOKUP(K$1,INDIRECT("'"&$A18&"'!$A$12:$Z$19"),MATCH("Points (Auto-generate)",INDIRECT("'"&$A18&"'!$A$12:$Z$12"),0),0)),"ER")) -> NA | L18: =IF($F18=0,"NA",IF($A18=INDIRECT("'"&$A18&"'!$B$1"),IF(VLOOKUP(L$1,INDIRECT("'"&$A18&"'!$A$12:$Z$19"),MATCH("Points (Auto-generate)",INDIRECT("'"&$A18&"'!$A$12:$Z$12"),0),0)="","?",VLOOKUP(L$1,INDIRECT("'"&$A18&"'!$A$12:$Z$19"),MATCH("Points (Auto-generate)",INDIRECT("'"&$A18&"'!$A$12:$Z$12"),0),0)),"ER")) -> NA | M18: =IF($F18=0,"NA",IF($A18=INDIRECT("'"&$A18&"'!$B$1"),IF(VLOOKUP(M$1,INDIRECT("'"&$A18&"'!$A$12:$Z$19"),MATCH("Points (Auto-generate)",INDIRECT("'"&$A18&"'!$A$12:$Z$12"),0),0)="","?",VLOOKUP(M$1,INDIRECT("'"&$A18&"'!$A$12:$Z$19"),MATCH("Points (Auto-generate)",INDIRECT("'"&$A18&"'!$A$12:$Z$12"),0),0)),"ER")) -> NA
A19: UPD5b | B19: =VLOOKUP($A19,'PARASTATAL Questions'!$A:$J,3,0)&"" -> Urban Planning & Design (UPD) | C19: =VLOOKUP($A19,'PARASTATAL Questions'!$A:$J,4,0)&"" -> SQ | D19: =VLOOKUP($A19,'PARASTATAL Questions'!$A:$J,5,0)&"" -> Does the water supply board actually consider environmental sustainability in planning and delivering water and sanitation services? | E19: =VLOOKUP($A19,'PARASTATAL Questions'!$A:$J,7,0)&"" -> Implementation | F19: =VLOOKUP($A19,'PARASTATAL Questions'!$A:$J,6,0) -> 5 | G19: =IF($F19=0,"NA",IF($A19=INDIRECT("'"&$A19&"'!$B$1"),IF(VLOOKUP(G$1,INDIRECT("'"&$A19&"'!$A$12:$Z$19"),MATCH("Points (Auto-generate)",INDIRECT("'"&$A19&"'!$A$12:$Z$12"),0),0)="","?",VLOOKUP(G$1,INDIRECT("'"&$A19&"'!$A$12:$Z$19"),MATCH("Points (Auto-generate)",INDIRECT("'"&$A19&"'!$A$12:$Z$12"),0),0)),"ER")) -> 5 | H19: =IF($F19=0,"NA",IF($A19=INDIRECT("'"&$A19&"'!$B$1"),IF(VLOOKUP(H$1,INDIRECT("'"&$A19&"'!$A$12:$Z$19"),MATCH("Points (Auto-generate)",INDIRECT("'"&$A19&"'!$A$12:$Z$12"),0),0)="","?",VLOOKUP(H$1,INDIRECT("'"&$A19&"'!$A$12:$Z$19"),MATCH("Points (Auto-generate)",INDIRECT("'"&$A19&"'!$A$12:$Z$12"),0),0)),"ER")) -> NA | I19: =IF($F19=0,"NA",IF($A19=INDIRECT("'"&$A19&"'!$B$1"),IF(VLOOKUP(I$1,INDIRECT("'"&$A19&"'!$A$12:$Z$19"),MATCH("Points (Auto-generate)",INDIRECT("'"&$A19&"'!$A$12:$Z$12"),0),0)="","?",VLOOKUP(I$1,INDIRECT("'"&$A19&"'!$A$12:$Z$19"),MATCH("Points (Auto-generate)",INDIRECT("'"&$A19&"'!$A$12:$Z$12"),0),0)),"ER")) -> NA | J19: =IF($F19=0,"NA",IF($A19=INDIRECT("'"&$A19&"'!$B$1"),IF(VLOOKUP(J$1,INDIRECT("'"&$A19&"'!$A$12:$Z$19"),MATCH("Points (Auto-generate)",INDIRECT("'"&$A19&"'!$A$12:$Z$12"),0),0)="","?",VLOOKUP(J$1,INDIRECT("'"&$A19&"'!$A$12:$Z$19"),MATCH("Points (Auto-generate)",INDIRECT("'"&$A19&"'!$A$12:$Z$12"),0),0)),"ER")) -> NA | K19: =IF($F19=0,"NA",IF($A19=INDIRECT("'"&$A19&"'!$B$1"),IF(VLOOKUP(K$1,INDIRECT("'"&$A19&"'!$A$12:$Z$19"),MATCH("Points (Auto-generate)",INDIRECT("'"&$A19&"'!$A$12:$Z$12"),0),0)="","?",VLOOKUP(K$1,INDIRECT("'"&$A19&"'!$A$12:$Z$19"),MATCH("Points (Auto-generate)",INDIRECT("'"&$A19&"'!$A$12:$Z$12"),0),0)),"ER")) -> NA | L19: =IF($F19=0,"NA",IF($A19=INDIRECT("'"&$A19&"'!$B$1"),IF(VLOOKUP(L$1,INDIRECT("'"&$A19&"'!$A$12:$Z$19"),MATCH("Points (Auto-generate)",INDIRECT("'"&$A19&"'!$A$12:$Z$12"),0),0)="","?",VLOOKUP(L$1,INDIRECT("'"&$A19&"'!$A$12:$Z$19"),MATCH("Points (Auto-generate)",INDIRECT("'"&$A19&"'!$A$12:$Z$12"),0),0)),"ER")) -> NA | M19: =IF($F19=0,"NA",IF($A19=INDIRECT("'"&$A19&"'!$B$1"),IF(VLOOKUP(M$1,INDIRECT("'"&$A19&"'!$A$12:$Z$19"),MATCH("Points (Auto-generate)",INDIRECT("'"&$A19&"'!$A$12:$Z$12"),0),0)="","?",VLOOKUP(M$1,INDIRECT("'"&$A19&"'!$A$12:$Z$19"),MATCH("Points (Auto-generate)",INDIRECT("'"&$A19&"'!$A$12:$Z$12"),0),0)),"ER")) -> NA
A20: UPD6 | B20: =VLOOKUP($A20,'PARASTATAL Questions'!$A:$J,3,0)&"" -> Urban Planning & Design (UPD) | C20: =VLOOKUP($A20,'PARASTATAL Questions'!$A:$J,4,0)&"" -> MQ | D20: =VLOOKUP($A20,'PARASTATAL Questions'!$A:$J,5,0)&"" -> Are environmental considerations explicitly required to be integrated into the transport corporation’s planning, service-delivery or major investment decisions? | E20: =VLOOKUP($A20,'PARASTATAL Questions'!$A:$J,7,0)&"" -> Law/Policy + Implementation | F20: =VLOOKUP($A20,'PARASTATAL Questions'!$A:$J,6,0) -> 10 | G20: =IF(OR(G21="ER",G22="ER"),"ER",IF(OR(G21="?",G22="?"),"?",IF(AND(G21="NA",G22="NA"),"NA",SUM(G21,G22)/((G21<>"NA")*$F$21+(G22<>"NA")*$F$22)*$F20))) -> NA | H20: =IF(OR(H21="ER",H22="ER"),"ER",IF(OR(H21="?",H22="?"),"?",IF(AND(H21="NA",H22="NA"),"NA",SUM(H21,H22)/((H21<>"NA")*$F$21+(H22<>"NA")*$F$22)*$F20))) -> ? | I20: =IF(OR(I21="ER",I22="ER"),"ER",IF(OR(I21="?",I22="?"),"?",IF(AND(I21="NA",I22="NA"),"NA",SUM(I21,I22)/((I21<>"NA")*$F$21+(I22<>"NA")*$F$22)*$F20))) -> NA | J20: =IF(OR(J21="ER",J22="ER"),"ER",IF(OR(J21="?",J22="?"),"?",IF(AND(J21="NA",J22="NA"),"NA",SUM(J21,J22)/((J21<>"NA")*$F$21+(J22<>"NA")*$F$22)*$F20))) -> NA | K20: =IF(OR(K21="ER",K22="ER"),"ER",IF(OR(K21="?",K22="?"),"?",IF(AND(K21="NA",K22="NA"),"NA",SUM(K21,K22)/((K21<>"NA")*$F$21+(K22<>"NA")*$F$22)*$F20))) -> NA | L20: =IF(OR(L21="ER",L22="ER"),"ER",IF(OR(L21="?",L22="?"),"?",IF(AND(L21="NA",L22="NA"),"NA",SUM(L21,L22)/((L21<>"NA")*$F$21+(L22<>"NA")*$F$22)*$F20))) -> NA | M20: =IF(OR(M21="ER",M22="ER"),"ER",IF(OR(M21="?",M22="?"),"?",IF(AND(M21="NA",M22="NA"),"NA",SUM(M21,M22)/((M21<>"NA")*$F$21+(M22<>"NA")*$F$22)*$F20))) -> NA
A21: UPD6a | B21: =VLOOKUP($A21,'PARASTATAL Questions'!$A:$J,3,0)&"" -> Urban Planning & Design (UPD) | C21: =VLOOKUP($A21,'PARASTATAL Questions'!$A:$J,4,0)&"" -> SQ | D21: =VLOOKUP($A21,'PARASTATAL Questions'!$A:$J,5,0)&"" -> Is the transport corporation mandated to consider environmental sustainability in planning and delivering urban transport services and investments? | E21: =VLOOKUP($A21,'PARASTATAL Questions'!$A:$J,7,0)&"" -> Law/Policy | F21: =VLOOKUP($A21,'PARASTATAL Questions'!$A:$J,6,0) -> 5 | G21: =IF($F21=0,"NA",IF($A21=INDIRECT("'"&$A21&"'!$B$1"),IF(VLOOKUP(G$1,INDIRECT("'"&$A21&"'!$A$12:$Z$19"),MATCH("Points (Auto-generate)",INDIRECT("'"&$A21&"'!$A$12:$Z$12"),0),0)="","?",VLOOKUP(G$1,INDIRECT("'"&$A21&"'!$A$12:$Z$19"),MATCH("Points (Auto-generate)",INDIRECT("'"&$A21&"'!$A$12:$Z$12"),0),0)),"ER")) -> NA | H21: =IF($F21=0,"NA",IF($A21=INDIRECT("'"&$A21&"'!$B$1"),IF(VLOOKUP(H$1,INDIRECT("'"&$A21&"'!$A$12:$Z$19"),MATCH("Points (Auto-generate)",INDIRECT("'"&$A21&"'!$A$12:$Z$12"),0),0)="","?",VLOOKUP(H$1,INDIRECT("'"&$A21&"'!$A$12:$Z$19"),MATCH("Points (Auto-generate)",INDIRECT("'"&$A21&"'!$A$12:$Z$12"),0),0)),"ER")) -> 5 | I21: =IF($F21=0,"NA",IF($A21=INDIRECT("'"&$A21&"'!$B$1"),IF(VLOOKUP(I$1,INDIRECT("'"&$A21&"'!$A$12:$Z$19"),MATCH("Points (Auto-generate)",INDIRECT("'"&$A21&"'!$A$12:$Z$12"),0),0)="","?",VLOOKUP(I$1,INDIRECT("'"&$A21&"'!$A$12:$Z$19"),MATCH("Points (Auto-generate)",INDIRECT("'"&$A21&"'!$A$12:$Z$12"),0),0)),"ER")) -> NA | J21: =IF($F21=0,"NA",IF($A21=INDIRECT("'"&$A21&"'!$B$1"),IF(VLOOKUP(J$1,INDIRECT("'"&$A21&"'!$A$12:$Z$19"),MATCH("Points (Auto-generate)",INDIRECT("'"&$A21&"'!$A$12:$Z$12"),0),0)="","?",VLOOKUP(J$1,INDIRECT("'"&$A21&"'!$A$12:$Z$19"),MATCH("Points (Auto-generate)",INDIRECT("'"&$A21&"'!$A$12:$Z$12"),0),0)),"ER")) -> NA | K21: =IF($F21=0,"NA",IF($A21=INDIRECT("'"&$A21&"'!$B$1"),IF(VLOOKUP(K$1,INDIRECT("'"&$A21&"'!$A$12:$Z$19"),MATCH("Points (Auto-generate)",INDIRECT("'"&$A21&"'!$A$12:$Z$12"),0),0)="","?",VLOOKUP(K$1,INDIRECT("'"&$A21&"'!$A$12:$Z$19"),MATCH("Points (Auto-generate)",INDIRECT("'"&$A21&"'!$A$12:$Z$12"),0),0)),"ER")) -> NA | L21: =IF($F21=0,"NA",IF($A21=INDIRECT("'"&$A21&"'!$B$1"),IF(VLOOKUP(L$1,INDIRECT("'"&$A21&"'!$A$12:$Z$19"),MATCH("Points (Auto-generate)",INDIRECT("'"&$A21&"'!$A$12:$Z$12"),0),0)="","?",VLOOKUP(L$1,INDIRECT("'"&$A21&"'!$A$12:$Z$19"),MATCH("Points (Auto-generate)",INDIRECT("'"&$A21&"'!$A$12:$Z$12"),0),0)),"ER")) -> NA | M21: =IF($F21=0,"NA",IF($A21=INDIRECT("'"&$A21&"'!$B$1"),IF(VLOOKUP(M$1,INDIRECT("'"&$A21&"'!$A$12:$Z$19"),MATCH("Points (Auto-generate)",INDIRECT("'"&$A21&"'!$A$12:$Z$12"),0),0)="","?",VLOOKUP(M$1,INDIRECT("'"&$A21&"'!$A$12:$Z$19"),MATCH("Points (Auto-generate)",INDIRECT("'"&$A21&"'!$A$12:$Z$12"),0),0)),"ER")) -> NA
A22: UPD6b | B22: =VLOOKUP($A22,'PARASTATAL Questions'!$A:$J,3,0)&"" -> Urban Planning & Design (UPD) | C22: =VLOOKUP($A22,'PARASTATAL Questions'!$A:$J,4,0)&"" -> SQ | D22: =VLOOKUP($A22,'PARASTATAL Questions'!$A:$J,5,0)&"" -> Does the transport corporation actually considers environmental sustainability in planning and delivering urban transport services and investments? | E22: =VLOOKUP($A22,'PARASTATAL Questions'!$A:$J,7,0)&"" -> Implementation | F22: =VLOOKUP($A22,'PARASTATAL Questions'!$A:$J,6,0) -> 5 | G22: =IF($F22=0,"NA",IF($A22=INDIRECT("'"&$A22&"'!$B$1"),IF(VLOOKUP(G$1,INDIRECT("'"&$A22&"'!$A$12:$Z$19"),MATCH("Points (Auto-generate)",INDIRECT("'"&$A22&"'!$A$12:$Z$12"),0),0)="","?",VLOOKUP(G$1,INDIRECT("'"&$A22&"'!$A$12:$Z$19"),MATCH("Points (Auto-generate)",INDIRECT("'"&$A22&"'!$A$12:$Z$12"),0),0)),"ER")) -> NA | H22: =IF($F22=0,"NA",IF($A22=INDIRECT("'"&$A22&"'!$B$1"),IF(VLOOKUP(H$1,INDIRECT("'"&$A22&"'!$A$12:$Z$19"),MATCH("Points (Auto-generate)",INDIRECT("'"&$A22&"'!$A$12:$Z$12"),0),0)="","?",VLOOKUP(H$1,INDIRECT("'"&$A22&"'!$A$12:$Z$19"),MATCH("Points (Auto-generate)",INDIRECT("'"&$A22&"'!$A$12:$Z$12"),0),0)),"ER")) -> ? | I22: =IF($F22=0,"NA",IF($A22=INDIRECT("'"&$A22&"'!$B$1"),IF(VLOOKUP(I$1,INDIRECT("'"&$A22&"'!$A$12:$Z$19"),MATCH("Points (Auto-generate)",INDIRECT("'"&$A22&"'!$A$12:$Z$12"),0),0)="","?",VLOOKUP(I$1,INDIRECT("'"&$A22&"'!$A$12:$Z$19"),MATCH("Points (Auto-generate)",INDIRECT("'"&$A22&"'!$A$12:$Z$12"),0),0)),"ER")) -> NA | J22: =IF($F22=0,"NA",IF($A22=INDIRECT("'"&$A22&"'!$B$1"),IF(VLOOKUP(J$1,INDIRECT("'"&$A22&"'!$A$12:$Z$19"),MATCH("Points (Auto-generate)",INDIRECT("'"&$A22&"'!$A$12:$Z$12"),0),0)="","?",VLOOKUP(J$1,INDIRECT("'"&$A22&"'!$A$12:$Z$19"),MATCH("Points (Auto-generate)",INDIRECT("'"&$A22&"'!$A$12:$Z$12"),0),0)),"ER")) -> NA | K22: =IF($F22=0,"NA",IF($A22=INDIRECT("'"&$A22&"'!$B$1"),IF(VLOOKUP(K$1,INDIRECT("'"&$A22&"'!$A$12:$Z$19"),MATCH("Points (Auto-generate)",INDIRECT("'"&$A22&"'!$A$12:$Z$12"),0),0)="","?",VLOOKUP(K$1,INDIRECT("'"&$A22&"'!$A$12:$Z$19"),MATCH("Points (Auto-generate)",INDIRECT("'"&$A22&"'!$A$12:$Z$12"),0),0)),"ER")) -> NA | L22: =IF($F22=0,"NA",IF($A22=INDIRECT("'"&$A22&"'!$B$1"),IF(VLOOKUP(L$1,INDIRECT("'"&$A22&"'!$A$12:$Z$19"),MATCH("Points (Auto-generate)",INDIRECT("'"&$A22&"'!$A$12:$Z$12"),0),0)="","?",VLOOKUP(L$1,INDIRECT("'"&$A22&"'!$A$12:$Z$19"),MATCH("Points (Auto-generate)",INDIRECT("'"&$A22&"'!$A$12:$Z$12"),0),0)),"ER")) -> NA | M22: =IF($F22=0,"NA",IF($A22=INDIRECT("'"&$A22&"'!$B$1"),IF(VLOOKUP(M$1,INDIRECT("'"&$A22&"'!$A$12:$Z$19"),MATCH("Points (Auto-generate)",INDIRECT("'"&$A22&"'!$A$12:$Z$12"),0),0)="","?",VLOOKUP(M$1,INDIRECT("'"&$A22&"'!$A$12:$Z$19"),MATCH("Points (Auto-generate)",INDIRECT("'"&$A22&"'!$A$12:$Z$12"),0),0)),"ER")) -> NA
A23: DPG1 | B23: =VLOOKUP($A23,'PARASTATAL Questions'!$A:$J,3,0)&"" -> Decentralised Participatory Governance | C23: =VLOOKUP($A23,'PARASTATAL Questions'!$A:$J,4,0)&"" -> MQ | D23: =VLOOKUP($A23,'PARASTATAL Questions'!$A:$J,5,0)&"" -> Are the functions and geographical jurisdiction of the parastatal clearly defined vis-à-vis the ULG and other relevant agencies? | E23: =VLOOKUP($A23,'PARASTATAL Questions'!$A:$J,7,0)&"" -> Law/Policy + Implementation | F23: =VLOOKUP($A23,'PARASTATAL Questions'!$A:$J,6,0) -> 10 | G23: =IF(OR(G24="ER",G25="ER"),"ER",IF(OR(G24="?",G25="?"),"?",IF(AND(G24="NA",G25="NA"),"NA",SUM(G24,G25)/((G24<>"NA")*$F$24+(G25<>"NA")*$F$25)*$F23))) -> ? | H23: =IF(OR(H24="ER",H25="ER"),"ER",IF(OR(H24="?",H25="?"),"?",IF(AND(H24="NA",H25="NA"),"NA",SUM(H24,H25)/((H24<>"NA")*$F$24+(H25<>"NA")*$F$25)*$F23))) -> ? | I23: =IF(OR(I24="ER",I25="ER"),"ER",IF(OR(I24="?",I25="?"),"?",IF(AND(I24="NA",I25="NA"),"NA",SUM(I24,I25)/((I24<>"NA")*$F$24+(I25<>"NA")*$F$25)*$F23))) -> 5 | J23: =IF(OR(J24="ER",J25="ER"),"ER",IF(OR(J24="?",J25="?"),"?",IF(AND(J24="NA",J25="NA"),"NA",SUM(J24,J25)/((J24<>"NA")*$F$24+(J25<>"NA")*$F$25)*$F23))) -> ? | K23: =IF(OR(K24="ER",K25="ER"),"ER",IF(OR(K24="?",K25="?"),"?",IF(AND(K24="NA",K25="NA"),"NA",SUM(K24,K25)/((K24<>"NA")*$F$24+(K25<>"NA")*$F$25)*$F23))) -> ? | L23: =IF(OR(L24="ER",L25="ER"),"ER",IF(OR(L24="?",L25="?"),"?",IF(AND(L24="NA",L25="NA"),"NA",SUM(L24,L25)/((L24<>"NA")*$F$24+(L25<>"NA")*$F$25)*$F23))) -> ? | M23: =IF(OR(M24="ER",M25="ER"),"ER",IF(OR(M24="?",M25="?"),"?",IF(AND(M24="NA",M25="NA"),"NA",SUM(M24,M25)/((M24<>"NA")*$F$24+(M25<>"NA")*$F$25)*$F23))) -> ?
A24: DPG1a | B24: =VLOOKUP($A24,'PARASTATAL Questions'!$A:$J,3,0)&"" -> Decentralised Participatory Governance | C24: =VLOOKUP($A24,'PARASTATAL Questions'!$A:$J,4,0)&"" -> SQ | D24: =VLOOKUP($A24,'PARASTATAL Questions'!$A:$J,5,0)&"" -> Does the law clearly demarcate the functions/responsibilities of the parastatal vis-à-vis the ULG? | E24: =VLOOKUP($A24,'PARASTATAL Questions'!$A:$J,7,0)&"" -> Law/policy | F24: =VLOOKUP($A24,'PARASTATAL Questions'!$A:$J,6,0) -> 5 | G24: =IF($F24=0,"NA",IF($A24=INDIRECT("'"&$A24&"'!$B$1"),IF(VLOOKUP(G$1,INDIRECT("'"&$A24&"'!$A$12:$Z$19"),MATCH("Points (Auto-generate)",INDIRECT("'"&$A24&"'!$A$12:$Z$12"),0),0)="","?",VLOOKUP(G$1,INDIRECT("'"&$A24&"'!$A$12:$Z$19"),MATCH("Points (Auto-generate)",INDIRECT("'"&$A24&"'!$A$12:$Z$12"),0),0)),"ER")) -> ? | H24: =IF($F24=0,"NA",IF($A24=INDIRECT("'"&$A24&"'!$B$1"),IF(VLOOKUP(H$1,INDIRECT("'"&$A24&"'!$A$12:$Z$19"),MATCH("Points (Auto-generate)",INDIRECT("'"&$A24&"'!$A$12:$Z$12"),0),0)="","?",VLOOKUP(H$1,INDIRECT("'"&$A24&"'!$A$12:$Z$19"),MATCH("Points (Auto-generate)",INDIRECT("'"&$A24&"'!$A$12:$Z$12"),0),0)),"ER")) -> ? | I24: =IF($F24=0,"NA",IF($A24=INDIRECT("'"&$A24&"'!$B$1"),IF(VLOOKUP(I$1,INDIRECT("'"&$A24&"'!$A$12:$Z$19"),MATCH("Points (Auto-generate)",INDIRECT("'"&$A24&"'!$A$12:$Z$12"),0),0)="","?",VLOOKUP(I$1,INDIRECT("'"&$A24&"'!$A$12:$Z$19"),MATCH("Points (Auto-generate)",INDIRECT("'"&$A24&"'!$A$12:$Z$12"),0),0)),"ER")) -> 0 | J24: =IF($F24=0,"NA",IF($A24=INDIRECT("'"&$A24&"'!$B$1"),IF(VLOOKUP(J$1,INDIRECT("'"&$A24&"'!$A$12:$Z$19"),MATCH("Points (Auto-generate)",INDIRECT("'"&$A24&"'!$A$12:$Z$12"),0),0)="","?",VLOOKUP(J$1,INDIRECT("'"&$A24&"'!$A$12:$Z$19"),MATCH("Points (Auto-generate)",INDIRECT("'"&$A24&"'!$A$12:$Z$12"),0),0)),"ER")) -> ? | K24: =IF($F24=0,"NA",IF($A24=INDIRECT("'"&$A24&"'!$B$1"),IF(VLOOKUP(K$1,INDIRECT("'"&$A24&"'!$A$12:$Z$19"),MATCH("Points (Auto-generate)",INDIRECT("'"&$A24&"'!$A$12:$Z$12"),0),0)="","?",VLOOKUP(K$1,INDIRECT("'"&$A24&"'!$A$12:$Z$19"),MATCH("Points (Auto-generate)",INDIRECT("'"&$A24&"'!$A$12:$Z$12"),0),0)),"ER")) -> ? | L24: =IF($F24=0,"NA",IF($A24=INDIRECT("'"&$A24&"'!$B$1"),IF(VLOOKUP(L$1,INDIRECT("'"&$A24&"'!$A$12:$Z$19"),MATCH("Points (Auto-generate)",INDIRECT("'"&$A24&"'!$A$12:$Z$12"),0),0)="","?",VLOOKUP(L$1,INDIRECT("'"&$A24&"'!$A$12:$Z$19"),MATCH("Points (Auto-generate)",INDIRECT("'"&$A24&"'!$A$12:$Z$12"),0),0)),"ER")) -> ? | M24: =IF($F24=0,"NA",IF($A24=INDIRECT("'"&$A24&"'!$B$1"),IF(VLOOKUP(M$1,INDIRECT("'"&$A24&"'!$A$12:$Z$19"),MATCH("Points (Auto-generate)",INDIRECT("'"&$A24&"'!$A$12:$Z$12"),0),0)="","?",VLOOKUP(M$1,INDIRECT("'"&$A24&"'!$A$12:$Z$19"),MATCH("Points (Auto-generate)",INDIRECT("'"&$A24&"'!$A$12:$Z$12"),0),0)),"ER")) -> ?
A25: DPG1b | B25: =VLOOKUP($A25,'PARASTATAL Questions'!$A:$J,3,0)&"" -> Decentralised Participatory Governance | C25: =VLOOKUP($A25,'PARASTATAL Questions'!$A:$J,4,0)&"" -> SQ | D25: =VLOOKUP($A25,'PARASTATAL Questions'!$A:$J,5,0)&"" -> Is the parastatal's territorial/geographic jurisdiction specifically defined in it's enabling law? | E25: =VLOOKUP($A25,'PARASTATAL Questions'!$A:$J,7,0)&"" -> Law/Policy | F25: =VLOOKUP($A25,'PARASTATAL Questions'!$A:$J,6,0) -> 5 | G25: =IF($F25=0,"NA",IF($A25=INDIRECT("'"&$A25&"'!$B$1"),IF(VLOOKUP(G$1,INDIRECT("'"&$A25&"'!$A$12:$Z$19"),MATCH("Points (Auto-generate)",INDIRECT("'"&$A25&"'!$A$12:$Z$12"),0),0)="","?",VLOOKUP(G$1,INDIRECT("'"&$A25&"'!$A$12:$Z$19"),MATCH("Points (Auto-generate)",INDIRECT("'"&$A25&"'!$A$12:$Z$12"),0),0)),"ER")) -> 5 | H25: =IF($F25=0,"NA",IF($A25=INDIRECT("'"&$A25&"'!$B$1"),IF(VLOOKUP(H$1,INDIRECT("'"&$A25&"'!$A$12:$Z$19"),MATCH("Points (Auto-generate)",INDIRECT("'"&$A25&"'!$A$12:$Z$12"),0),0)="","?",VLOOKUP(H$1,INDIRECT("'"&$A25&"'!$A$12:$Z$19"),MATCH("Points (Auto-generate)",INDIRECT("'"&$A25&"'!$A$12:$Z$12"),0),0)),"ER")) -> ? | I25: =IF($F25=0,"NA",IF($A25=INDIRECT("'"&$A25&"'!$B$1"),IF(VLOOKUP(I$1,INDIRECT("'"&$A25&"'!$A$12:$Z$19"),MATCH("Points (Auto-generate)",INDIRECT("'"&$A25&"'!$A$12:$Z$12"),0),0)="","?",VLOOKUP(I$1,INDIRECT("'"&$A25&"'!$A$12:$Z$19"),MATCH("Points (Auto-generate)",INDIRECT("'"&$A25&"'!$A$12:$Z$12"),0),0)),"ER")) -> 5 | J25: =IF($F25=0,"NA",IF($A25=INDIRECT("'"&$A25&"'!$B$1"),IF(VLOOKUP(J$1,INDIRECT("'"&$A25&"'!$A$12:$Z$19"),MATCH("Points (Auto-generate)",INDIRECT("'"&$A25&"'!$A$12:$Z$12"),0),0)="","?",VLOOKUP(J$1,INDIRECT("'"&$A25&"'!$A$12:$Z$19"),MATCH("Points (Auto-generate)",INDIRECT("'"&$A25&"'!$A$12:$Z$12"),0),0)),"ER")) -> ? | K25: =IF($F25=0,"NA",IF($A25=INDIRECT("'"&$A25&"'!$B$1"),IF(VLOOKUP(K$1,INDIRECT("'"&$A25&"'!$A$12:$Z$19"),MATCH("Points (Auto-generate)",INDIRECT("'"&$A25&"'!$A$12:$Z$12"),0),0)="","?",VLOOKUP(K$1,INDIRECT("'"&$A25&"'!$A$12:$Z$19"),MATCH("Points (Auto-generate)",INDIRECT("'"&$A25&"'!$A$12:$Z$12"),0),0)),"ER")) -> ? | L25: =IF($F25=0,"NA",IF($A25=INDIRECT("'"&$A25&"'!$B$1"),IF(VLOOKUP(L$1,INDIRECT("'"&$A25&"'!$A$12:$Z$19"),MATCH("Points (Auto-generate)",INDIRECT("'"&$A25&"'!$A$12:$Z$12"),0),0)="","?",VLOOKUP(L$1,INDIRECT("'"&$A25&"'!$A$12:$Z$19"),MATCH("Points (Auto-generate)",INDIRECT("'"&$A25&"'!$A$12:$Z$12"),0),0)),"ER")) -> ? | M25: =IF($F25=0,"NA",IF($A25=INDIRECT("'"&$A25&"'!$B$1"),IF(VLOOKUP(M$1,INDIRECT("'"&$A25&"'!$A$12:$Z$19"),MATCH("Points (Auto-generate)",INDIRECT("'"&$A25&"'!$A$12:$Z$12"),0),0)="","?",VLOOKUP(M$1,INDIRECT("'"&$A25&"'!$A$12:$Z$19"),MATCH("Points (Auto-generate)",INDIRECT("'"&$A25&"'!$A$12:$Z$12"),0),0)),"ER")) -> ?
A26: DPG2 | B26: =VLOOKUP($A26,'PARASTATAL Questions'!$A:$J,3,0)&"" -> Decentralised Participatory Governance | C26: =VLOOKUP($A26,'PARASTATAL Questions'!$A:$J,4,0)&"" -> MQ | D26: =VLOOKUP($A26,'PARASTATAL Questions'!$A:$J,5,0)&"" -> Is the parastatal accountable to the ULG? | E26: =VLOOKUP($A26,'PARASTATAL Questions'!$A:$J,7,0)&"" -> Law/Policy | F26: =VLOOKUP($A26,'PARASTATAL Questions'!$A:$J,6,0) -> 10 | G26: =IF(OR(G27="ER",G28="ER"),"ER",IF(OR(G27="?",G28="?"),"?",IF(AND(G27="NA",G28="NA"),"NA",SUM(G27,G28)/((G27<>"NA")*$F$27+(G28<>"NA")*$F$28)*$F26))) -> ? | H26: =IF(OR(H27="ER",H28="ER"),"ER",IF(OR(H27="?",H28="?"),"?",IF(AND(H27="NA",H28="NA"),"NA",SUM(H27,H28)/((H27<>"NA")*$F$27+(H28<>"NA")*$F$28)*$F26))) -> ? | I26: =IF(OR(I27="ER",I28="ER"),"ER",IF(OR(I27="?",I28="?"),"?",IF(AND(I27="NA",I28="NA"),"NA",SUM(I27,I28)/((I27<>"NA")*$F$27+(I28<>"NA")*$F$28)*$F26))) -> ? | J26: =IF(OR(J27="ER",J28="ER"),"ER",IF(OR(J27="?",J28="?"),"?",IF(AND(J27="NA",J28="NA"),"NA",SUM(J27,J28)/((J27<>"NA")*$F$27+(J28<>"NA")*$F$28)*$F26))) -> ? | K26: =IF(OR(K27="ER",K28="ER"),"ER",IF(OR(K27="?",K28="?"),"?",IF(AND(K27="NA",K28="NA"),"NA",SUM(K27,K28)/((K27<>"NA")*$F$27+(K28<>"NA")*$F$28)*$F26))) -> ? | L26: =IF(OR(L27="ER",L28="ER"),"ER",IF(OR(L27="?",L28="?"),"?",IF(AND(L27="NA",L28="NA"),"NA",SUM(L27,L28)/((L27<>"NA")*$F$27+(L28<>"NA")*$F$28)*$F26))) -> ? | M26: =IF(OR(M27="ER",M28="ER"),"ER",IF(OR(M27="?",M28="?"),"?",IF(AND(M27="NA",M28="NA"),"NA",SUM(M27,M28)/((M27<>"NA")*$F$27+(M28<>"NA")*$F$28)*$F26))) -> ?
